[2025-03-03T05:39:31.115+0000] {taskinstance.py:1103} INFO - Dependencies all met for dep_context=non-requeueable deps ti=<TaskInstance: dag_pipeline_query.create_fact_sales manual__2025-03-03T05:39:13.029042+00:00 [queued]>
[2025-03-03T05:39:31.137+0000] {taskinstance.py:1103} INFO - Dependencies all met for dep_context=requeueable deps ti=<TaskInstance: dag_pipeline_query.create_fact_sales manual__2025-03-03T05:39:13.029042+00:00 [queued]>
[2025-03-03T05:39:31.138+0000] {taskinstance.py:1308} INFO - Starting attempt 1 of 2
[2025-03-03T05:39:31.238+0000] {taskinstance.py:1327} INFO - Executing <Task(PostgresOperator): create_fact_sales> on 2025-03-03 05:39:13.029042+00:00
[2025-03-03T05:39:31.429+0000] {standard_task_runner.py:57} INFO - Started process 15939 to run task
[2025-03-03T05:39:31.433+0000] {standard_task_runner.py:84} INFO - Running: ['***', 'tasks', 'run', 'dag_pipeline_query', 'create_fact_sales', 'manual__2025-03-03T05:39:13.029042+00:00', '--job-id', '38', '--raw', '--subdir', 'DAGS_FOLDER/dag_pipeline_query.py', '--cfg-path', '/tmp/tmpi96gl99_']
[2025-03-03T05:39:31.436+0000] {standard_task_runner.py:85} INFO - Job 38: Subtask create_fact_sales
[2025-03-03T05:39:31.724+0000] {logging_mixin.py:149} WARNING - /home/***/.local/lib/python3.7/site-packages/***/settings.py:195 DeprecationWarning: The sql_alchemy_conn option in [core] has been moved to the sql_alchemy_conn option in [database] - the old setting has been used, but please update your config.
[2025-03-03T05:39:31.883+0000] {task_command.py:410} INFO - Running <TaskInstance: dag_pipeline_query.create_fact_sales manual__2025-03-03T05:39:13.029042+00:00 [running]> on host 9b8c8285a7ac
[2025-03-03T05:39:32.947+0000] {taskinstance.py:1547} INFO - Exporting env vars: AIRFLOW_CTX_DAG_OWNER='Raffi' AIRFLOW_CTX_DAG_ID='dag_pipeline_query' AIRFLOW_CTX_TASK_ID='create_fact_sales' AIRFLOW_CTX_EXECUTION_DATE='2025-03-03T05:39:13.029042+00:00' AIRFLOW_CTX_TRY_NUMBER='1' AIRFLOW_CTX_DAG_RUN_ID='manual__2025-03-03T05:39:13.029042+00:00'
[2025-03-03T05:39:32.949+0000] {sql.py:262} INFO - Executing: CREATE TABLE IF NOT EXISTS fact_sales AS
select 
ts.*,
tp.product_name,
tp.category as product_category,
tp.sub_category  as sub_category_product,
tp.price,
tps.disc,
tps.event_name as disc_name,
    CASE 
        WHEN tps.disc IS NOT NULL THEN (tp.price * ts.quantity) - (tp.price * ts.quantity) * COALESCE(tps.disc, 0) / 100
        ELSE tp.price * ts.quantity
    END AS amount
from tbl_sales ts 
left join tbl_product tp 
on tp.id  = ts.product_id 
left join tbl_promotions tps 
on tps.time = date(ts.order_date)
where 
ts.order_status = 2 and ts.payment_status = 2 and (ts.shipping_status = 2 or ts.shipping_status is null)
[2025-03-03T05:39:33.023+0000] {base.py:73} INFO - Using connection ID 'sales_project_conn' for task execution.
[2025-03-03T05:39:33.201+0000] {base.py:73} INFO - Using connection ID 'sales_project_conn' for task execution.
[2025-03-03T05:39:33.227+0000] {sql.py:375} INFO - Running statement: CREATE TABLE IF NOT EXISTS fact_sales AS
select 
ts.*,
tp.product_name,
tp.category as product_category,
tp.sub_category  as sub_category_product,
tp.price,
tps.disc,
tps.event_name as disc_name,
    CASE 
        WHEN tps.disc IS NOT NULL THEN (tp.price * ts.quantity) - (tp.price * ts.quantity) * COALESCE(tps.disc, 0) / 100
        ELSE tp.price * ts.quantity
    END AS amount
from tbl_sales ts 
left join tbl_product tp 
on tp.id  = ts.product_id 
left join tbl_promotions tps 
on tps.time = date(ts.order_date)
where 
ts.order_status = 2 and ts.payment_status = 2 and (ts.shipping_status = 2 or ts.shipping_status is null), parameters: None
[2025-03-03T05:39:34.901+0000] {taskinstance.py:1824} ERROR - Task failed with exception
Traceback (most recent call last):
  File "/home/airflow/.local/lib/python3.7/site-packages/airflow/providers/common/sql/operators/sql.py", line 274, in execute
    **extra_kwargs,
  File "/home/airflow/.local/lib/python3.7/site-packages/airflow/providers/common/sql/hooks/sql.py", line 349, in run
    self._run_command(cur, sql_statement, parameters)
  File "/home/airflow/.local/lib/python3.7/site-packages/airflow/providers/common/sql/hooks/sql.py", line 380, in _run_command
    cur.execute(sql_statement)
psycopg2.errors.NumericValueOutOfRange: integer out of range

[2025-03-03T05:39:34.953+0000] {taskinstance.py:1350} INFO - Marking task as UP_FOR_RETRY. dag_id=dag_pipeline_query, task_id=create_fact_sales, execution_date=20250303T053913, start_date=20250303T053931, end_date=20250303T053934
[2025-03-03T05:39:35.791+0000] {standard_task_runner.py:109} ERROR - Failed to execute job 38 for task create_fact_sales (integer out of range
; 15939)
[2025-03-03T05:39:35.824+0000] {local_task_job_runner.py:225} INFO - Task exited with return code 1
[2025-03-03T05:39:36.015+0000] {taskinstance.py:2651} INFO - 0 downstream tasks scheduled from follow-on schedule check
