[2025-03-03T01:40:23.846+0000] {taskinstance.py:1103} INFO - Dependencies all met for dep_context=non-requeueable deps ti=<TaskInstance: dag_full_load.full_load_tbl_branch manual__2025-03-03T01:40:19.292886+00:00 [queued]>
[2025-03-03T01:40:23.872+0000] {taskinstance.py:1103} INFO - Dependencies all met for dep_context=requeueable deps ti=<TaskInstance: dag_full_load.full_load_tbl_branch manual__2025-03-03T01:40:19.292886+00:00 [queued]>
[2025-03-03T01:40:23.873+0000] {taskinstance.py:1308} INFO - Starting attempt 1 of 2
[2025-03-03T01:40:24.147+0000] {taskinstance.py:1327} INFO - Executing <Task(PythonOperator): full_load_tbl_branch> on 2025-03-03 01:40:19.292886+00:00
[2025-03-03T01:40:24.197+0000] {standard_task_runner.py:57} INFO - Started process 492 to run task
[2025-03-03T01:40:24.201+0000] {standard_task_runner.py:84} INFO - Running: ['***', 'tasks', 'run', 'dag_full_load', 'full_load_tbl_branch', 'manual__2025-03-03T01:40:19.292886+00:00', '--job-id', '6', '--raw', '--subdir', 'DAGS_FOLDER/dag_full_load.py', '--cfg-path', '/tmp/tmpusmreaza']
[2025-03-03T01:40:24.203+0000] {standard_task_runner.py:85} INFO - Job 6: Subtask full_load_tbl_branch
[2025-03-03T01:40:24.447+0000] {logging_mixin.py:149} WARNING - /home/***/.local/lib/python3.7/site-packages/***/settings.py:195 DeprecationWarning: The sql_alchemy_conn option in [core] has been moved to the sql_alchemy_conn option in [database] - the old setting has been used, but please update your config.
[2025-03-03T01:40:24.545+0000] {task_command.py:410} INFO - Running <TaskInstance: dag_full_load.full_load_tbl_branch manual__2025-03-03T01:40:19.292886+00:00 [running]> on host 93536f18dd3f
[2025-03-03T01:40:26.143+0000] {taskinstance.py:1547} INFO - Exporting env vars: AIRFLOW_CTX_DAG_OWNER='Raffi' AIRFLOW_CTX_DAG_ID='dag_full_load' AIRFLOW_CTX_TASK_ID='full_load_tbl_branch' AIRFLOW_CTX_EXECUTION_DATE='2025-03-03T01:40:19.292886+00:00' AIRFLOW_CTX_TRY_NUMBER='1' AIRFLOW_CTX_DAG_RUN_ID='manual__2025-03-03T01:40:19.292886+00:00'
[2025-03-03T01:40:26.161+0000] {taskinstance.py:1824} ERROR - Task failed with exception
Traceback (most recent call last):
  File "/home/airflow/.local/lib/python3.7/site-packages/airflow/operators/python.py", line 181, in execute
    return_value = self.execute_callable()
  File "/home/airflow/.local/lib/python3.7/site-packages/airflow/operators/python.py", line 198, in execute_callable
    return self.python_callable(*self.op_args, **self.op_kwargs)
  File "/opt/airflow/dags/full_load_tbl_branch.py", line 32, in full_load_tbl_branch
    full_load_postgres(DB_USER, DB_PASSWORD, DB_HOST, DB_PORT, DB_NAME, SCHEMA_NAME, TABLE_NAME, engine, create_table_query, df)
  File "/opt/airflow/dags/full_load_postgres.py", line 25, in full_load_postgres
    port=DB_PORT
  File "/home/airflow/.local/lib/python3.7/site-packages/psycopg2/__init__.py", line 122, in connect
    conn = _connect(dsn, connection_factory=connection_factory, **kwasync)
psycopg2.OperationalError: connection to server at "localhost" (::1), port 5432 failed: Connection refused
	Is the server running on that host and accepting TCP/IP connections?
connection to server at "localhost" (127.0.0.1), port 5432 failed: Connection refused
	Is the server running on that host and accepting TCP/IP connections?

[2025-03-03T01:40:26.251+0000] {taskinstance.py:1350} INFO - Marking task as UP_FOR_RETRY. dag_id=dag_full_load, task_id=full_load_tbl_branch, execution_date=20250303T014019, start_date=20250303T014023, end_date=20250303T014026
[2025-03-03T01:40:26.865+0000] {standard_task_runner.py:109} ERROR - Failed to execute job 6 for task full_load_tbl_branch (connection to server at "localhost" (::1), port 5432 failed: Connection refused
	Is the server running on that host and accepting TCP/IP connections?
connection to server at "localhost" (127.0.0.1), port 5432 failed: Connection refused
	Is the server running on that host and accepting TCP/IP connections?
; 492)
[2025-03-03T01:40:26.943+0000] {local_task_job_runner.py:225} INFO - Task exited with return code 1
[2025-03-03T01:40:27.304+0000] {taskinstance.py:2651} INFO - 0 downstream tasks scheduled from follow-on schedule check
