[2025-03-03T03:38:00.826+0000] {taskinstance.py:1103} INFO - Dependencies all met for dep_context=non-requeueable deps ti=<TaskInstance: dag_pipeline_query.create_fact_query manual__2025-03-03T03:34:28.452047+00:00 [queued]>
[2025-03-03T03:38:00.846+0000] {taskinstance.py:1103} INFO - Dependencies all met for dep_context=requeueable deps ti=<TaskInstance: dag_pipeline_query.create_fact_query manual__2025-03-03T03:34:28.452047+00:00 [queued]>
[2025-03-03T03:38:00.847+0000] {taskinstance.py:1308} INFO - Starting attempt 2 of 3
[2025-03-03T03:38:01.005+0000] {taskinstance.py:1327} INFO - Executing <Task(PostgresOperator): create_fact_query> on 2025-03-03 03:34:28.452047+00:00
[2025-03-03T03:38:01.014+0000] {standard_task_runner.py:57} INFO - Started process 2740 to run task
[2025-03-03T03:38:01.019+0000] {standard_task_runner.py:84} INFO - Running: ['***', 'tasks', 'run', 'dag_pipeline_query', 'create_fact_query', 'manual__2025-03-03T03:34:28.452047+00:00', '--job-id', '29', '--raw', '--subdir', 'DAGS_FOLDER/dag_pipeline_query.py', '--cfg-path', '/tmp/tmpms9kikg7']
[2025-03-03T03:38:01.022+0000] {standard_task_runner.py:85} INFO - Job 29: Subtask create_fact_query
[2025-03-03T03:38:01.513+0000] {logging_mixin.py:149} WARNING - /home/***/.local/lib/python3.7/site-packages/***/settings.py:195 DeprecationWarning: The sql_alchemy_conn option in [core] has been moved to the sql_alchemy_conn option in [database] - the old setting has been used, but please update your config.
[2025-03-03T03:38:01.726+0000] {task_command.py:410} INFO - Running <TaskInstance: dag_pipeline_query.create_fact_query manual__2025-03-03T03:34:28.452047+00:00 [running]> on host 9b8c8285a7ac
[2025-03-03T03:38:02.583+0000] {abstractoperator.py:597} ERROR - Exception rendering Jinja template for task 'create_fact_query', field 'sql'. Template: '/opt/***/dags/sql/create_fact_employee.sql'
Traceback (most recent call last):
  File "/home/airflow/.local/lib/python3.7/site-packages/airflow/models/abstractoperator.py", line 589, in _do_render_template_fields
    seen_oids,
  File "/home/airflow/.local/lib/python3.7/site-packages/airflow/template/templater.py", line 153, in render_template
    template = jinja_env.get_template(value)
  File "/home/airflow/.local/lib/python3.7/site-packages/jinja2/environment.py", line 1010, in get_template
    return self._load_template(name, globals)
  File "/home/airflow/.local/lib/python3.7/site-packages/jinja2/environment.py", line 969, in _load_template
    template = self.loader.load(self, name, self.make_globals(globals))
  File "/home/airflow/.local/lib/python3.7/site-packages/jinja2/loaders.py", line 126, in load
    source, filename, uptodate = self.get_source(environment, name)
  File "/home/airflow/.local/lib/python3.7/site-packages/jinja2/loaders.py", line 218, in get_source
    raise TemplateNotFound(template)
jinja2.exceptions.TemplateNotFound: /opt/airflow/dags/sql/create_fact_employee.sql
[2025-03-03T03:38:02.585+0000] {taskinstance.py:1824} ERROR - Task failed with exception
Traceback (most recent call last):
  File "/home/airflow/.local/lib/python3.7/site-packages/airflow/models/taskinstance.py", line 1407, in _run_raw_task
    self._execute_task_with_callbacks(context, test_mode)
  File "/home/airflow/.local/lib/python3.7/site-packages/airflow/models/taskinstance.py", line 1531, in _execute_task_with_callbacks
    task_orig = self.render_templates(context=context)
  File "/home/airflow/.local/lib/python3.7/site-packages/airflow/models/taskinstance.py", line 2179, in render_templates
    original_task.render_template_fields(context)
  File "/home/airflow/.local/lib/python3.7/site-packages/airflow/models/baseoperator.py", line 1254, in render_template_fields
    self._do_render_template_fields(self, self.template_fields, context, jinja_env, set())
  File "/home/airflow/.local/lib/python3.7/site-packages/airflow/utils/session.py", line 76, in wrapper
    return func(*args, session=session, **kwargs)
  File "/home/airflow/.local/lib/python3.7/site-packages/airflow/models/abstractoperator.py", line 589, in _do_render_template_fields
    seen_oids,
  File "/home/airflow/.local/lib/python3.7/site-packages/airflow/template/templater.py", line 153, in render_template
    template = jinja_env.get_template(value)
  File "/home/airflow/.local/lib/python3.7/site-packages/jinja2/environment.py", line 1010, in get_template
    return self._load_template(name, globals)
  File "/home/airflow/.local/lib/python3.7/site-packages/jinja2/environment.py", line 969, in _load_template
    template = self.loader.load(self, name, self.make_globals(globals))
  File "/home/airflow/.local/lib/python3.7/site-packages/jinja2/loaders.py", line 126, in load
    source, filename, uptodate = self.get_source(environment, name)
  File "/home/airflow/.local/lib/python3.7/site-packages/jinja2/loaders.py", line 218, in get_source
    raise TemplateNotFound(template)
jinja2.exceptions.TemplateNotFound: /opt/airflow/dags/sql/create_fact_employee.sql
[2025-03-03T03:38:02.631+0000] {taskinstance.py:1350} INFO - Marking task as UP_FOR_RETRY. dag_id=dag_pipeline_query, task_id=create_fact_query, execution_date=20250303T033428, start_date=20250303T033800, end_date=20250303T033802
[2025-03-03T03:38:02.778+0000] {standard_task_runner.py:109} ERROR - Failed to execute job 29 for task create_fact_query (/opt/airflow/dags/sql/create_fact_employee.sql; 2740)
[2025-03-03T03:38:02.797+0000] {local_task_job_runner.py:225} INFO - Task exited with return code 1
[2025-03-03T03:38:02.963+0000] {taskinstance.py:2651} INFO - 0 downstream tasks scheduled from follow-on schedule check
