[2025-03-03T03:45:06.532+0000] {taskinstance.py:1103} INFO - Dependencies all met for dep_context=non-requeueable deps ti=<TaskInstance: dag_pipeline_query.create_fact_query manual__2025-03-03T03:34:28.452047+00:00 [queued]>
[2025-03-03T03:45:06.551+0000] {taskinstance.py:1103} INFO - Dependencies all met for dep_context=requeueable deps ti=<TaskInstance: dag_pipeline_query.create_fact_query manual__2025-03-03T03:34:28.452047+00:00 [queued]>
[2025-03-03T03:45:06.554+0000] {taskinstance.py:1308} INFO - Starting attempt 4 of 5
[2025-03-03T03:45:06.897+0000] {taskinstance.py:1327} INFO - Executing <Task(PostgresOperator): create_fact_query> on 2025-03-03 03:34:28.452047+00:00
[2025-03-03T03:45:07.391+0000] {standard_task_runner.py:57} INFO - Started process 3216 to run task
[2025-03-03T03:45:07.394+0000] {standard_task_runner.py:84} INFO - Running: ['***', 'tasks', 'run', 'dag_pipeline_query', 'create_fact_query', 'manual__2025-03-03T03:34:28.452047+00:00', '--job-id', '31', '--raw', '--subdir', 'DAGS_FOLDER/dag_pipeline_query.py', '--cfg-path', '/tmp/tmpbzx6upz3']
[2025-03-03T03:45:07.396+0000] {standard_task_runner.py:85} INFO - Job 31: Subtask create_fact_query
[2025-03-03T03:45:07.820+0000] {logging_mixin.py:149} WARNING - /home/***/.local/lib/python3.7/site-packages/***/settings.py:195 DeprecationWarning: The sql_alchemy_conn option in [core] has been moved to the sql_alchemy_conn option in [database] - the old setting has been used, but please update your config.
[2025-03-03T03:45:07.969+0000] {task_command.py:410} INFO - Running <TaskInstance: dag_pipeline_query.create_fact_query manual__2025-03-03T03:34:28.452047+00:00 [running]> on host 9b8c8285a7ac
[2025-03-03T03:45:09.152+0000] {taskinstance.py:1547} INFO - Exporting env vars: AIRFLOW_CTX_DAG_OWNER='Raffi' AIRFLOW_CTX_DAG_ID='dag_pipeline_query' AIRFLOW_CTX_TASK_ID='create_fact_query' AIRFLOW_CTX_EXECUTION_DATE='2025-03-03T03:34:28.452047+00:00' AIRFLOW_CTX_TRY_NUMBER='4' AIRFLOW_CTX_DAG_RUN_ID='manual__2025-03-03T03:34:28.452047+00:00'
[2025-03-03T03:45:09.154+0000] {sql.py:262} INFO - Executing: CREATE TABLE IF NOT EXISTS fact_employee AS
select 
*
from tbl_employee te 
where te.active = 'true'
[2025-03-03T03:45:09.197+0000] {base.py:73} INFO - Using connection ID 'postgres_default' for task execution.
[2025-03-03T03:45:26.536+0000] {base.py:73} INFO - Using connection ID 'postgres_default' for task execution.
[2025-03-03T03:45:26.549+0000] {taskinstance.py:1824} ERROR - Task failed with exception
Traceback (most recent call last):
  File "/home/airflow/.local/lib/python3.7/site-packages/airflow/providers/common/sql/operators/sql.py", line 274, in execute
    **extra_kwargs,
  File "/home/airflow/.local/lib/python3.7/site-packages/airflow/providers/common/sql/hooks/sql.py", line 342, in run
    with closing(self.get_conn()) as conn:
  File "/home/airflow/.local/lib/python3.7/site-packages/airflow/providers/postgres/hooks/postgres.py", line 144, in get_conn
    self.conn = psycopg2.connect(**conn_args)
  File "/home/airflow/.local/lib/python3.7/site-packages/psycopg2/__init__.py", line 122, in connect
    conn = _connect(dsn, connection_factory=connection_factory, **kwasync)
psycopg2.OperationalError: connection to server at "postgres" (172.18.0.2), port 5432 failed: FATAL:  password authentication failed for user "postgres"

[2025-03-03T03:45:26.634+0000] {taskinstance.py:1350} INFO - Marking task as UP_FOR_RETRY. dag_id=dag_pipeline_query, task_id=create_fact_query, execution_date=20250303T033428, start_date=20250303T034506, end_date=20250303T034526
[2025-03-03T03:45:26.697+0000] {standard_task_runner.py:109} ERROR - Failed to execute job 31 for task create_fact_query (connection to server at "postgres" (172.18.0.2), port 5432 failed: FATAL:  password authentication failed for user "postgres"
; 3216)
[2025-03-03T03:45:26.751+0000] {local_task_job_runner.py:225} INFO - Task exited with return code 1
[2025-03-03T03:45:26.828+0000] {taskinstance.py:2651} INFO - 0 downstream tasks scheduled from follow-on schedule check
