[2025-03-02T22:57:36.408+0000] {processor.py:157} INFO - Started process (PID=199) to work on /opt/airflow/dags/dag_pipeline_generate_data.py
[2025-03-02T22:57:36.410+0000] {processor.py:826} INFO - Processing file /opt/airflow/dags/dag_pipeline_generate_data.py for tasks to queue
[2025-03-02T22:57:36.411+0000] {logging_mixin.py:149} INFO - [2025-03-02T22:57:36.411+0000] {dagbag.py:541} INFO - Filling up the DagBag from /opt/airflow/dags/dag_pipeline_generate_data.py
[2025-03-02T22:58:09.448+0000] {logging_mixin.py:149} INFO - [2025-03-02T22:58:09.447+0000] {timeout.py:68} ERROR - Process timed out, PID: 199
[2025-03-02T22:58:09.796+0000] {logging_mixin.py:149} INFO - [2025-03-02T22:58:09.782+0000] {dagbag.py:350} ERROR - Failed to import: /opt/airflow/dags/dag_pipeline_generate_data.py
Traceback (most recent call last):
  File "/home/airflow/.local/lib/python3.7/site-packages/airflow/models/dagbag.py", line 346, in parse
    loader.exec_module(new_module)
  File "<frozen importlib._bootstrap_external>", line 728, in exec_module
  File "<frozen importlib._bootstrap>", line 219, in _call_with_frames_removed
  File "/opt/airflow/dags/dag_pipeline_generate_data.py", line 4, in <module>
    import generate_data
  File "/opt/airflow/dags/generate_data.py", line 3, in <module>
    from faker import Faker
  File "/home/airflow/.local/lib/python3.7/site-packages/faker/__init__.py", line 1, in <module>
    from faker.factory import Factory
  File "/home/airflow/.local/lib/python3.7/site-packages/faker/factory.py", line 8, in <module>
    from .config import AVAILABLE_LOCALES, DEFAULT_LOCALE, PROVIDERS
  File "/home/airflow/.local/lib/python3.7/site-packages/faker/config.py", line 13, in <module>
    AVAILABLE_LOCALES = find_available_locales(PROVIDERS)
  File "/home/airflow/.local/lib/python3.7/site-packages/faker/utils/loading.py", line 45, in find_available_locales
    provider_module = import_module(provider_path)
  File "/usr/local/lib/python3.7/importlib/__init__.py", line 127, in import_module
    return _bootstrap._gcd_import(name[level:], package, level)
  File "<frozen importlib._bootstrap>", line 1006, in _gcd_import
  File "<frozen importlib._bootstrap>", line 983, in _find_and_load
  File "<frozen importlib._bootstrap>", line 967, in _find_and_load_unlocked
  File "<frozen importlib._bootstrap>", line 677, in _load_unlocked
  File "<frozen importlib._bootstrap_external>", line 724, in exec_module
  File "<frozen importlib._bootstrap_external>", line 818, in get_code
  File "<frozen importlib._bootstrap_external>", line 917, in get_data
  File "/home/airflow/.local/lib/python3.7/site-packages/airflow/utils/timeout.py", line 69, in handle_timeout
    raise AirflowTaskTimeout(self.error_message)
airflow.exceptions.AirflowTaskTimeout: DagBag import timeout for /opt/airflow/dags/dag_pipeline_generate_data.py after 30.0s.
Please take a look at these docs to improve your DAG import time:
* https://airflow.apache.org/docs/apache-airflow/2.6.1/best-practices.html#top-level-python-code
* https://airflow.apache.org/docs/apache-airflow/2.6.1/best-practices.html#reducing-dag-complexity, PID: 199
[2025-03-02T22:58:09.797+0000] {processor.py:838} WARNING - No viable dags retrieved from /opt/airflow/dags/dag_pipeline_generate_data.py
[2025-03-02T22:58:10.549+0000] {processor.py:179} INFO - Processing /opt/airflow/dags/dag_pipeline_generate_data.py took 31.316 seconds
[2025-03-02T22:58:40.862+0000] {processor.py:157} INFO - Started process (PID=237) to work on /opt/airflow/dags/dag_pipeline_generate_data.py
[2025-03-02T22:58:40.863+0000] {processor.py:826} INFO - Processing file /opt/airflow/dags/dag_pipeline_generate_data.py for tasks to queue
[2025-03-02T22:58:40.864+0000] {logging_mixin.py:149} INFO - [2025-03-02T22:58:40.864+0000] {dagbag.py:541} INFO - Filling up the DagBag from /opt/airflow/dags/dag_pipeline_generate_data.py
[2025-03-02T22:58:57.304+0000] {logging_mixin.py:149} INFO - [2025-03-02T22:58:56.139+0000] {dagbag.py:350} ERROR - Failed to import: /opt/airflow/dags/dag_pipeline_generate_data.py
Traceback (most recent call last):
  File "/home/airflow/.local/lib/python3.7/site-packages/airflow/models/dagbag.py", line 346, in parse
    loader.exec_module(new_module)
  File "<frozen importlib._bootstrap_external>", line 728, in exec_module
  File "<frozen importlib._bootstrap>", line 219, in _call_with_frames_removed
  File "/opt/airflow/dags/dag_pipeline_generate_data.py", line 26, in <module>
    dag=dag,
  File "/home/airflow/.local/lib/python3.7/site-packages/airflow/models/baseoperator.py", line 429, in apply_defaults
    result = func(self, **kwargs, default_args=default_args)
  File "/home/airflow/.local/lib/python3.7/site-packages/airflow/operators/python.py", line 168, in __init__
    raise AirflowException("`python_callable` param must be callable")
airflow.exceptions.AirflowException: `python_callable` param must be callable
[2025-03-02T22:58:57.306+0000] {processor.py:838} WARNING - No viable dags retrieved from /opt/airflow/dags/dag_pipeline_generate_data.py
[2025-03-02T22:58:57.819+0000] {processor.py:179} INFO - Processing /opt/airflow/dags/dag_pipeline_generate_data.py took 14.376 seconds
[2025-03-02T22:59:27.972+0000] {processor.py:157} INFO - Started process (PID=273) to work on /opt/airflow/dags/dag_pipeline_generate_data.py
[2025-03-02T22:59:27.973+0000] {processor.py:826} INFO - Processing file /opt/airflow/dags/dag_pipeline_generate_data.py for tasks to queue
[2025-03-02T22:59:27.974+0000] {logging_mixin.py:149} INFO - [2025-03-02T22:59:27.974+0000] {dagbag.py:541} INFO - Filling up the DagBag from /opt/airflow/dags/dag_pipeline_generate_data.py
[2025-03-02T22:59:32.060+0000] {logging_mixin.py:149} INFO - [2025-03-02T22:59:32.053+0000] {dagbag.py:350} ERROR - Failed to import: /opt/airflow/dags/dag_pipeline_generate_data.py
Traceback (most recent call last):
  File "/home/airflow/.local/lib/python3.7/site-packages/airflow/models/dagbag.py", line 346, in parse
    loader.exec_module(new_module)
  File "<frozen importlib._bootstrap_external>", line 728, in exec_module
  File "<frozen importlib._bootstrap>", line 219, in _call_with_frames_removed
  File "/opt/airflow/dags/dag_pipeline_generate_data.py", line 26, in <module>
    dag=dag,
  File "/home/airflow/.local/lib/python3.7/site-packages/airflow/models/baseoperator.py", line 429, in apply_defaults
    result = func(self, **kwargs, default_args=default_args)
  File "/home/airflow/.local/lib/python3.7/site-packages/airflow/operators/python.py", line 168, in __init__
    raise AirflowException("`python_callable` param must be callable")
airflow.exceptions.AirflowException: `python_callable` param must be callable
[2025-03-02T22:59:32.061+0000] {processor.py:838} WARNING - No viable dags retrieved from /opt/airflow/dags/dag_pipeline_generate_data.py
[2025-03-02T22:59:32.593+0000] {processor.py:179} INFO - Processing /opt/airflow/dags/dag_pipeline_generate_data.py took 4.623 seconds
[2025-03-02T23:00:03.410+0000] {processor.py:157} INFO - Started process (PID=304) to work on /opt/airflow/dags/dag_pipeline_generate_data.py
[2025-03-02T23:00:03.412+0000] {processor.py:826} INFO - Processing file /opt/airflow/dags/dag_pipeline_generate_data.py for tasks to queue
[2025-03-02T23:00:03.414+0000] {logging_mixin.py:149} INFO - [2025-03-02T23:00:03.414+0000] {dagbag.py:541} INFO - Filling up the DagBag from /opt/airflow/dags/dag_pipeline_generate_data.py
[2025-03-02T23:00:07.593+0000] {logging_mixin.py:149} INFO - [2025-03-02T23:00:07.587+0000] {dagbag.py:350} ERROR - Failed to import: /opt/airflow/dags/dag_pipeline_generate_data.py
Traceback (most recent call last):
  File "/home/airflow/.local/lib/python3.7/site-packages/airflow/models/dagbag.py", line 346, in parse
    loader.exec_module(new_module)
  File "<frozen importlib._bootstrap_external>", line 728, in exec_module
  File "<frozen importlib._bootstrap>", line 219, in _call_with_frames_removed
  File "/opt/airflow/dags/dag_pipeline_generate_data.py", line 26, in <module>
    dag=dag,
  File "/home/airflow/.local/lib/python3.7/site-packages/airflow/models/baseoperator.py", line 429, in apply_defaults
    result = func(self, **kwargs, default_args=default_args)
  File "/home/airflow/.local/lib/python3.7/site-packages/airflow/operators/python.py", line 168, in __init__
    raise AirflowException("`python_callable` param must be callable")
airflow.exceptions.AirflowException: `python_callable` param must be callable
[2025-03-02T23:00:07.594+0000] {processor.py:838} WARNING - No viable dags retrieved from /opt/airflow/dags/dag_pipeline_generate_data.py
[2025-03-02T23:00:07.923+0000] {processor.py:179} INFO - Processing /opt/airflow/dags/dag_pipeline_generate_data.py took 4.519 seconds
[2025-03-02T23:00:38.101+0000] {processor.py:157} INFO - Started process (PID=340) to work on /opt/airflow/dags/dag_pipeline_generate_data.py
[2025-03-02T23:00:38.103+0000] {processor.py:826} INFO - Processing file /opt/airflow/dags/dag_pipeline_generate_data.py for tasks to queue
[2025-03-02T23:00:38.104+0000] {logging_mixin.py:149} INFO - [2025-03-02T23:00:38.104+0000] {dagbag.py:541} INFO - Filling up the DagBag from /opt/airflow/dags/dag_pipeline_generate_data.py
[2025-03-02T23:00:41.329+0000] {logging_mixin.py:149} INFO - [2025-03-02T23:00:41.323+0000] {dagbag.py:350} ERROR - Failed to import: /opt/airflow/dags/dag_pipeline_generate_data.py
Traceback (most recent call last):
  File "/home/airflow/.local/lib/python3.7/site-packages/airflow/models/dagbag.py", line 346, in parse
    loader.exec_module(new_module)
  File "<frozen importlib._bootstrap_external>", line 728, in exec_module
  File "<frozen importlib._bootstrap>", line 219, in _call_with_frames_removed
  File "/opt/airflow/dags/dag_pipeline_generate_data.py", line 26, in <module>
    dag=dag,
  File "/home/airflow/.local/lib/python3.7/site-packages/airflow/models/baseoperator.py", line 429, in apply_defaults
    result = func(self, **kwargs, default_args=default_args)
  File "/home/airflow/.local/lib/python3.7/site-packages/airflow/operators/python.py", line 168, in __init__
    raise AirflowException("`python_callable` param must be callable")
airflow.exceptions.AirflowException: `python_callable` param must be callable
[2025-03-02T23:00:41.330+0000] {processor.py:838} WARNING - No viable dags retrieved from /opt/airflow/dags/dag_pipeline_generate_data.py
[2025-03-02T23:00:42.042+0000] {processor.py:179} INFO - Processing /opt/airflow/dags/dag_pipeline_generate_data.py took 3.944 seconds
[2025-03-02T23:01:12.343+0000] {processor.py:157} INFO - Started process (PID=371) to work on /opt/airflow/dags/dag_pipeline_generate_data.py
[2025-03-02T23:01:12.345+0000] {processor.py:826} INFO - Processing file /opt/airflow/dags/dag_pipeline_generate_data.py for tasks to queue
[2025-03-02T23:01:12.346+0000] {logging_mixin.py:149} INFO - [2025-03-02T23:01:12.345+0000] {dagbag.py:541} INFO - Filling up the DagBag from /opt/airflow/dags/dag_pipeline_generate_data.py
[2025-03-02T23:01:16.510+0000] {logging_mixin.py:149} INFO - [2025-03-02T23:01:16.503+0000] {dagbag.py:350} ERROR - Failed to import: /opt/airflow/dags/dag_pipeline_generate_data.py
Traceback (most recent call last):
  File "/home/airflow/.local/lib/python3.7/site-packages/airflow/models/dagbag.py", line 346, in parse
    loader.exec_module(new_module)
  File "<frozen importlib._bootstrap_external>", line 728, in exec_module
  File "<frozen importlib._bootstrap>", line 219, in _call_with_frames_removed
  File "/opt/airflow/dags/dag_pipeline_generate_data.py", line 26, in <module>
    dag=dag,
  File "/home/airflow/.local/lib/python3.7/site-packages/airflow/models/baseoperator.py", line 429, in apply_defaults
    result = func(self, **kwargs, default_args=default_args)
  File "/home/airflow/.local/lib/python3.7/site-packages/airflow/operators/python.py", line 168, in __init__
    raise AirflowException("`python_callable` param must be callable")
airflow.exceptions.AirflowException: `python_callable` param must be callable
[2025-03-02T23:01:16.511+0000] {processor.py:838} WARNING - No viable dags retrieved from /opt/airflow/dags/dag_pipeline_generate_data.py
[2025-03-02T23:01:16.938+0000] {processor.py:179} INFO - Processing /opt/airflow/dags/dag_pipeline_generate_data.py took 4.598 seconds
[2025-03-02T23:01:47.136+0000] {processor.py:157} INFO - Started process (PID=402) to work on /opt/airflow/dags/dag_pipeline_generate_data.py
[2025-03-02T23:01:47.138+0000] {processor.py:826} INFO - Processing file /opt/airflow/dags/dag_pipeline_generate_data.py for tasks to queue
[2025-03-02T23:01:47.139+0000] {logging_mixin.py:149} INFO - [2025-03-02T23:01:47.138+0000] {dagbag.py:541} INFO - Filling up the DagBag from /opt/airflow/dags/dag_pipeline_generate_data.py
[2025-03-02T23:01:50.912+0000] {logging_mixin.py:149} INFO - [2025-03-02T23:01:50.905+0000] {dagbag.py:350} ERROR - Failed to import: /opt/airflow/dags/dag_pipeline_generate_data.py
Traceback (most recent call last):
  File "/home/airflow/.local/lib/python3.7/site-packages/airflow/models/dagbag.py", line 346, in parse
    loader.exec_module(new_module)
  File "<frozen importlib._bootstrap_external>", line 728, in exec_module
  File "<frozen importlib._bootstrap>", line 219, in _call_with_frames_removed
  File "/opt/airflow/dags/dag_pipeline_generate_data.py", line 26, in <module>
    dag=dag,
  File "/home/airflow/.local/lib/python3.7/site-packages/airflow/models/baseoperator.py", line 429, in apply_defaults
    result = func(self, **kwargs, default_args=default_args)
  File "/home/airflow/.local/lib/python3.7/site-packages/airflow/operators/python.py", line 168, in __init__
    raise AirflowException("`python_callable` param must be callable")
airflow.exceptions.AirflowException: `python_callable` param must be callable
[2025-03-02T23:01:50.913+0000] {processor.py:838} WARNING - No viable dags retrieved from /opt/airflow/dags/dag_pipeline_generate_data.py
[2025-03-02T23:01:51.127+0000] {processor.py:179} INFO - Processing /opt/airflow/dags/dag_pipeline_generate_data.py took 3.993 seconds
[2025-03-02T23:02:21.363+0000] {processor.py:157} INFO - Started process (PID=433) to work on /opt/airflow/dags/dag_pipeline_generate_data.py
[2025-03-02T23:02:21.364+0000] {processor.py:826} INFO - Processing file /opt/airflow/dags/dag_pipeline_generate_data.py for tasks to queue
[2025-03-02T23:02:21.365+0000] {logging_mixin.py:149} INFO - [2025-03-02T23:02:21.365+0000] {dagbag.py:541} INFO - Filling up the DagBag from /opt/airflow/dags/dag_pipeline_generate_data.py
[2025-03-02T23:02:25.000+0000] {logging_mixin.py:149} INFO - [2025-03-02T23:02:24.992+0000] {dagbag.py:350} ERROR - Failed to import: /opt/airflow/dags/dag_pipeline_generate_data.py
Traceback (most recent call last):
  File "/home/airflow/.local/lib/python3.7/site-packages/airflow/models/dagbag.py", line 346, in parse
    loader.exec_module(new_module)
  File "<frozen importlib._bootstrap_external>", line 728, in exec_module
  File "<frozen importlib._bootstrap>", line 219, in _call_with_frames_removed
  File "/opt/airflow/dags/dag_pipeline_generate_data.py", line 26, in <module>
    dag=dag,
  File "/home/airflow/.local/lib/python3.7/site-packages/airflow/models/baseoperator.py", line 429, in apply_defaults
    result = func(self, **kwargs, default_args=default_args)
  File "/home/airflow/.local/lib/python3.7/site-packages/airflow/operators/python.py", line 168, in __init__
    raise AirflowException("`python_callable` param must be callable")
airflow.exceptions.AirflowException: `python_callable` param must be callable
[2025-03-02T23:02:25.001+0000] {processor.py:838} WARNING - No viable dags retrieved from /opt/airflow/dags/dag_pipeline_generate_data.py
[2025-03-02T23:02:25.248+0000] {processor.py:179} INFO - Processing /opt/airflow/dags/dag_pipeline_generate_data.py took 3.888 seconds
[2025-03-02T23:02:55.519+0000] {processor.py:157} INFO - Started process (PID=464) to work on /opt/airflow/dags/dag_pipeline_generate_data.py
[2025-03-02T23:02:55.520+0000] {processor.py:826} INFO - Processing file /opt/airflow/dags/dag_pipeline_generate_data.py for tasks to queue
[2025-03-02T23:02:55.521+0000] {logging_mixin.py:149} INFO - [2025-03-02T23:02:55.520+0000] {dagbag.py:541} INFO - Filling up the DagBag from /opt/airflow/dags/dag_pipeline_generate_data.py
[2025-03-02T23:02:58.748+0000] {logging_mixin.py:149} INFO - [2025-03-02T23:02:58.743+0000] {dagbag.py:350} ERROR - Failed to import: /opt/airflow/dags/dag_pipeline_generate_data.py
Traceback (most recent call last):
  File "/home/airflow/.local/lib/python3.7/site-packages/airflow/models/dagbag.py", line 346, in parse
    loader.exec_module(new_module)
  File "<frozen importlib._bootstrap_external>", line 728, in exec_module
  File "<frozen importlib._bootstrap>", line 219, in _call_with_frames_removed
  File "/opt/airflow/dags/dag_pipeline_generate_data.py", line 26, in <module>
    dag=dag,
  File "/home/airflow/.local/lib/python3.7/site-packages/airflow/models/baseoperator.py", line 429, in apply_defaults
    result = func(self, **kwargs, default_args=default_args)
  File "/home/airflow/.local/lib/python3.7/site-packages/airflow/operators/python.py", line 168, in __init__
    raise AirflowException("`python_callable` param must be callable")
airflow.exceptions.AirflowException: `python_callable` param must be callable
[2025-03-02T23:02:58.749+0000] {processor.py:838} WARNING - No viable dags retrieved from /opt/airflow/dags/dag_pipeline_generate_data.py
[2025-03-02T23:02:58.874+0000] {processor.py:179} INFO - Processing /opt/airflow/dags/dag_pipeline_generate_data.py took 3.358 seconds
[2025-03-02T23:03:29.630+0000] {processor.py:157} INFO - Started process (PID=495) to work on /opt/airflow/dags/dag_pipeline_generate_data.py
[2025-03-02T23:03:29.631+0000] {processor.py:826} INFO - Processing file /opt/airflow/dags/dag_pipeline_generate_data.py for tasks to queue
[2025-03-02T23:03:29.632+0000] {logging_mixin.py:149} INFO - [2025-03-02T23:03:29.632+0000] {dagbag.py:541} INFO - Filling up the DagBag from /opt/airflow/dags/dag_pipeline_generate_data.py
[2025-03-02T23:03:33.407+0000] {logging_mixin.py:149} INFO - [2025-03-02T23:03:33.401+0000] {dagbag.py:350} ERROR - Failed to import: /opt/airflow/dags/dag_pipeline_generate_data.py
Traceback (most recent call last):
  File "/home/airflow/.local/lib/python3.7/site-packages/airflow/models/dagbag.py", line 346, in parse
    loader.exec_module(new_module)
  File "<frozen importlib._bootstrap_external>", line 728, in exec_module
  File "<frozen importlib._bootstrap>", line 219, in _call_with_frames_removed
  File "/opt/airflow/dags/dag_pipeline_generate_data.py", line 26, in <module>
    dag=dag,
  File "/home/airflow/.local/lib/python3.7/site-packages/airflow/models/baseoperator.py", line 429, in apply_defaults
    result = func(self, **kwargs, default_args=default_args)
  File "/home/airflow/.local/lib/python3.7/site-packages/airflow/operators/python.py", line 168, in __init__
    raise AirflowException("`python_callable` param must be callable")
airflow.exceptions.AirflowException: `python_callable` param must be callable
[2025-03-02T23:03:33.407+0000] {processor.py:838} WARNING - No viable dags retrieved from /opt/airflow/dags/dag_pipeline_generate_data.py
[2025-03-02T23:03:33.866+0000] {processor.py:179} INFO - Processing /opt/airflow/dags/dag_pipeline_generate_data.py took 4.239 seconds
[2025-03-02T23:04:04.480+0000] {processor.py:157} INFO - Started process (PID=526) to work on /opt/airflow/dags/dag_pipeline_generate_data.py
[2025-03-02T23:04:04.482+0000] {processor.py:826} INFO - Processing file /opt/airflow/dags/dag_pipeline_generate_data.py for tasks to queue
[2025-03-02T23:04:04.483+0000] {logging_mixin.py:149} INFO - [2025-03-02T23:04:04.483+0000] {dagbag.py:541} INFO - Filling up the DagBag from /opt/airflow/dags/dag_pipeline_generate_data.py
[2025-03-02T23:04:07.695+0000] {logging_mixin.py:149} INFO - [2025-03-02T23:04:07.690+0000] {dagbag.py:350} ERROR - Failed to import: /opt/airflow/dags/dag_pipeline_generate_data.py
Traceback (most recent call last):
  File "/home/airflow/.local/lib/python3.7/site-packages/airflow/models/dagbag.py", line 346, in parse
    loader.exec_module(new_module)
  File "<frozen importlib._bootstrap_external>", line 728, in exec_module
  File "<frozen importlib._bootstrap>", line 219, in _call_with_frames_removed
  File "/opt/airflow/dags/dag_pipeline_generate_data.py", line 26, in <module>
    dag=dag,
  File "/home/airflow/.local/lib/python3.7/site-packages/airflow/models/baseoperator.py", line 429, in apply_defaults
    result = func(self, **kwargs, default_args=default_args)
  File "/home/airflow/.local/lib/python3.7/site-packages/airflow/operators/python.py", line 168, in __init__
    raise AirflowException("`python_callable` param must be callable")
airflow.exceptions.AirflowException: `python_callable` param must be callable
[2025-03-02T23:04:07.696+0000] {processor.py:838} WARNING - No viable dags retrieved from /opt/airflow/dags/dag_pipeline_generate_data.py
[2025-03-02T23:04:07.996+0000] {processor.py:179} INFO - Processing /opt/airflow/dags/dag_pipeline_generate_data.py took 3.518 seconds
[2025-03-02T23:04:38.232+0000] {processor.py:157} INFO - Started process (PID=557) to work on /opt/airflow/dags/dag_pipeline_generate_data.py
[2025-03-02T23:04:38.233+0000] {processor.py:826} INFO - Processing file /opt/airflow/dags/dag_pipeline_generate_data.py for tasks to queue
[2025-03-02T23:04:38.234+0000] {logging_mixin.py:149} INFO - [2025-03-02T23:04:38.234+0000] {dagbag.py:541} INFO - Filling up the DagBag from /opt/airflow/dags/dag_pipeline_generate_data.py
[2025-03-02T23:04:41.744+0000] {logging_mixin.py:149} INFO - [2025-03-02T23:04:41.737+0000] {dagbag.py:350} ERROR - Failed to import: /opt/airflow/dags/dag_pipeline_generate_data.py
Traceback (most recent call last):
  File "/home/airflow/.local/lib/python3.7/site-packages/airflow/models/dagbag.py", line 346, in parse
    loader.exec_module(new_module)
  File "<frozen importlib._bootstrap_external>", line 728, in exec_module
  File "<frozen importlib._bootstrap>", line 219, in _call_with_frames_removed
  File "/opt/airflow/dags/dag_pipeline_generate_data.py", line 26, in <module>
    dag=dag,
  File "/home/airflow/.local/lib/python3.7/site-packages/airflow/models/baseoperator.py", line 429, in apply_defaults
    result = func(self, **kwargs, default_args=default_args)
  File "/home/airflow/.local/lib/python3.7/site-packages/airflow/operators/python.py", line 168, in __init__
    raise AirflowException("`python_callable` param must be callable")
airflow.exceptions.AirflowException: `python_callable` param must be callable
[2025-03-02T23:04:41.745+0000] {processor.py:838} WARNING - No viable dags retrieved from /opt/airflow/dags/dag_pipeline_generate_data.py
[2025-03-02T23:04:41.913+0000] {processor.py:179} INFO - Processing /opt/airflow/dags/dag_pipeline_generate_data.py took 3.684 seconds
[2025-03-02T23:05:12.518+0000] {processor.py:157} INFO - Started process (PID=588) to work on /opt/airflow/dags/dag_pipeline_generate_data.py
[2025-03-02T23:05:12.519+0000] {processor.py:826} INFO - Processing file /opt/airflow/dags/dag_pipeline_generate_data.py for tasks to queue
[2025-03-02T23:05:12.520+0000] {logging_mixin.py:149} INFO - [2025-03-02T23:05:12.519+0000] {dagbag.py:541} INFO - Filling up the DagBag from /opt/airflow/dags/dag_pipeline_generate_data.py
[2025-03-02T23:05:16.365+0000] {logging_mixin.py:149} INFO - [2025-03-02T23:05:16.359+0000] {dagbag.py:350} ERROR - Failed to import: /opt/airflow/dags/dag_pipeline_generate_data.py
Traceback (most recent call last):
  File "/home/airflow/.local/lib/python3.7/site-packages/airflow/models/dagbag.py", line 346, in parse
    loader.exec_module(new_module)
  File "<frozen importlib._bootstrap_external>", line 728, in exec_module
  File "<frozen importlib._bootstrap>", line 219, in _call_with_frames_removed
  File "/opt/airflow/dags/dag_pipeline_generate_data.py", line 26, in <module>
    dag=dag,
  File "/home/airflow/.local/lib/python3.7/site-packages/airflow/models/baseoperator.py", line 429, in apply_defaults
    result = func(self, **kwargs, default_args=default_args)
  File "/home/airflow/.local/lib/python3.7/site-packages/airflow/operators/python.py", line 168, in __init__
    raise AirflowException("`python_callable` param must be callable")
airflow.exceptions.AirflowException: `python_callable` param must be callable
[2025-03-02T23:05:16.365+0000] {processor.py:838} WARNING - No viable dags retrieved from /opt/airflow/dags/dag_pipeline_generate_data.py
[2025-03-02T23:05:17.383+0000] {processor.py:179} INFO - Processing /opt/airflow/dags/dag_pipeline_generate_data.py took 4.116 seconds
[2025-03-02T23:05:47.532+0000] {processor.py:157} INFO - Started process (PID=619) to work on /opt/airflow/dags/dag_pipeline_generate_data.py
[2025-03-02T23:05:47.533+0000] {processor.py:826} INFO - Processing file /opt/airflow/dags/dag_pipeline_generate_data.py for tasks to queue
[2025-03-02T23:05:47.534+0000] {logging_mixin.py:149} INFO - [2025-03-02T23:05:47.534+0000] {dagbag.py:541} INFO - Filling up the DagBag from /opt/airflow/dags/dag_pipeline_generate_data.py
[2025-03-02T23:05:54.339+0000] {logging_mixin.py:149} INFO - [2025-03-02T23:05:54.334+0000] {dagbag.py:350} ERROR - Failed to import: /opt/airflow/dags/dag_pipeline_generate_data.py
Traceback (most recent call last):
  File "/home/airflow/.local/lib/python3.7/site-packages/airflow/models/dagbag.py", line 346, in parse
    loader.exec_module(new_module)
  File "<frozen importlib._bootstrap_external>", line 728, in exec_module
  File "<frozen importlib._bootstrap>", line 219, in _call_with_frames_removed
  File "/opt/airflow/dags/dag_pipeline_generate_data.py", line 26, in <module>
    dag=dag,
  File "/home/airflow/.local/lib/python3.7/site-packages/airflow/models/baseoperator.py", line 429, in apply_defaults
    result = func(self, **kwargs, default_args=default_args)
  File "/home/airflow/.local/lib/python3.7/site-packages/airflow/operators/python.py", line 168, in __init__
    raise AirflowException("`python_callable` param must be callable")
airflow.exceptions.AirflowException: `python_callable` param must be callable
[2025-03-02T23:05:54.340+0000] {processor.py:838} WARNING - No viable dags retrieved from /opt/airflow/dags/dag_pipeline_generate_data.py
[2025-03-02T23:05:54.653+0000] {processor.py:179} INFO - Processing /opt/airflow/dags/dag_pipeline_generate_data.py took 4.468 seconds
[2025-03-02T23:06:25.252+0000] {processor.py:157} INFO - Started process (PID=650) to work on /opt/airflow/dags/dag_pipeline_generate_data.py
[2025-03-02T23:06:25.253+0000] {processor.py:826} INFO - Processing file /opt/airflow/dags/dag_pipeline_generate_data.py for tasks to queue
[2025-03-02T23:06:25.254+0000] {logging_mixin.py:149} INFO - [2025-03-02T23:06:25.254+0000] {dagbag.py:541} INFO - Filling up the DagBag from /opt/airflow/dags/dag_pipeline_generate_data.py
[2025-03-02T23:06:29.420+0000] {logging_mixin.py:149} INFO - [2025-03-02T23:06:29.414+0000] {dagbag.py:350} ERROR - Failed to import: /opt/airflow/dags/dag_pipeline_generate_data.py
Traceback (most recent call last):
  File "/home/airflow/.local/lib/python3.7/site-packages/airflow/models/dagbag.py", line 346, in parse
    loader.exec_module(new_module)
  File "<frozen importlib._bootstrap_external>", line 728, in exec_module
  File "<frozen importlib._bootstrap>", line 219, in _call_with_frames_removed
  File "/opt/airflow/dags/dag_pipeline_generate_data.py", line 26, in <module>
    dag=dag,
  File "/home/airflow/.local/lib/python3.7/site-packages/airflow/models/baseoperator.py", line 429, in apply_defaults
    result = func(self, **kwargs, default_args=default_args)
  File "/home/airflow/.local/lib/python3.7/site-packages/airflow/operators/python.py", line 168, in __init__
    raise AirflowException("`python_callable` param must be callable")
airflow.exceptions.AirflowException: `python_callable` param must be callable
[2025-03-02T23:06:29.421+0000] {processor.py:838} WARNING - No viable dags retrieved from /opt/airflow/dags/dag_pipeline_generate_data.py
[2025-03-02T23:06:29.659+0000] {processor.py:179} INFO - Processing /opt/airflow/dags/dag_pipeline_generate_data.py took 4.411 seconds
[2025-03-02T23:06:59.935+0000] {processor.py:157} INFO - Started process (PID=686) to work on /opt/airflow/dags/dag_pipeline_generate_data.py
[2025-03-02T23:06:59.936+0000] {processor.py:826} INFO - Processing file /opt/airflow/dags/dag_pipeline_generate_data.py for tasks to queue
[2025-03-02T23:06:59.937+0000] {logging_mixin.py:149} INFO - [2025-03-02T23:06:59.937+0000] {dagbag.py:541} INFO - Filling up the DagBag from /opt/airflow/dags/dag_pipeline_generate_data.py
[2025-03-02T23:07:03.649+0000] {logging_mixin.py:149} INFO - [2025-03-02T23:07:03.644+0000] {dagbag.py:350} ERROR - Failed to import: /opt/airflow/dags/dag_pipeline_generate_data.py
Traceback (most recent call last):
  File "/home/airflow/.local/lib/python3.7/site-packages/airflow/models/dagbag.py", line 346, in parse
    loader.exec_module(new_module)
  File "<frozen importlib._bootstrap_external>", line 728, in exec_module
  File "<frozen importlib._bootstrap>", line 219, in _call_with_frames_removed
  File "/opt/airflow/dags/dag_pipeline_generate_data.py", line 26, in <module>
    dag=dag,
  File "/home/airflow/.local/lib/python3.7/site-packages/airflow/models/baseoperator.py", line 429, in apply_defaults
    result = func(self, **kwargs, default_args=default_args)
  File "/home/airflow/.local/lib/python3.7/site-packages/airflow/operators/python.py", line 168, in __init__
    raise AirflowException("`python_callable` param must be callable")
airflow.exceptions.AirflowException: `python_callable` param must be callable
[2025-03-02T23:07:03.650+0000] {processor.py:838} WARNING - No viable dags retrieved from /opt/airflow/dags/dag_pipeline_generate_data.py
[2025-03-02T23:07:04.321+0000] {processor.py:179} INFO - Processing /opt/airflow/dags/dag_pipeline_generate_data.py took 4.388 seconds
[2025-03-02T23:07:35.074+0000] {processor.py:157} INFO - Started process (PID=717) to work on /opt/airflow/dags/dag_pipeline_generate_data.py
[2025-03-02T23:07:35.075+0000] {processor.py:826} INFO - Processing file /opt/airflow/dags/dag_pipeline_generate_data.py for tasks to queue
[2025-03-02T23:07:35.076+0000] {logging_mixin.py:149} INFO - [2025-03-02T23:07:35.075+0000] {dagbag.py:541} INFO - Filling up the DagBag from /opt/airflow/dags/dag_pipeline_generate_data.py
[2025-03-02T23:07:38.901+0000] {logging_mixin.py:149} INFO - [2025-03-02T23:07:38.895+0000] {dagbag.py:350} ERROR - Failed to import: /opt/airflow/dags/dag_pipeline_generate_data.py
Traceback (most recent call last):
  File "/home/airflow/.local/lib/python3.7/site-packages/airflow/models/dagbag.py", line 346, in parse
    loader.exec_module(new_module)
  File "<frozen importlib._bootstrap_external>", line 728, in exec_module
  File "<frozen importlib._bootstrap>", line 219, in _call_with_frames_removed
  File "/opt/airflow/dags/dag_pipeline_generate_data.py", line 26, in <module>
    dag=dag,
  File "/home/airflow/.local/lib/python3.7/site-packages/airflow/models/baseoperator.py", line 429, in apply_defaults
    result = func(self, **kwargs, default_args=default_args)
  File "/home/airflow/.local/lib/python3.7/site-packages/airflow/operators/python.py", line 168, in __init__
    raise AirflowException("`python_callable` param must be callable")
airflow.exceptions.AirflowException: `python_callable` param must be callable
[2025-03-02T23:07:38.902+0000] {processor.py:838} WARNING - No viable dags retrieved from /opt/airflow/dags/dag_pipeline_generate_data.py
[2025-03-02T23:07:39.406+0000] {processor.py:179} INFO - Processing /opt/airflow/dags/dag_pipeline_generate_data.py took 4.335 seconds
[2025-03-02T23:08:09.829+0000] {processor.py:157} INFO - Started process (PID=748) to work on /opt/airflow/dags/dag_pipeline_generate_data.py
[2025-03-02T23:08:09.830+0000] {processor.py:826} INFO - Processing file /opt/airflow/dags/dag_pipeline_generate_data.py for tasks to queue
[2025-03-02T23:08:09.830+0000] {logging_mixin.py:149} INFO - [2025-03-02T23:08:09.830+0000] {dagbag.py:541} INFO - Filling up the DagBag from /opt/airflow/dags/dag_pipeline_generate_data.py
[2025-03-02T23:08:15.818+0000] {logging_mixin.py:149} INFO - [2025-03-02T23:08:15.813+0000] {dagbag.py:350} ERROR - Failed to import: /opt/airflow/dags/dag_pipeline_generate_data.py
Traceback (most recent call last):
  File "/home/airflow/.local/lib/python3.7/site-packages/airflow/models/dagbag.py", line 346, in parse
    loader.exec_module(new_module)
  File "<frozen importlib._bootstrap_external>", line 728, in exec_module
  File "<frozen importlib._bootstrap>", line 219, in _call_with_frames_removed
  File "/opt/airflow/dags/dag_pipeline_generate_data.py", line 26, in <module>
    dag=dag,
  File "/home/airflow/.local/lib/python3.7/site-packages/airflow/models/baseoperator.py", line 429, in apply_defaults
    result = func(self, **kwargs, default_args=default_args)
  File "/home/airflow/.local/lib/python3.7/site-packages/airflow/operators/python.py", line 168, in __init__
    raise AirflowException("`python_callable` param must be callable")
airflow.exceptions.AirflowException: `python_callable` param must be callable
[2025-03-02T23:08:15.822+0000] {processor.py:838} WARNING - No viable dags retrieved from /opt/airflow/dags/dag_pipeline_generate_data.py
[2025-03-02T23:08:16.104+0000] {processor.py:179} INFO - Processing /opt/airflow/dags/dag_pipeline_generate_data.py took 6.278 seconds
[2025-03-02T23:08:46.385+0000] {processor.py:157} INFO - Started process (PID=779) to work on /opt/airflow/dags/dag_pipeline_generate_data.py
[2025-03-02T23:08:46.386+0000] {processor.py:826} INFO - Processing file /opt/airflow/dags/dag_pipeline_generate_data.py for tasks to queue
[2025-03-02T23:08:46.387+0000] {logging_mixin.py:149} INFO - [2025-03-02T23:08:46.387+0000] {dagbag.py:541} INFO - Filling up the DagBag from /opt/airflow/dags/dag_pipeline_generate_data.py
[2025-03-02T23:08:50.226+0000] {logging_mixin.py:149} INFO - [2025-03-02T23:08:50.221+0000] {dagbag.py:350} ERROR - Failed to import: /opt/airflow/dags/dag_pipeline_generate_data.py
Traceback (most recent call last):
  File "/home/airflow/.local/lib/python3.7/site-packages/airflow/models/dagbag.py", line 346, in parse
    loader.exec_module(new_module)
  File "<frozen importlib._bootstrap_external>", line 728, in exec_module
  File "<frozen importlib._bootstrap>", line 219, in _call_with_frames_removed
  File "/opt/airflow/dags/dag_pipeline_generate_data.py", line 26, in <module>
    dag=dag,
  File "/home/airflow/.local/lib/python3.7/site-packages/airflow/models/baseoperator.py", line 429, in apply_defaults
    result = func(self, **kwargs, default_args=default_args)
  File "/home/airflow/.local/lib/python3.7/site-packages/airflow/operators/python.py", line 168, in __init__
    raise AirflowException("`python_callable` param must be callable")
airflow.exceptions.AirflowException: `python_callable` param must be callable
[2025-03-02T23:08:50.227+0000] {processor.py:838} WARNING - No viable dags retrieved from /opt/airflow/dags/dag_pipeline_generate_data.py
[2025-03-02T23:08:50.582+0000] {processor.py:179} INFO - Processing /opt/airflow/dags/dag_pipeline_generate_data.py took 4.200 seconds
[2025-03-02T23:09:20.854+0000] {processor.py:157} INFO - Started process (PID=810) to work on /opt/airflow/dags/dag_pipeline_generate_data.py
[2025-03-02T23:09:20.855+0000] {processor.py:826} INFO - Processing file /opt/airflow/dags/dag_pipeline_generate_data.py for tasks to queue
[2025-03-02T23:09:20.856+0000] {logging_mixin.py:149} INFO - [2025-03-02T23:09:20.855+0000] {dagbag.py:541} INFO - Filling up the DagBag from /opt/airflow/dags/dag_pipeline_generate_data.py
[2025-03-02T23:09:24.025+0000] {logging_mixin.py:149} INFO - [2025-03-02T23:09:24.019+0000] {dagbag.py:350} ERROR - Failed to import: /opt/airflow/dags/dag_pipeline_generate_data.py
Traceback (most recent call last):
  File "/home/airflow/.local/lib/python3.7/site-packages/airflow/models/dagbag.py", line 346, in parse
    loader.exec_module(new_module)
  File "<frozen importlib._bootstrap_external>", line 728, in exec_module
  File "<frozen importlib._bootstrap>", line 219, in _call_with_frames_removed
  File "/opt/airflow/dags/dag_pipeline_generate_data.py", line 26, in <module>
    dag=dag,
  File "/home/airflow/.local/lib/python3.7/site-packages/airflow/models/baseoperator.py", line 429, in apply_defaults
    result = func(self, **kwargs, default_args=default_args)
  File "/home/airflow/.local/lib/python3.7/site-packages/airflow/operators/python.py", line 168, in __init__
    raise AirflowException("`python_callable` param must be callable")
airflow.exceptions.AirflowException: `python_callable` param must be callable
[2025-03-02T23:09:24.025+0000] {processor.py:838} WARNING - No viable dags retrieved from /opt/airflow/dags/dag_pipeline_generate_data.py
[2025-03-02T23:09:24.265+0000] {processor.py:179} INFO - Processing /opt/airflow/dags/dag_pipeline_generate_data.py took 3.414 seconds
[2025-03-02T23:09:54.976+0000] {processor.py:157} INFO - Started process (PID=841) to work on /opt/airflow/dags/dag_pipeline_generate_data.py
[2025-03-02T23:09:54.977+0000] {processor.py:826} INFO - Processing file /opt/airflow/dags/dag_pipeline_generate_data.py for tasks to queue
[2025-03-02T23:09:54.977+0000] {logging_mixin.py:149} INFO - [2025-03-02T23:09:54.977+0000] {dagbag.py:541} INFO - Filling up the DagBag from /opt/airflow/dags/dag_pipeline_generate_data.py
[2025-03-02T23:09:58.056+0000] {logging_mixin.py:149} INFO - [2025-03-02T23:09:58.051+0000] {dagbag.py:350} ERROR - Failed to import: /opt/airflow/dags/dag_pipeline_generate_data.py
Traceback (most recent call last):
  File "/home/airflow/.local/lib/python3.7/site-packages/airflow/models/dagbag.py", line 346, in parse
    loader.exec_module(new_module)
  File "<frozen importlib._bootstrap_external>", line 728, in exec_module
  File "<frozen importlib._bootstrap>", line 219, in _call_with_frames_removed
  File "/opt/airflow/dags/dag_pipeline_generate_data.py", line 26, in <module>
    dag=dag,
  File "/home/airflow/.local/lib/python3.7/site-packages/airflow/models/baseoperator.py", line 429, in apply_defaults
    result = func(self, **kwargs, default_args=default_args)
  File "/home/airflow/.local/lib/python3.7/site-packages/airflow/operators/python.py", line 168, in __init__
    raise AirflowException("`python_callable` param must be callable")
airflow.exceptions.AirflowException: `python_callable` param must be callable
[2025-03-02T23:09:58.057+0000] {processor.py:838} WARNING - No viable dags retrieved from /opt/airflow/dags/dag_pipeline_generate_data.py
[2025-03-02T23:09:58.133+0000] {processor.py:179} INFO - Processing /opt/airflow/dags/dag_pipeline_generate_data.py took 3.160 seconds
[2025-03-02T23:10:28.387+0000] {processor.py:157} INFO - Started process (PID=872) to work on /opt/airflow/dags/dag_pipeline_generate_data.py
[2025-03-02T23:10:28.388+0000] {processor.py:826} INFO - Processing file /opt/airflow/dags/dag_pipeline_generate_data.py for tasks to queue
[2025-03-02T23:10:28.389+0000] {logging_mixin.py:149} INFO - [2025-03-02T23:10:28.389+0000] {dagbag.py:541} INFO - Filling up the DagBag from /opt/airflow/dags/dag_pipeline_generate_data.py
[2025-03-02T23:10:31.562+0000] {logging_mixin.py:149} INFO - [2025-03-02T23:10:31.557+0000] {dagbag.py:350} ERROR - Failed to import: /opt/airflow/dags/dag_pipeline_generate_data.py
Traceback (most recent call last):
  File "/home/airflow/.local/lib/python3.7/site-packages/airflow/models/dagbag.py", line 346, in parse
    loader.exec_module(new_module)
  File "<frozen importlib._bootstrap_external>", line 728, in exec_module
  File "<frozen importlib._bootstrap>", line 219, in _call_with_frames_removed
  File "/opt/airflow/dags/dag_pipeline_generate_data.py", line 26, in <module>
    dag=dag,
  File "/home/airflow/.local/lib/python3.7/site-packages/airflow/models/baseoperator.py", line 429, in apply_defaults
    result = func(self, **kwargs, default_args=default_args)
  File "/home/airflow/.local/lib/python3.7/site-packages/airflow/operators/python.py", line 168, in __init__
    raise AirflowException("`python_callable` param must be callable")
airflow.exceptions.AirflowException: `python_callable` param must be callable
[2025-03-02T23:10:31.562+0000] {processor.py:838} WARNING - No viable dags retrieved from /opt/airflow/dags/dag_pipeline_generate_data.py
[2025-03-02T23:10:32.572+0000] {processor.py:179} INFO - Processing /opt/airflow/dags/dag_pipeline_generate_data.py took 4.188 seconds
[2025-03-02T23:11:02.782+0000] {processor.py:157} INFO - Started process (PID=903) to work on /opt/airflow/dags/dag_pipeline_generate_data.py
[2025-03-02T23:11:02.783+0000] {processor.py:826} INFO - Processing file /opt/airflow/dags/dag_pipeline_generate_data.py for tasks to queue
[2025-03-02T23:11:02.784+0000] {logging_mixin.py:149} INFO - [2025-03-02T23:11:02.784+0000] {dagbag.py:541} INFO - Filling up the DagBag from /opt/airflow/dags/dag_pipeline_generate_data.py
[2025-03-02T23:11:05.947+0000] {logging_mixin.py:149} INFO - [2025-03-02T23:11:05.942+0000] {dagbag.py:350} ERROR - Failed to import: /opt/airflow/dags/dag_pipeline_generate_data.py
Traceback (most recent call last):
  File "/home/airflow/.local/lib/python3.7/site-packages/airflow/models/dagbag.py", line 346, in parse
    loader.exec_module(new_module)
  File "<frozen importlib._bootstrap_external>", line 728, in exec_module
  File "<frozen importlib._bootstrap>", line 219, in _call_with_frames_removed
  File "/opt/airflow/dags/dag_pipeline_generate_data.py", line 26, in <module>
    dag=dag,
  File "/home/airflow/.local/lib/python3.7/site-packages/airflow/models/baseoperator.py", line 429, in apply_defaults
    result = func(self, **kwargs, default_args=default_args)
  File "/home/airflow/.local/lib/python3.7/site-packages/airflow/operators/python.py", line 168, in __init__
    raise AirflowException("`python_callable` param must be callable")
airflow.exceptions.AirflowException: `python_callable` param must be callable
[2025-03-02T23:11:05.947+0000] {processor.py:838} WARNING - No viable dags retrieved from /opt/airflow/dags/dag_pipeline_generate_data.py
[2025-03-02T23:11:06.910+0000] {processor.py:179} INFO - Processing /opt/airflow/dags/dag_pipeline_generate_data.py took 4.131 seconds
[2025-03-02T23:11:36.985+0000] {processor.py:157} INFO - Started process (PID=934) to work on /opt/airflow/dags/dag_pipeline_generate_data.py
[2025-03-02T23:11:36.987+0000] {processor.py:826} INFO - Processing file /opt/airflow/dags/dag_pipeline_generate_data.py for tasks to queue
[2025-03-02T23:11:36.988+0000] {logging_mixin.py:149} INFO - [2025-03-02T23:11:36.988+0000] {dagbag.py:541} INFO - Filling up the DagBag from /opt/airflow/dags/dag_pipeline_generate_data.py
[2025-03-02T23:11:41.003+0000] {logging_mixin.py:149} INFO - [2025-03-02T23:11:40.994+0000] {dagbag.py:350} ERROR - Failed to import: /opt/airflow/dags/dag_pipeline_generate_data.py
Traceback (most recent call last):
  File "/home/airflow/.local/lib/python3.7/site-packages/airflow/models/dagbag.py", line 346, in parse
    loader.exec_module(new_module)
  File "<frozen importlib._bootstrap_external>", line 728, in exec_module
  File "<frozen importlib._bootstrap>", line 219, in _call_with_frames_removed
  File "/opt/airflow/dags/dag_pipeline_generate_data.py", line 26, in <module>
    dag=dag,
  File "/home/airflow/.local/lib/python3.7/site-packages/airflow/models/baseoperator.py", line 429, in apply_defaults
    result = func(self, **kwargs, default_args=default_args)
  File "/home/airflow/.local/lib/python3.7/site-packages/airflow/operators/python.py", line 168, in __init__
    raise AirflowException("`python_callable` param must be callable")
airflow.exceptions.AirflowException: `python_callable` param must be callable
[2025-03-02T23:11:41.004+0000] {processor.py:838} WARNING - No viable dags retrieved from /opt/airflow/dags/dag_pipeline_generate_data.py
[2025-03-02T23:11:41.557+0000] {processor.py:179} INFO - Processing /opt/airflow/dags/dag_pipeline_generate_data.py took 4.577 seconds
[2025-03-02T23:12:11.849+0000] {processor.py:157} INFO - Started process (PID=965) to work on /opt/airflow/dags/dag_pipeline_generate_data.py
[2025-03-02T23:12:11.850+0000] {processor.py:826} INFO - Processing file /opt/airflow/dags/dag_pipeline_generate_data.py for tasks to queue
[2025-03-02T23:12:11.851+0000] {logging_mixin.py:149} INFO - [2025-03-02T23:12:11.851+0000] {dagbag.py:541} INFO - Filling up the DagBag from /opt/airflow/dags/dag_pipeline_generate_data.py
[2025-03-02T23:12:17.376+0000] {logging_mixin.py:149} INFO - [2025-03-02T23:12:17.372+0000] {dagbag.py:350} ERROR - Failed to import: /opt/airflow/dags/dag_pipeline_generate_data.py
Traceback (most recent call last):
  File "/home/airflow/.local/lib/python3.7/site-packages/airflow/models/dagbag.py", line 346, in parse
    loader.exec_module(new_module)
  File "<frozen importlib._bootstrap_external>", line 728, in exec_module
  File "<frozen importlib._bootstrap>", line 219, in _call_with_frames_removed
  File "/opt/airflow/dags/dag_pipeline_generate_data.py", line 26, in <module>
    dag=dag,
  File "/home/airflow/.local/lib/python3.7/site-packages/airflow/models/baseoperator.py", line 429, in apply_defaults
    result = func(self, **kwargs, default_args=default_args)
  File "/home/airflow/.local/lib/python3.7/site-packages/airflow/operators/python.py", line 168, in __init__
    raise AirflowException("`python_callable` param must be callable")
airflow.exceptions.AirflowException: `python_callable` param must be callable
[2025-03-02T23:12:17.377+0000] {processor.py:838} WARNING - No viable dags retrieved from /opt/airflow/dags/dag_pipeline_generate_data.py
[2025-03-02T23:12:17.485+0000] {processor.py:179} INFO - Processing /opt/airflow/dags/dag_pipeline_generate_data.py took 5.639 seconds
[2025-03-02T23:12:48.024+0000] {processor.py:157} INFO - Started process (PID=996) to work on /opt/airflow/dags/dag_pipeline_generate_data.py
[2025-03-02T23:12:48.025+0000] {processor.py:826} INFO - Processing file /opt/airflow/dags/dag_pipeline_generate_data.py for tasks to queue
[2025-03-02T23:12:48.026+0000] {logging_mixin.py:149} INFO - [2025-03-02T23:12:48.026+0000] {dagbag.py:541} INFO - Filling up the DagBag from /opt/airflow/dags/dag_pipeline_generate_data.py
[2025-03-02T23:12:52.030+0000] {logging_mixin.py:149} INFO - [2025-03-02T23:12:52.024+0000] {dagbag.py:350} ERROR - Failed to import: /opt/airflow/dags/dag_pipeline_generate_data.py
Traceback (most recent call last):
  File "/home/airflow/.local/lib/python3.7/site-packages/airflow/models/dagbag.py", line 346, in parse
    loader.exec_module(new_module)
  File "<frozen importlib._bootstrap_external>", line 728, in exec_module
  File "<frozen importlib._bootstrap>", line 219, in _call_with_frames_removed
  File "/opt/airflow/dags/dag_pipeline_generate_data.py", line 26, in <module>
    dag=dag,
  File "/home/airflow/.local/lib/python3.7/site-packages/airflow/models/baseoperator.py", line 429, in apply_defaults
    result = func(self, **kwargs, default_args=default_args)
  File "/home/airflow/.local/lib/python3.7/site-packages/airflow/operators/python.py", line 168, in __init__
    raise AirflowException("`python_callable` param must be callable")
airflow.exceptions.AirflowException: `python_callable` param must be callable
[2025-03-02T23:12:52.030+0000] {processor.py:838} WARNING - No viable dags retrieved from /opt/airflow/dags/dag_pipeline_generate_data.py
[2025-03-02T23:12:52.423+0000] {processor.py:179} INFO - Processing /opt/airflow/dags/dag_pipeline_generate_data.py took 4.402 seconds
[2025-03-02T23:13:22.663+0000] {processor.py:157} INFO - Started process (PID=1027) to work on /opt/airflow/dags/dag_pipeline_generate_data.py
[2025-03-02T23:13:22.664+0000] {processor.py:826} INFO - Processing file /opt/airflow/dags/dag_pipeline_generate_data.py for tasks to queue
[2025-03-02T23:13:22.666+0000] {logging_mixin.py:149} INFO - [2025-03-02T23:13:22.665+0000] {dagbag.py:541} INFO - Filling up the DagBag from /opt/airflow/dags/dag_pipeline_generate_data.py
[2025-03-02T23:13:26.079+0000] {logging_mixin.py:149} INFO - [2025-03-02T23:13:26.072+0000] {dagbag.py:350} ERROR - Failed to import: /opt/airflow/dags/dag_pipeline_generate_data.py
Traceback (most recent call last):
  File "/home/airflow/.local/lib/python3.7/site-packages/airflow/models/dagbag.py", line 346, in parse
    loader.exec_module(new_module)
  File "<frozen importlib._bootstrap_external>", line 728, in exec_module
  File "<frozen importlib._bootstrap>", line 219, in _call_with_frames_removed
  File "/opt/airflow/dags/dag_pipeline_generate_data.py", line 26, in <module>
    dag=dag,
  File "/home/airflow/.local/lib/python3.7/site-packages/airflow/models/baseoperator.py", line 429, in apply_defaults
    result = func(self, **kwargs, default_args=default_args)
  File "/home/airflow/.local/lib/python3.7/site-packages/airflow/operators/python.py", line 168, in __init__
    raise AirflowException("`python_callable` param must be callable")
airflow.exceptions.AirflowException: `python_callable` param must be callable
[2025-03-02T23:13:26.080+0000] {processor.py:838} WARNING - No viable dags retrieved from /opt/airflow/dags/dag_pipeline_generate_data.py
[2025-03-02T23:13:26.531+0000] {processor.py:179} INFO - Processing /opt/airflow/dags/dag_pipeline_generate_data.py took 3.874 seconds
[2025-03-02T23:13:57.024+0000] {processor.py:157} INFO - Started process (PID=1058) to work on /opt/airflow/dags/dag_pipeline_generate_data.py
[2025-03-02T23:13:57.025+0000] {processor.py:826} INFO - Processing file /opt/airflow/dags/dag_pipeline_generate_data.py for tasks to queue
[2025-03-02T23:13:57.026+0000] {logging_mixin.py:149} INFO - [2025-03-02T23:13:57.026+0000] {dagbag.py:541} INFO - Filling up the DagBag from /opt/airflow/dags/dag_pipeline_generate_data.py
[2025-03-02T23:14:00.778+0000] {logging_mixin.py:149} INFO - [2025-03-02T23:14:00.773+0000] {dagbag.py:350} ERROR - Failed to import: /opt/airflow/dags/dag_pipeline_generate_data.py
Traceback (most recent call last):
  File "/home/airflow/.local/lib/python3.7/site-packages/airflow/models/dagbag.py", line 346, in parse
    loader.exec_module(new_module)
  File "<frozen importlib._bootstrap_external>", line 728, in exec_module
  File "<frozen importlib._bootstrap>", line 219, in _call_with_frames_removed
  File "/opt/airflow/dags/dag_pipeline_generate_data.py", line 26, in <module>
    dag=dag,
  File "/home/airflow/.local/lib/python3.7/site-packages/airflow/models/baseoperator.py", line 429, in apply_defaults
    result = func(self, **kwargs, default_args=default_args)
  File "/home/airflow/.local/lib/python3.7/site-packages/airflow/operators/python.py", line 168, in __init__
    raise AirflowException("`python_callable` param must be callable")
airflow.exceptions.AirflowException: `python_callable` param must be callable
[2025-03-02T23:14:00.778+0000] {processor.py:838} WARNING - No viable dags retrieved from /opt/airflow/dags/dag_pipeline_generate_data.py
[2025-03-02T23:14:04.465+0000] {processor.py:179} INFO - Processing /opt/airflow/dags/dag_pipeline_generate_data.py took 4.680 seconds
[2025-03-02T23:14:34.697+0000] {processor.py:157} INFO - Started process (PID=1089) to work on /opt/airflow/dags/dag_pipeline_generate_data.py
[2025-03-02T23:14:34.698+0000] {processor.py:826} INFO - Processing file /opt/airflow/dags/dag_pipeline_generate_data.py for tasks to queue
[2025-03-02T23:14:34.700+0000] {logging_mixin.py:149} INFO - [2025-03-02T23:14:34.699+0000] {dagbag.py:541} INFO - Filling up the DagBag from /opt/airflow/dags/dag_pipeline_generate_data.py
[2025-03-02T23:14:39.794+0000] {logging_mixin.py:149} INFO - [2025-03-02T23:14:39.788+0000] {dagbag.py:350} ERROR - Failed to import: /opt/airflow/dags/dag_pipeline_generate_data.py
Traceback (most recent call last):
  File "/home/airflow/.local/lib/python3.7/site-packages/airflow/models/dagbag.py", line 346, in parse
    loader.exec_module(new_module)
  File "<frozen importlib._bootstrap_external>", line 728, in exec_module
  File "<frozen importlib._bootstrap>", line 219, in _call_with_frames_removed
  File "/opt/airflow/dags/dag_pipeline_generate_data.py", line 26, in <module>
    dag=dag,
  File "/home/airflow/.local/lib/python3.7/site-packages/airflow/models/baseoperator.py", line 429, in apply_defaults
    result = func(self, **kwargs, default_args=default_args)
  File "/home/airflow/.local/lib/python3.7/site-packages/airflow/operators/python.py", line 168, in __init__
    raise AirflowException("`python_callable` param must be callable")
airflow.exceptions.AirflowException: `python_callable` param must be callable
[2025-03-02T23:14:39.795+0000] {processor.py:838} WARNING - No viable dags retrieved from /opt/airflow/dags/dag_pipeline_generate_data.py
[2025-03-02T23:14:40.113+0000] {processor.py:179} INFO - Processing /opt/airflow/dags/dag_pipeline_generate_data.py took 3.507 seconds
[2025-03-02T23:15:10.216+0000] {processor.py:157} INFO - Started process (PID=1125) to work on /opt/airflow/dags/dag_pipeline_generate_data.py
[2025-03-02T23:15:10.217+0000] {processor.py:826} INFO - Processing file /opt/airflow/dags/dag_pipeline_generate_data.py for tasks to queue
[2025-03-02T23:15:10.218+0000] {logging_mixin.py:149} INFO - [2025-03-02T23:15:10.218+0000] {dagbag.py:541} INFO - Filling up the DagBag from /opt/airflow/dags/dag_pipeline_generate_data.py
[2025-03-02T23:15:13.541+0000] {logging_mixin.py:149} INFO - [2025-03-02T23:15:13.536+0000] {dagbag.py:350} ERROR - Failed to import: /opt/airflow/dags/dag_pipeline_generate_data.py
Traceback (most recent call last):
  File "/home/airflow/.local/lib/python3.7/site-packages/airflow/models/dagbag.py", line 346, in parse
    loader.exec_module(new_module)
  File "<frozen importlib._bootstrap_external>", line 728, in exec_module
  File "<frozen importlib._bootstrap>", line 219, in _call_with_frames_removed
  File "/opt/airflow/dags/dag_pipeline_generate_data.py", line 26, in <module>
    dag=dag,
  File "/home/airflow/.local/lib/python3.7/site-packages/airflow/models/baseoperator.py", line 429, in apply_defaults
    result = func(self, **kwargs, default_args=default_args)
  File "/home/airflow/.local/lib/python3.7/site-packages/airflow/operators/python.py", line 168, in __init__
    raise AirflowException("`python_callable` param must be callable")
airflow.exceptions.AirflowException: `python_callable` param must be callable
[2025-03-02T23:15:13.541+0000] {processor.py:838} WARNING - No viable dags retrieved from /opt/airflow/dags/dag_pipeline_generate_data.py
[2025-03-02T23:15:13.888+0000] {processor.py:179} INFO - Processing /opt/airflow/dags/dag_pipeline_generate_data.py took 3.675 seconds
[2025-03-02T23:15:44.041+0000] {processor.py:157} INFO - Started process (PID=1156) to work on /opt/airflow/dags/dag_pipeline_generate_data.py
[2025-03-02T23:15:44.042+0000] {processor.py:826} INFO - Processing file /opt/airflow/dags/dag_pipeline_generate_data.py for tasks to queue
[2025-03-02T23:15:44.043+0000] {logging_mixin.py:149} INFO - [2025-03-02T23:15:44.043+0000] {dagbag.py:541} INFO - Filling up the DagBag from /opt/airflow/dags/dag_pipeline_generate_data.py
[2025-03-02T23:15:47.493+0000] {logging_mixin.py:149} INFO - [2025-03-02T23:15:47.487+0000] {dagbag.py:350} ERROR - Failed to import: /opt/airflow/dags/dag_pipeline_generate_data.py
Traceback (most recent call last):
  File "/home/airflow/.local/lib/python3.7/site-packages/airflow/models/dagbag.py", line 346, in parse
    loader.exec_module(new_module)
  File "<frozen importlib._bootstrap_external>", line 728, in exec_module
  File "<frozen importlib._bootstrap>", line 219, in _call_with_frames_removed
  File "/opt/airflow/dags/dag_pipeline_generate_data.py", line 26, in <module>
    dag=dag,
  File "/home/airflow/.local/lib/python3.7/site-packages/airflow/models/baseoperator.py", line 429, in apply_defaults
    result = func(self, **kwargs, default_args=default_args)
  File "/home/airflow/.local/lib/python3.7/site-packages/airflow/operators/python.py", line 168, in __init__
    raise AirflowException("`python_callable` param must be callable")
airflow.exceptions.AirflowException: `python_callable` param must be callable
[2025-03-02T23:15:47.493+0000] {processor.py:838} WARNING - No viable dags retrieved from /opt/airflow/dags/dag_pipeline_generate_data.py
[2025-03-02T23:15:47.726+0000] {processor.py:179} INFO - Processing /opt/airflow/dags/dag_pipeline_generate_data.py took 3.688 seconds
[2025-03-02T23:16:17.883+0000] {processor.py:157} INFO - Started process (PID=1187) to work on /opt/airflow/dags/dag_pipeline_generate_data.py
[2025-03-02T23:16:17.884+0000] {processor.py:826} INFO - Processing file /opt/airflow/dags/dag_pipeline_generate_data.py for tasks to queue
[2025-03-02T23:16:17.884+0000] {logging_mixin.py:149} INFO - [2025-03-02T23:16:17.884+0000] {dagbag.py:541} INFO - Filling up the DagBag from /opt/airflow/dags/dag_pipeline_generate_data.py
[2025-03-02T23:16:20.996+0000] {logging_mixin.py:149} INFO - [2025-03-02T23:16:20.990+0000] {dagbag.py:350} ERROR - Failed to import: /opt/airflow/dags/dag_pipeline_generate_data.py
Traceback (most recent call last):
  File "/home/airflow/.local/lib/python3.7/site-packages/airflow/models/dagbag.py", line 346, in parse
    loader.exec_module(new_module)
  File "<frozen importlib._bootstrap_external>", line 728, in exec_module
  File "<frozen importlib._bootstrap>", line 219, in _call_with_frames_removed
  File "/opt/airflow/dags/dag_pipeline_generate_data.py", line 26, in <module>
    dag=dag,
  File "/home/airflow/.local/lib/python3.7/site-packages/airflow/models/baseoperator.py", line 429, in apply_defaults
    result = func(self, **kwargs, default_args=default_args)
  File "/home/airflow/.local/lib/python3.7/site-packages/airflow/operators/python.py", line 168, in __init__
    raise AirflowException("`python_callable` param must be callable")
airflow.exceptions.AirflowException: `python_callable` param must be callable
[2025-03-02T23:16:20.996+0000] {processor.py:838} WARNING - No viable dags retrieved from /opt/airflow/dags/dag_pipeline_generate_data.py
[2025-03-02T23:16:21.245+0000] {processor.py:179} INFO - Processing /opt/airflow/dags/dag_pipeline_generate_data.py took 3.366 seconds
[2025-03-02T23:16:51.606+0000] {processor.py:157} INFO - Started process (PID=1218) to work on /opt/airflow/dags/dag_pipeline_generate_data.py
[2025-03-02T23:16:51.607+0000] {processor.py:826} INFO - Processing file /opt/airflow/dags/dag_pipeline_generate_data.py for tasks to queue
[2025-03-02T23:16:51.608+0000] {logging_mixin.py:149} INFO - [2025-03-02T23:16:51.608+0000] {dagbag.py:541} INFO - Filling up the DagBag from /opt/airflow/dags/dag_pipeline_generate_data.py
[2025-03-02T23:16:55.522+0000] {logging_mixin.py:149} INFO - [2025-03-02T23:16:55.516+0000] {dagbag.py:350} ERROR - Failed to import: /opt/airflow/dags/dag_pipeline_generate_data.py
Traceback (most recent call last):
  File "/home/airflow/.local/lib/python3.7/site-packages/airflow/models/dagbag.py", line 346, in parse
    loader.exec_module(new_module)
  File "<frozen importlib._bootstrap_external>", line 728, in exec_module
  File "<frozen importlib._bootstrap>", line 219, in _call_with_frames_removed
  File "/opt/airflow/dags/dag_pipeline_generate_data.py", line 26, in <module>
    dag=dag,
  File "/home/airflow/.local/lib/python3.7/site-packages/airflow/models/baseoperator.py", line 429, in apply_defaults
    result = func(self, **kwargs, default_args=default_args)
  File "/home/airflow/.local/lib/python3.7/site-packages/airflow/operators/python.py", line 168, in __init__
    raise AirflowException("`python_callable` param must be callable")
airflow.exceptions.AirflowException: `python_callable` param must be callable
[2025-03-02T23:16:55.522+0000] {processor.py:838} WARNING - No viable dags retrieved from /opt/airflow/dags/dag_pipeline_generate_data.py
[2025-03-02T23:16:55.824+0000] {processor.py:179} INFO - Processing /opt/airflow/dags/dag_pipeline_generate_data.py took 4.222 seconds
[2025-03-02T23:17:26.053+0000] {processor.py:157} INFO - Started process (PID=1249) to work on /opt/airflow/dags/dag_pipeline_generate_data.py
[2025-03-02T23:17:26.054+0000] {processor.py:826} INFO - Processing file /opt/airflow/dags/dag_pipeline_generate_data.py for tasks to queue
[2025-03-02T23:17:26.055+0000] {logging_mixin.py:149} INFO - [2025-03-02T23:17:26.055+0000] {dagbag.py:541} INFO - Filling up the DagBag from /opt/airflow/dags/dag_pipeline_generate_data.py
[2025-03-02T23:17:29.089+0000] {logging_mixin.py:149} INFO - [2025-03-02T23:17:29.083+0000] {dagbag.py:350} ERROR - Failed to import: /opt/airflow/dags/dag_pipeline_generate_data.py
Traceback (most recent call last):
  File "/home/airflow/.local/lib/python3.7/site-packages/airflow/models/dagbag.py", line 346, in parse
    loader.exec_module(new_module)
  File "<frozen importlib._bootstrap_external>", line 728, in exec_module
  File "<frozen importlib._bootstrap>", line 219, in _call_with_frames_removed
  File "/opt/airflow/dags/dag_pipeline_generate_data.py", line 26, in <module>
    dag=dag,
  File "/home/airflow/.local/lib/python3.7/site-packages/airflow/models/baseoperator.py", line 429, in apply_defaults
    result = func(self, **kwargs, default_args=default_args)
  File "/home/airflow/.local/lib/python3.7/site-packages/airflow/operators/python.py", line 168, in __init__
    raise AirflowException("`python_callable` param must be callable")
airflow.exceptions.AirflowException: `python_callable` param must be callable
[2025-03-02T23:17:29.089+0000] {processor.py:838} WARNING - No viable dags retrieved from /opt/airflow/dags/dag_pipeline_generate_data.py
[2025-03-02T23:17:29.895+0000] {processor.py:179} INFO - Processing /opt/airflow/dags/dag_pipeline_generate_data.py took 3.845 seconds
[2025-03-02T23:18:00.135+0000] {processor.py:157} INFO - Started process (PID=1280) to work on /opt/airflow/dags/dag_pipeline_generate_data.py
[2025-03-02T23:18:00.136+0000] {processor.py:826} INFO - Processing file /opt/airflow/dags/dag_pipeline_generate_data.py for tasks to queue
[2025-03-02T23:18:00.138+0000] {logging_mixin.py:149} INFO - [2025-03-02T23:18:00.137+0000] {dagbag.py:541} INFO - Filling up the DagBag from /opt/airflow/dags/dag_pipeline_generate_data.py
[2025-03-02T23:18:03.827+0000] {logging_mixin.py:149} INFO - [2025-03-02T23:18:03.819+0000] {dagbag.py:350} ERROR - Failed to import: /opt/airflow/dags/dag_pipeline_generate_data.py
Traceback (most recent call last):
  File "/home/airflow/.local/lib/python3.7/site-packages/airflow/models/dagbag.py", line 346, in parse
    loader.exec_module(new_module)
  File "<frozen importlib._bootstrap_external>", line 728, in exec_module
  File "<frozen importlib._bootstrap>", line 219, in _call_with_frames_removed
  File "/opt/airflow/dags/dag_pipeline_generate_data.py", line 26, in <module>
    dag=dag,
  File "/home/airflow/.local/lib/python3.7/site-packages/airflow/models/baseoperator.py", line 429, in apply_defaults
    result = func(self, **kwargs, default_args=default_args)
  File "/home/airflow/.local/lib/python3.7/site-packages/airflow/operators/python.py", line 168, in __init__
    raise AirflowException("`python_callable` param must be callable")
airflow.exceptions.AirflowException: `python_callable` param must be callable
[2025-03-02T23:18:03.828+0000] {processor.py:838} WARNING - No viable dags retrieved from /opt/airflow/dags/dag_pipeline_generate_data.py
[2025-03-02T23:18:05.097+0000] {processor.py:179} INFO - Processing /opt/airflow/dags/dag_pipeline_generate_data.py took 4.966 seconds
[2025-03-02T23:18:35.651+0000] {processor.py:157} INFO - Started process (PID=1311) to work on /opt/airflow/dags/dag_pipeline_generate_data.py
[2025-03-02T23:18:35.652+0000] {processor.py:826} INFO - Processing file /opt/airflow/dags/dag_pipeline_generate_data.py for tasks to queue
[2025-03-02T23:18:35.653+0000] {logging_mixin.py:149} INFO - [2025-03-02T23:18:35.653+0000] {dagbag.py:541} INFO - Filling up the DagBag from /opt/airflow/dags/dag_pipeline_generate_data.py
[2025-03-02T23:18:38.722+0000] {logging_mixin.py:149} INFO - [2025-03-02T23:18:38.717+0000] {dagbag.py:350} ERROR - Failed to import: /opt/airflow/dags/dag_pipeline_generate_data.py
Traceback (most recent call last):
  File "/home/airflow/.local/lib/python3.7/site-packages/airflow/models/dagbag.py", line 346, in parse
    loader.exec_module(new_module)
  File "<frozen importlib._bootstrap_external>", line 728, in exec_module
  File "<frozen importlib._bootstrap>", line 219, in _call_with_frames_removed
  File "/opt/airflow/dags/dag_pipeline_generate_data.py", line 26, in <module>
    dag=dag,
  File "/home/airflow/.local/lib/python3.7/site-packages/airflow/models/baseoperator.py", line 429, in apply_defaults
    result = func(self, **kwargs, default_args=default_args)
  File "/home/airflow/.local/lib/python3.7/site-packages/airflow/operators/python.py", line 168, in __init__
    raise AirflowException("`python_callable` param must be callable")
airflow.exceptions.AirflowException: `python_callable` param must be callable
[2025-03-02T23:18:38.723+0000] {processor.py:838} WARNING - No viable dags retrieved from /opt/airflow/dags/dag_pipeline_generate_data.py
[2025-03-02T23:18:38.947+0000] {processor.py:179} INFO - Processing /opt/airflow/dags/dag_pipeline_generate_data.py took 3.299 seconds
[2025-03-02T23:19:09.149+0000] {processor.py:157} INFO - Started process (PID=1342) to work on /opt/airflow/dags/dag_pipeline_generate_data.py
[2025-03-02T23:19:09.150+0000] {processor.py:826} INFO - Processing file /opt/airflow/dags/dag_pipeline_generate_data.py for tasks to queue
[2025-03-02T23:19:09.151+0000] {logging_mixin.py:149} INFO - [2025-03-02T23:19:09.151+0000] {dagbag.py:541} INFO - Filling up the DagBag from /opt/airflow/dags/dag_pipeline_generate_data.py
[2025-03-02T23:19:12.525+0000] {logging_mixin.py:149} INFO - [2025-03-02T23:19:12.519+0000] {dagbag.py:350} ERROR - Failed to import: /opt/airflow/dags/dag_pipeline_generate_data.py
Traceback (most recent call last):
  File "/home/airflow/.local/lib/python3.7/site-packages/airflow/models/dagbag.py", line 346, in parse
    loader.exec_module(new_module)
  File "<frozen importlib._bootstrap_external>", line 728, in exec_module
  File "<frozen importlib._bootstrap>", line 219, in _call_with_frames_removed
  File "/opt/airflow/dags/dag_pipeline_generate_data.py", line 26, in <module>
    dag=dag,
  File "/home/airflow/.local/lib/python3.7/site-packages/airflow/models/baseoperator.py", line 429, in apply_defaults
    result = func(self, **kwargs, default_args=default_args)
  File "/home/airflow/.local/lib/python3.7/site-packages/airflow/operators/python.py", line 168, in __init__
    raise AirflowException("`python_callable` param must be callable")
airflow.exceptions.AirflowException: `python_callable` param must be callable
[2025-03-02T23:19:12.525+0000] {processor.py:838} WARNING - No viable dags retrieved from /opt/airflow/dags/dag_pipeline_generate_data.py
[2025-03-02T23:19:12.675+0000] {processor.py:179} INFO - Processing /opt/airflow/dags/dag_pipeline_generate_data.py took 3.530 seconds
[2025-03-02T23:19:43.090+0000] {processor.py:157} INFO - Started process (PID=1373) to work on /opt/airflow/dags/dag_pipeline_generate_data.py
[2025-03-02T23:19:43.091+0000] {processor.py:826} INFO - Processing file /opt/airflow/dags/dag_pipeline_generate_data.py for tasks to queue
[2025-03-02T23:19:43.092+0000] {logging_mixin.py:149} INFO - [2025-03-02T23:19:43.092+0000] {dagbag.py:541} INFO - Filling up the DagBag from /opt/airflow/dags/dag_pipeline_generate_data.py
[2025-03-02T23:19:46.833+0000] {logging_mixin.py:149} INFO - [2025-03-02T23:19:46.827+0000] {dagbag.py:350} ERROR - Failed to import: /opt/airflow/dags/dag_pipeline_generate_data.py
Traceback (most recent call last):
  File "/home/airflow/.local/lib/python3.7/site-packages/airflow/models/dagbag.py", line 346, in parse
    loader.exec_module(new_module)
  File "<frozen importlib._bootstrap_external>", line 728, in exec_module
  File "<frozen importlib._bootstrap>", line 219, in _call_with_frames_removed
  File "/opt/airflow/dags/dag_pipeline_generate_data.py", line 26, in <module>
    dag=dag,
  File "/home/airflow/.local/lib/python3.7/site-packages/airflow/models/baseoperator.py", line 429, in apply_defaults
    result = func(self, **kwargs, default_args=default_args)
  File "/home/airflow/.local/lib/python3.7/site-packages/airflow/operators/python.py", line 168, in __init__
    raise AirflowException("`python_callable` param must be callable")
airflow.exceptions.AirflowException: `python_callable` param must be callable
[2025-03-02T23:19:46.834+0000] {processor.py:838} WARNING - No viable dags retrieved from /opt/airflow/dags/dag_pipeline_generate_data.py
[2025-03-02T23:19:46.917+0000] {processor.py:179} INFO - Processing /opt/airflow/dags/dag_pipeline_generate_data.py took 3.830 seconds
[2025-03-02T23:20:17.707+0000] {processor.py:157} INFO - Started process (PID=1404) to work on /opt/airflow/dags/dag_pipeline_generate_data.py
[2025-03-02T23:20:17.708+0000] {processor.py:826} INFO - Processing file /opt/airflow/dags/dag_pipeline_generate_data.py for tasks to queue
[2025-03-02T23:20:17.709+0000] {logging_mixin.py:149} INFO - [2025-03-02T23:20:17.709+0000] {dagbag.py:541} INFO - Filling up the DagBag from /opt/airflow/dags/dag_pipeline_generate_data.py
[2025-03-02T23:20:21.137+0000] {logging_mixin.py:149} INFO - [2025-03-02T23:20:21.131+0000] {dagbag.py:350} ERROR - Failed to import: /opt/airflow/dags/dag_pipeline_generate_data.py
Traceback (most recent call last):
  File "/home/airflow/.local/lib/python3.7/site-packages/airflow/models/dagbag.py", line 346, in parse
    loader.exec_module(new_module)
  File "<frozen importlib._bootstrap_external>", line 728, in exec_module
  File "<frozen importlib._bootstrap>", line 219, in _call_with_frames_removed
  File "/opt/airflow/dags/dag_pipeline_generate_data.py", line 26, in <module>
    dag=dag,
  File "/home/airflow/.local/lib/python3.7/site-packages/airflow/models/baseoperator.py", line 429, in apply_defaults
    result = func(self, **kwargs, default_args=default_args)
  File "/home/airflow/.local/lib/python3.7/site-packages/airflow/operators/python.py", line 168, in __init__
    raise AirflowException("`python_callable` param must be callable")
airflow.exceptions.AirflowException: `python_callable` param must be callable
[2025-03-02T23:20:21.137+0000] {processor.py:838} WARNING - No viable dags retrieved from /opt/airflow/dags/dag_pipeline_generate_data.py
[2025-03-02T23:20:21.304+0000] {processor.py:179} INFO - Processing /opt/airflow/dags/dag_pipeline_generate_data.py took 3.600 seconds
[2025-03-02T23:20:51.890+0000] {processor.py:157} INFO - Started process (PID=1435) to work on /opt/airflow/dags/dag_pipeline_generate_data.py
[2025-03-02T23:20:51.891+0000] {processor.py:826} INFO - Processing file /opt/airflow/dags/dag_pipeline_generate_data.py for tasks to queue
[2025-03-02T23:20:51.892+0000] {logging_mixin.py:149} INFO - [2025-03-02T23:20:51.891+0000] {dagbag.py:541} INFO - Filling up the DagBag from /opt/airflow/dags/dag_pipeline_generate_data.py
[2025-03-02T23:20:55.007+0000] {logging_mixin.py:149} INFO - [2025-03-02T23:20:55.002+0000] {dagbag.py:350} ERROR - Failed to import: /opt/airflow/dags/dag_pipeline_generate_data.py
Traceback (most recent call last):
  File "/home/airflow/.local/lib/python3.7/site-packages/airflow/models/dagbag.py", line 346, in parse
    loader.exec_module(new_module)
  File "<frozen importlib._bootstrap_external>", line 728, in exec_module
  File "<frozen importlib._bootstrap>", line 219, in _call_with_frames_removed
  File "/opt/airflow/dags/dag_pipeline_generate_data.py", line 26, in <module>
    dag=dag,
  File "/home/airflow/.local/lib/python3.7/site-packages/airflow/models/baseoperator.py", line 429, in apply_defaults
    result = func(self, **kwargs, default_args=default_args)
  File "/home/airflow/.local/lib/python3.7/site-packages/airflow/operators/python.py", line 168, in __init__
    raise AirflowException("`python_callable` param must be callable")
airflow.exceptions.AirflowException: `python_callable` param must be callable
[2025-03-02T23:20:55.008+0000] {processor.py:838} WARNING - No viable dags retrieved from /opt/airflow/dags/dag_pipeline_generate_data.py
[2025-03-02T23:20:55.357+0000] {processor.py:179} INFO - Processing /opt/airflow/dags/dag_pipeline_generate_data.py took 3.470 seconds
[2025-03-02T23:21:25.900+0000] {processor.py:157} INFO - Started process (PID=1466) to work on /opt/airflow/dags/dag_pipeline_generate_data.py
[2025-03-02T23:21:25.901+0000] {processor.py:826} INFO - Processing file /opt/airflow/dags/dag_pipeline_generate_data.py for tasks to queue
[2025-03-02T23:21:25.902+0000] {logging_mixin.py:149} INFO - [2025-03-02T23:21:25.902+0000] {dagbag.py:541} INFO - Filling up the DagBag from /opt/airflow/dags/dag_pipeline_generate_data.py
[2025-03-02T23:21:29.091+0000] {logging_mixin.py:149} INFO - [2025-03-02T23:21:29.086+0000] {dagbag.py:350} ERROR - Failed to import: /opt/airflow/dags/dag_pipeline_generate_data.py
Traceback (most recent call last):
  File "/home/airflow/.local/lib/python3.7/site-packages/airflow/models/dagbag.py", line 346, in parse
    loader.exec_module(new_module)
  File "<frozen importlib._bootstrap_external>", line 728, in exec_module
  File "<frozen importlib._bootstrap>", line 219, in _call_with_frames_removed
  File "/opt/airflow/dags/dag_pipeline_generate_data.py", line 26, in <module>
    dag=dag,
  File "/home/airflow/.local/lib/python3.7/site-packages/airflow/models/baseoperator.py", line 429, in apply_defaults
    result = func(self, **kwargs, default_args=default_args)
  File "/home/airflow/.local/lib/python3.7/site-packages/airflow/operators/python.py", line 168, in __init__
    raise AirflowException("`python_callable` param must be callable")
airflow.exceptions.AirflowException: `python_callable` param must be callable
[2025-03-02T23:21:29.092+0000] {processor.py:838} WARNING - No viable dags retrieved from /opt/airflow/dags/dag_pipeline_generate_data.py
[2025-03-02T23:21:30.069+0000] {processor.py:179} INFO - Processing /opt/airflow/dags/dag_pipeline_generate_data.py took 4.171 seconds
[2025-03-02T23:22:00.318+0000] {processor.py:157} INFO - Started process (PID=1497) to work on /opt/airflow/dags/dag_pipeline_generate_data.py
[2025-03-02T23:22:00.319+0000] {processor.py:826} INFO - Processing file /opt/airflow/dags/dag_pipeline_generate_data.py for tasks to queue
[2025-03-02T23:22:00.320+0000] {logging_mixin.py:149} INFO - [2025-03-02T23:22:00.320+0000] {dagbag.py:541} INFO - Filling up the DagBag from /opt/airflow/dags/dag_pipeline_generate_data.py
[2025-03-02T23:22:04.074+0000] {logging_mixin.py:149} INFO - [2025-03-02T23:22:04.069+0000] {dagbag.py:350} ERROR - Failed to import: /opt/airflow/dags/dag_pipeline_generate_data.py
Traceback (most recent call last):
  File "/home/airflow/.local/lib/python3.7/site-packages/airflow/models/dagbag.py", line 346, in parse
    loader.exec_module(new_module)
  File "<frozen importlib._bootstrap_external>", line 728, in exec_module
  File "<frozen importlib._bootstrap>", line 219, in _call_with_frames_removed
  File "/opt/airflow/dags/dag_pipeline_generate_data.py", line 26, in <module>
    dag=dag,
  File "/home/airflow/.local/lib/python3.7/site-packages/airflow/models/baseoperator.py", line 429, in apply_defaults
    result = func(self, **kwargs, default_args=default_args)
  File "/home/airflow/.local/lib/python3.7/site-packages/airflow/operators/python.py", line 168, in __init__
    raise AirflowException("`python_callable` param must be callable")
airflow.exceptions.AirflowException: `python_callable` param must be callable
[2025-03-02T23:22:04.075+0000] {processor.py:838} WARNING - No viable dags retrieved from /opt/airflow/dags/dag_pipeline_generate_data.py
[2025-03-02T23:22:09.117+0000] {processor.py:179} INFO - Processing /opt/airflow/dags/dag_pipeline_generate_data.py took 8.802 seconds
[2025-03-02T23:22:42.431+0000] {processor.py:157} INFO - Started process (PID=1528) to work on /opt/airflow/dags/dag_pipeline_generate_data.py
[2025-03-02T23:22:42.432+0000] {processor.py:826} INFO - Processing file /opt/airflow/dags/dag_pipeline_generate_data.py for tasks to queue
[2025-03-02T23:22:42.432+0000] {logging_mixin.py:149} INFO - [2025-03-02T23:22:42.432+0000] {dagbag.py:541} INFO - Filling up the DagBag from /opt/airflow/dags/dag_pipeline_generate_data.py
[2025-03-02T23:22:46.140+0000] {logging_mixin.py:149} INFO - [2025-03-02T23:22:46.134+0000] {dagbag.py:350} ERROR - Failed to import: /opt/airflow/dags/dag_pipeline_generate_data.py
Traceback (most recent call last):
  File "/home/airflow/.local/lib/python3.7/site-packages/airflow/models/dagbag.py", line 346, in parse
    loader.exec_module(new_module)
  File "<frozen importlib._bootstrap_external>", line 728, in exec_module
  File "<frozen importlib._bootstrap>", line 219, in _call_with_frames_removed
  File "/opt/airflow/dags/dag_pipeline_generate_data.py", line 26, in <module>
    dag=dag,
  File "/home/airflow/.local/lib/python3.7/site-packages/airflow/models/baseoperator.py", line 429, in apply_defaults
    result = func(self, **kwargs, default_args=default_args)
  File "/home/airflow/.local/lib/python3.7/site-packages/airflow/operators/python.py", line 168, in __init__
    raise AirflowException("`python_callable` param must be callable")
airflow.exceptions.AirflowException: `python_callable` param must be callable
[2025-03-02T23:22:46.141+0000] {processor.py:838} WARNING - No viable dags retrieved from /opt/airflow/dags/dag_pipeline_generate_data.py
[2025-03-02T23:22:46.610+0000] {processor.py:179} INFO - Processing /opt/airflow/dags/dag_pipeline_generate_data.py took 4.182 seconds
[2025-03-02T23:23:17.137+0000] {processor.py:157} INFO - Started process (PID=1559) to work on /opt/airflow/dags/dag_pipeline_generate_data.py
[2025-03-02T23:23:17.138+0000] {processor.py:826} INFO - Processing file /opt/airflow/dags/dag_pipeline_generate_data.py for tasks to queue
[2025-03-02T23:23:17.139+0000] {logging_mixin.py:149} INFO - [2025-03-02T23:23:17.139+0000] {dagbag.py:541} INFO - Filling up the DagBag from /opt/airflow/dags/dag_pipeline_generate_data.py
[2025-03-02T23:23:23.832+0000] {logging_mixin.py:149} INFO - [2025-03-02T23:23:23.827+0000] {dagbag.py:350} ERROR - Failed to import: /opt/airflow/dags/dag_pipeline_generate_data.py
Traceback (most recent call last):
  File "/home/airflow/.local/lib/python3.7/site-packages/airflow/models/dagbag.py", line 346, in parse
    loader.exec_module(new_module)
  File "<frozen importlib._bootstrap_external>", line 728, in exec_module
  File "<frozen importlib._bootstrap>", line 219, in _call_with_frames_removed
  File "/opt/airflow/dags/dag_pipeline_generate_data.py", line 26, in <module>
    dag=dag,
  File "/home/airflow/.local/lib/python3.7/site-packages/airflow/models/baseoperator.py", line 429, in apply_defaults
    result = func(self, **kwargs, default_args=default_args)
  File "/home/airflow/.local/lib/python3.7/site-packages/airflow/operators/python.py", line 168, in __init__
    raise AirflowException("`python_callable` param must be callable")
airflow.exceptions.AirflowException: `python_callable` param must be callable
[2025-03-02T23:23:23.833+0000] {processor.py:838} WARNING - No viable dags retrieved from /opt/airflow/dags/dag_pipeline_generate_data.py
[2025-03-02T23:23:24.101+0000] {processor.py:179} INFO - Processing /opt/airflow/dags/dag_pipeline_generate_data.py took 4.055 seconds
[2025-03-02T23:23:56.181+0000] {processor.py:157} INFO - Started process (PID=1595) to work on /opt/airflow/dags/dag_pipeline_generate_data.py
[2025-03-02T23:23:56.182+0000] {processor.py:826} INFO - Processing file /opt/airflow/dags/dag_pipeline_generate_data.py for tasks to queue
[2025-03-02T23:23:56.183+0000] {logging_mixin.py:149} INFO - [2025-03-02T23:23:56.183+0000] {dagbag.py:541} INFO - Filling up the DagBag from /opt/airflow/dags/dag_pipeline_generate_data.py
[2025-03-02T23:23:59.833+0000] {logging_mixin.py:149} INFO - [2025-03-02T23:23:59.827+0000] {dagbag.py:350} ERROR - Failed to import: /opt/airflow/dags/dag_pipeline_generate_data.py
Traceback (most recent call last):
  File "/home/airflow/.local/lib/python3.7/site-packages/airflow/models/dagbag.py", line 346, in parse
    loader.exec_module(new_module)
  File "<frozen importlib._bootstrap_external>", line 728, in exec_module
  File "<frozen importlib._bootstrap>", line 219, in _call_with_frames_removed
  File "/opt/airflow/dags/dag_pipeline_generate_data.py", line 26, in <module>
    dag=dag,
  File "/home/airflow/.local/lib/python3.7/site-packages/airflow/models/baseoperator.py", line 429, in apply_defaults
    result = func(self, **kwargs, default_args=default_args)
  File "/home/airflow/.local/lib/python3.7/site-packages/airflow/operators/python.py", line 168, in __init__
    raise AirflowException("`python_callable` param must be callable")
airflow.exceptions.AirflowException: `python_callable` param must be callable
[2025-03-02T23:23:59.834+0000] {processor.py:838} WARNING - No viable dags retrieved from /opt/airflow/dags/dag_pipeline_generate_data.py
[2025-03-02T23:24:01.019+0000] {processor.py:179} INFO - Processing /opt/airflow/dags/dag_pipeline_generate_data.py took 4.842 seconds
[2025-03-02T23:24:31.197+0000] {processor.py:157} INFO - Started process (PID=1626) to work on /opt/airflow/dags/dag_pipeline_generate_data.py
[2025-03-02T23:24:31.198+0000] {processor.py:826} INFO - Processing file /opt/airflow/dags/dag_pipeline_generate_data.py for tasks to queue
[2025-03-02T23:24:31.199+0000] {logging_mixin.py:149} INFO - [2025-03-02T23:24:31.198+0000] {dagbag.py:541} INFO - Filling up the DagBag from /opt/airflow/dags/dag_pipeline_generate_data.py
[2025-03-02T23:24:34.904+0000] {logging_mixin.py:149} INFO - [2025-03-02T23:24:34.898+0000] {dagbag.py:350} ERROR - Failed to import: /opt/airflow/dags/dag_pipeline_generate_data.py
Traceback (most recent call last):
  File "/home/airflow/.local/lib/python3.7/site-packages/airflow/models/dagbag.py", line 346, in parse
    loader.exec_module(new_module)
  File "<frozen importlib._bootstrap_external>", line 728, in exec_module
  File "<frozen importlib._bootstrap>", line 219, in _call_with_frames_removed
  File "/opt/airflow/dags/dag_pipeline_generate_data.py", line 26, in <module>
    dag=dag,
  File "/home/airflow/.local/lib/python3.7/site-packages/airflow/models/baseoperator.py", line 429, in apply_defaults
    result = func(self, **kwargs, default_args=default_args)
  File "/home/airflow/.local/lib/python3.7/site-packages/airflow/operators/python.py", line 168, in __init__
    raise AirflowException("`python_callable` param must be callable")
airflow.exceptions.AirflowException: `python_callable` param must be callable
[2025-03-02T23:24:34.905+0000] {processor.py:838} WARNING - No viable dags retrieved from /opt/airflow/dags/dag_pipeline_generate_data.py
[2025-03-02T23:24:35.126+0000] {processor.py:179} INFO - Processing /opt/airflow/dags/dag_pipeline_generate_data.py took 3.933 seconds
[2025-03-02T23:25:05.479+0000] {processor.py:157} INFO - Started process (PID=1657) to work on /opt/airflow/dags/dag_pipeline_generate_data.py
[2025-03-02T23:25:05.480+0000] {processor.py:826} INFO - Processing file /opt/airflow/dags/dag_pipeline_generate_data.py for tasks to queue
[2025-03-02T23:25:05.481+0000] {logging_mixin.py:149} INFO - [2025-03-02T23:25:05.481+0000] {dagbag.py:541} INFO - Filling up the DagBag from /opt/airflow/dags/dag_pipeline_generate_data.py
[2025-03-02T23:25:10.064+0000] {logging_mixin.py:149} INFO - [2025-03-02T23:25:10.057+0000] {dagbag.py:350} ERROR - Failed to import: /opt/airflow/dags/dag_pipeline_generate_data.py
Traceback (most recent call last):
  File "/home/airflow/.local/lib/python3.7/site-packages/airflow/models/dagbag.py", line 346, in parse
    loader.exec_module(new_module)
  File "<frozen importlib._bootstrap_external>", line 728, in exec_module
  File "<frozen importlib._bootstrap>", line 219, in _call_with_frames_removed
  File "/opt/airflow/dags/dag_pipeline_generate_data.py", line 26, in <module>
    dag=dag,
  File "/home/airflow/.local/lib/python3.7/site-packages/airflow/models/baseoperator.py", line 429, in apply_defaults
    result = func(self, **kwargs, default_args=default_args)
  File "/home/airflow/.local/lib/python3.7/site-packages/airflow/operators/python.py", line 168, in __init__
    raise AirflowException("`python_callable` param must be callable")
airflow.exceptions.AirflowException: `python_callable` param must be callable
[2025-03-02T23:25:10.065+0000] {processor.py:838} WARNING - No viable dags retrieved from /opt/airflow/dags/dag_pipeline_generate_data.py
[2025-03-02T23:25:10.556+0000] {processor.py:179} INFO - Processing /opt/airflow/dags/dag_pipeline_generate_data.py took 5.081 seconds
[2025-03-02T23:25:41.268+0000] {processor.py:157} INFO - Started process (PID=1688) to work on /opt/airflow/dags/dag_pipeline_generate_data.py
[2025-03-02T23:25:41.269+0000] {processor.py:826} INFO - Processing file /opt/airflow/dags/dag_pipeline_generate_data.py for tasks to queue
[2025-03-02T23:25:41.270+0000] {logging_mixin.py:149} INFO - [2025-03-02T23:25:41.270+0000] {dagbag.py:541} INFO - Filling up the DagBag from /opt/airflow/dags/dag_pipeline_generate_data.py
[2025-03-02T23:25:44.776+0000] {logging_mixin.py:149} INFO - [2025-03-02T23:25:44.769+0000] {dagbag.py:350} ERROR - Failed to import: /opt/airflow/dags/dag_pipeline_generate_data.py
Traceback (most recent call last):
  File "/home/airflow/.local/lib/python3.7/site-packages/airflow/models/dagbag.py", line 346, in parse
    loader.exec_module(new_module)
  File "<frozen importlib._bootstrap_external>", line 728, in exec_module
  File "<frozen importlib._bootstrap>", line 219, in _call_with_frames_removed
  File "/opt/airflow/dags/dag_pipeline_generate_data.py", line 26, in <module>
    dag=dag,
  File "/home/airflow/.local/lib/python3.7/site-packages/airflow/models/baseoperator.py", line 429, in apply_defaults
    result = func(self, **kwargs, default_args=default_args)
  File "/home/airflow/.local/lib/python3.7/site-packages/airflow/operators/python.py", line 168, in __init__
    raise AirflowException("`python_callable` param must be callable")
airflow.exceptions.AirflowException: `python_callable` param must be callable
[2025-03-02T23:25:44.778+0000] {processor.py:838} WARNING - No viable dags retrieved from /opt/airflow/dags/dag_pipeline_generate_data.py
[2025-03-02T23:25:45.090+0000] {processor.py:179} INFO - Processing /opt/airflow/dags/dag_pipeline_generate_data.py took 3.826 seconds
[2025-03-02T23:26:15.398+0000] {processor.py:157} INFO - Started process (PID=1719) to work on /opt/airflow/dags/dag_pipeline_generate_data.py
[2025-03-02T23:26:15.399+0000] {processor.py:826} INFO - Processing file /opt/airflow/dags/dag_pipeline_generate_data.py for tasks to queue
[2025-03-02T23:26:15.400+0000] {logging_mixin.py:149} INFO - [2025-03-02T23:26:15.400+0000] {dagbag.py:541} INFO - Filling up the DagBag from /opt/airflow/dags/dag_pipeline_generate_data.py
[2025-03-02T23:26:19.065+0000] {logging_mixin.py:149} INFO - [2025-03-02T23:26:18.941+0000] {dagbag.py:350} ERROR - Failed to import: /opt/airflow/dags/dag_pipeline_generate_data.py
Traceback (most recent call last):
  File "/home/airflow/.local/lib/python3.7/site-packages/airflow/models/dagbag.py", line 346, in parse
    loader.exec_module(new_module)
  File "<frozen importlib._bootstrap_external>", line 728, in exec_module
  File "<frozen importlib._bootstrap>", line 219, in _call_with_frames_removed
  File "/opt/airflow/dags/dag_pipeline_generate_data.py", line 26, in <module>
    dag=dag,
  File "/home/airflow/.local/lib/python3.7/site-packages/airflow/models/baseoperator.py", line 429, in apply_defaults
    result = func(self, **kwargs, default_args=default_args)
  File "/home/airflow/.local/lib/python3.7/site-packages/airflow/operators/python.py", line 168, in __init__
    raise AirflowException("`python_callable` param must be callable")
airflow.exceptions.AirflowException: `python_callable` param must be callable
[2025-03-02T23:26:19.066+0000] {processor.py:838} WARNING - No viable dags retrieved from /opt/airflow/dags/dag_pipeline_generate_data.py
[2025-03-02T23:26:20.450+0000] {processor.py:179} INFO - Processing /opt/airflow/dags/dag_pipeline_generate_data.py took 5.056 seconds
[2025-03-02T23:26:51.115+0000] {processor.py:157} INFO - Started process (PID=1753) to work on /opt/airflow/dags/dag_pipeline_generate_data.py
[2025-03-02T23:26:51.116+0000] {processor.py:826} INFO - Processing file /opt/airflow/dags/dag_pipeline_generate_data.py for tasks to queue
[2025-03-02T23:26:51.117+0000] {logging_mixin.py:149} INFO - [2025-03-02T23:26:51.117+0000] {dagbag.py:541} INFO - Filling up the DagBag from /opt/airflow/dags/dag_pipeline_generate_data.py
[2025-03-02T23:26:56.300+0000] {logging_mixin.py:149} INFO - [2025-03-02T23:26:56.294+0000] {dagbag.py:350} ERROR - Failed to import: /opt/airflow/dags/dag_pipeline_generate_data.py
Traceback (most recent call last):
  File "/home/airflow/.local/lib/python3.7/site-packages/airflow/models/dagbag.py", line 346, in parse
    loader.exec_module(new_module)
  File "<frozen importlib._bootstrap_external>", line 728, in exec_module
  File "<frozen importlib._bootstrap>", line 219, in _call_with_frames_removed
  File "/opt/airflow/dags/dag_pipeline_generate_data.py", line 26, in <module>
    dag=dag,
  File "/home/airflow/.local/lib/python3.7/site-packages/airflow/models/baseoperator.py", line 429, in apply_defaults
    result = func(self, **kwargs, default_args=default_args)
  File "/home/airflow/.local/lib/python3.7/site-packages/airflow/operators/python.py", line 168, in __init__
    raise AirflowException("`python_callable` param must be callable")
airflow.exceptions.AirflowException: `python_callable` param must be callable
[2025-03-02T23:26:56.301+0000] {processor.py:838} WARNING - No viable dags retrieved from /opt/airflow/dags/dag_pipeline_generate_data.py
[2025-03-02T23:26:56.706+0000] {processor.py:179} INFO - Processing /opt/airflow/dags/dag_pipeline_generate_data.py took 5.595 seconds
[2025-03-02T23:27:26.793+0000] {processor.py:157} INFO - Started process (PID=1784) to work on /opt/airflow/dags/dag_pipeline_generate_data.py
[2025-03-02T23:27:26.794+0000] {processor.py:826} INFO - Processing file /opt/airflow/dags/dag_pipeline_generate_data.py for tasks to queue
[2025-03-02T23:27:26.796+0000] {logging_mixin.py:149} INFO - [2025-03-02T23:27:26.795+0000] {dagbag.py:541} INFO - Filling up the DagBag from /opt/airflow/dags/dag_pipeline_generate_data.py
[2025-03-02T23:27:31.291+0000] {logging_mixin.py:149} INFO - [2025-03-02T23:27:31.285+0000] {dagbag.py:350} ERROR - Failed to import: /opt/airflow/dags/dag_pipeline_generate_data.py
Traceback (most recent call last):
  File "/home/airflow/.local/lib/python3.7/site-packages/airflow/models/dagbag.py", line 346, in parse
    loader.exec_module(new_module)
  File "<frozen importlib._bootstrap_external>", line 728, in exec_module
  File "<frozen importlib._bootstrap>", line 219, in _call_with_frames_removed
  File "/opt/airflow/dags/dag_pipeline_generate_data.py", line 26, in <module>
    dag=dag,
  File "/home/airflow/.local/lib/python3.7/site-packages/airflow/models/baseoperator.py", line 429, in apply_defaults
    result = func(self, **kwargs, default_args=default_args)
  File "/home/airflow/.local/lib/python3.7/site-packages/airflow/operators/python.py", line 168, in __init__
    raise AirflowException("`python_callable` param must be callable")
airflow.exceptions.AirflowException: `python_callable` param must be callable
[2025-03-02T23:27:31.292+0000] {processor.py:838} WARNING - No viable dags retrieved from /opt/airflow/dags/dag_pipeline_generate_data.py
[2025-03-02T23:27:31.587+0000] {processor.py:179} INFO - Processing /opt/airflow/dags/dag_pipeline_generate_data.py took 4.797 seconds
[2025-03-02T23:28:02.029+0000] {processor.py:157} INFO - Started process (PID=1815) to work on /opt/airflow/dags/dag_pipeline_generate_data.py
[2025-03-02T23:28:02.030+0000] {processor.py:826} INFO - Processing file /opt/airflow/dags/dag_pipeline_generate_data.py for tasks to queue
[2025-03-02T23:28:02.031+0000] {logging_mixin.py:149} INFO - [2025-03-02T23:28:02.031+0000] {dagbag.py:541} INFO - Filling up the DagBag from /opt/airflow/dags/dag_pipeline_generate_data.py
[2025-03-02T23:28:03.529+0000] {logging_mixin.py:149} INFO - [2025-03-02T23:28:02.933+0000] {dagbag.py:350} ERROR - Failed to import: /opt/airflow/dags/dag_pipeline_generate_data.py
Traceback (most recent call last):
  File "/home/airflow/.local/lib/python3.7/site-packages/airflow/models/dagbag.py", line 346, in parse
    loader.exec_module(new_module)
  File "<frozen importlib._bootstrap_external>", line 728, in exec_module
  File "<frozen importlib._bootstrap>", line 219, in _call_with_frames_removed
  File "/opt/airflow/dags/dag_pipeline_generate_data.py", line 4, in <module>
    import generate_data
  File "/opt/airflow/dags/generate_data.py", line 29, in <module>
    branch_data = pd.read_csv("df_branch.csv")
  File "/home/airflow/.local/lib/python3.7/site-packages/pandas/util/_decorators.py", line 311, in wrapper
    return func(*args, **kwargs)
  File "/home/airflow/.local/lib/python3.7/site-packages/pandas/io/parsers/readers.py", line 586, in read_csv
    return _read(filepath_or_buffer, kwds)
  File "/home/airflow/.local/lib/python3.7/site-packages/pandas/io/parsers/readers.py", line 482, in _read
    parser = TextFileReader(filepath_or_buffer, **kwds)
  File "/home/airflow/.local/lib/python3.7/site-packages/pandas/io/parsers/readers.py", line 811, in __init__
    self._engine = self._make_engine(self.engine)
  File "/home/airflow/.local/lib/python3.7/site-packages/pandas/io/parsers/readers.py", line 1040, in _make_engine
    return mapping[engine](self.f, **self.options)  # type: ignore[call-arg]
  File "/home/airflow/.local/lib/python3.7/site-packages/pandas/io/parsers/c_parser_wrapper.py", line 69, in __init__
    self._reader = parsers.TextReader(self.handles.handle, **kwds)
  File "pandas/_libs/parsers.pyx", line 549, in pandas._libs.parsers.TextReader.__cinit__
pandas.errors.EmptyDataError: No columns to parse from file
[2025-03-02T23:28:03.531+0000] {processor.py:838} WARNING - No viable dags retrieved from /opt/airflow/dags/dag_pipeline_generate_data.py
[2025-03-02T23:28:04.202+0000] {processor.py:179} INFO - Processing /opt/airflow/dags/dag_pipeline_generate_data.py took 2.177 seconds
[2025-03-02T23:28:34.476+0000] {processor.py:157} INFO - Started process (PID=1843) to work on /opt/airflow/dags/dag_pipeline_generate_data.py
[2025-03-02T23:28:34.477+0000] {processor.py:826} INFO - Processing file /opt/airflow/dags/dag_pipeline_generate_data.py for tasks to queue
[2025-03-02T23:28:34.478+0000] {logging_mixin.py:149} INFO - [2025-03-02T23:28:34.478+0000] {dagbag.py:541} INFO - Filling up the DagBag from /opt/airflow/dags/dag_pipeline_generate_data.py
[2025-03-02T23:28:37.561+0000] {logging_mixin.py:149} INFO - [2025-03-02T23:28:37.555+0000] {dagbag.py:350} ERROR - Failed to import: /opt/airflow/dags/dag_pipeline_generate_data.py
Traceback (most recent call last):
  File "/home/airflow/.local/lib/python3.7/site-packages/airflow/models/dagbag.py", line 346, in parse
    loader.exec_module(new_module)
  File "<frozen importlib._bootstrap_external>", line 728, in exec_module
  File "<frozen importlib._bootstrap>", line 219, in _call_with_frames_removed
  File "/opt/airflow/dags/dag_pipeline_generate_data.py", line 26, in <module>
    dag=dag,
  File "/home/airflow/.local/lib/python3.7/site-packages/airflow/models/baseoperator.py", line 429, in apply_defaults
    result = func(self, **kwargs, default_args=default_args)
  File "/home/airflow/.local/lib/python3.7/site-packages/airflow/operators/python.py", line 168, in __init__
    raise AirflowException("`python_callable` param must be callable")
airflow.exceptions.AirflowException: `python_callable` param must be callable
[2025-03-02T23:28:37.562+0000] {processor.py:838} WARNING - No viable dags retrieved from /opt/airflow/dags/dag_pipeline_generate_data.py
[2025-03-02T23:28:39.408+0000] {processor.py:179} INFO - Processing /opt/airflow/dags/dag_pipeline_generate_data.py took 4.935 seconds
[2025-03-02T23:29:10.061+0000] {processor.py:157} INFO - Started process (PID=1874) to work on /opt/airflow/dags/dag_pipeline_generate_data.py
[2025-03-02T23:29:10.063+0000] {processor.py:826} INFO - Processing file /opt/airflow/dags/dag_pipeline_generate_data.py for tasks to queue
[2025-03-02T23:29:10.064+0000] {logging_mixin.py:149} INFO - [2025-03-02T23:29:10.064+0000] {dagbag.py:541} INFO - Filling up the DagBag from /opt/airflow/dags/dag_pipeline_generate_data.py
[2025-03-02T23:29:13.841+0000] {logging_mixin.py:149} INFO - [2025-03-02T23:29:13.693+0000] {dagbag.py:350} ERROR - Failed to import: /opt/airflow/dags/dag_pipeline_generate_data.py
Traceback (most recent call last):
  File "/home/airflow/.local/lib/python3.7/site-packages/airflow/models/dagbag.py", line 346, in parse
    loader.exec_module(new_module)
  File "<frozen importlib._bootstrap_external>", line 728, in exec_module
  File "<frozen importlib._bootstrap>", line 219, in _call_with_frames_removed
  File "/opt/airflow/dags/dag_pipeline_generate_data.py", line 26, in <module>
    dag=dag,
  File "/home/airflow/.local/lib/python3.7/site-packages/airflow/models/baseoperator.py", line 429, in apply_defaults
    result = func(self, **kwargs, default_args=default_args)
  File "/home/airflow/.local/lib/python3.7/site-packages/airflow/operators/python.py", line 168, in __init__
    raise AirflowException("`python_callable` param must be callable")
airflow.exceptions.AirflowException: `python_callable` param must be callable
[2025-03-02T23:29:13.842+0000] {processor.py:838} WARNING - No viable dags retrieved from /opt/airflow/dags/dag_pipeline_generate_data.py
[2025-03-02T23:29:14.504+0000] {processor.py:179} INFO - Processing /opt/airflow/dags/dag_pipeline_generate_data.py took 4.447 seconds
[2025-03-02T23:29:44.689+0000] {processor.py:157} INFO - Started process (PID=1905) to work on /opt/airflow/dags/dag_pipeline_generate_data.py
[2025-03-02T23:29:44.690+0000] {processor.py:826} INFO - Processing file /opt/airflow/dags/dag_pipeline_generate_data.py for tasks to queue
[2025-03-02T23:29:44.691+0000] {logging_mixin.py:149} INFO - [2025-03-02T23:29:44.691+0000] {dagbag.py:541} INFO - Filling up the DagBag from /opt/airflow/dags/dag_pipeline_generate_data.py
[2025-03-02T23:29:48.670+0000] {logging_mixin.py:149} INFO - [2025-03-02T23:29:48.661+0000] {dagbag.py:350} ERROR - Failed to import: /opt/airflow/dags/dag_pipeline_generate_data.py
Traceback (most recent call last):
  File "/home/airflow/.local/lib/python3.7/site-packages/airflow/models/dagbag.py", line 346, in parse
    loader.exec_module(new_module)
  File "<frozen importlib._bootstrap_external>", line 728, in exec_module
  File "<frozen importlib._bootstrap>", line 219, in _call_with_frames_removed
  File "/opt/airflow/dags/dag_pipeline_generate_data.py", line 26, in <module>
    dag=dag,
  File "/home/airflow/.local/lib/python3.7/site-packages/airflow/models/baseoperator.py", line 429, in apply_defaults
    result = func(self, **kwargs, default_args=default_args)
  File "/home/airflow/.local/lib/python3.7/site-packages/airflow/operators/python.py", line 168, in __init__
    raise AirflowException("`python_callable` param must be callable")
airflow.exceptions.AirflowException: `python_callable` param must be callable
[2025-03-02T23:29:48.671+0000] {processor.py:838} WARNING - No viable dags retrieved from /opt/airflow/dags/dag_pipeline_generate_data.py
[2025-03-02T23:29:49.316+0000] {processor.py:179} INFO - Processing /opt/airflow/dags/dag_pipeline_generate_data.py took 4.630 seconds
[2025-03-02T23:30:19.853+0000] {processor.py:157} INFO - Started process (PID=1939) to work on /opt/airflow/dags/dag_pipeline_generate_data.py
[2025-03-02T23:30:19.854+0000] {processor.py:826} INFO - Processing file /opt/airflow/dags/dag_pipeline_generate_data.py for tasks to queue
[2025-03-02T23:30:19.855+0000] {logging_mixin.py:149} INFO - [2025-03-02T23:30:19.855+0000] {dagbag.py:541} INFO - Filling up the DagBag from /opt/airflow/dags/dag_pipeline_generate_data.py
[2025-03-02T23:30:23.534+0000] {logging_mixin.py:149} INFO - [2025-03-02T23:30:23.527+0000] {dagbag.py:350} ERROR - Failed to import: /opt/airflow/dags/dag_pipeline_generate_data.py
Traceback (most recent call last):
  File "/home/airflow/.local/lib/python3.7/site-packages/airflow/models/dagbag.py", line 346, in parse
    loader.exec_module(new_module)
  File "<frozen importlib._bootstrap_external>", line 728, in exec_module
  File "<frozen importlib._bootstrap>", line 219, in _call_with_frames_removed
  File "/opt/airflow/dags/dag_pipeline_generate_data.py", line 26, in <module>
    dag=dag,
  File "/home/airflow/.local/lib/python3.7/site-packages/airflow/models/baseoperator.py", line 429, in apply_defaults
    result = func(self, **kwargs, default_args=default_args)
  File "/home/airflow/.local/lib/python3.7/site-packages/airflow/operators/python.py", line 168, in __init__
    raise AirflowException("`python_callable` param must be callable")
airflow.exceptions.AirflowException: `python_callable` param must be callable
[2025-03-02T23:30:23.535+0000] {processor.py:838} WARNING - No viable dags retrieved from /opt/airflow/dags/dag_pipeline_generate_data.py
[2025-03-02T23:30:25.064+0000] {processor.py:179} INFO - Processing /opt/airflow/dags/dag_pipeline_generate_data.py took 5.213 seconds
[2025-03-02T23:30:55.300+0000] {processor.py:157} INFO - Started process (PID=1967) to work on /opt/airflow/dags/dag_pipeline_generate_data.py
[2025-03-02T23:30:55.301+0000] {processor.py:826} INFO - Processing file /opt/airflow/dags/dag_pipeline_generate_data.py for tasks to queue
[2025-03-02T23:30:55.302+0000] {logging_mixin.py:149} INFO - [2025-03-02T23:30:55.302+0000] {dagbag.py:541} INFO - Filling up the DagBag from /opt/airflow/dags/dag_pipeline_generate_data.py
[2025-03-02T23:31:07.189+0000] {logging_mixin.py:149} INFO - [2025-03-02T23:31:07.184+0000] {dagbag.py:350} ERROR - Failed to import: /opt/airflow/dags/dag_pipeline_generate_data.py
Traceback (most recent call last):
  File "/home/airflow/.local/lib/python3.7/site-packages/airflow/models/dagbag.py", line 346, in parse
    loader.exec_module(new_module)
  File "<frozen importlib._bootstrap_external>", line 728, in exec_module
  File "<frozen importlib._bootstrap>", line 219, in _call_with_frames_removed
  File "/opt/airflow/dags/dag_pipeline_generate_data.py", line 26, in <module>
    dag=dag,
  File "/home/airflow/.local/lib/python3.7/site-packages/airflow/models/baseoperator.py", line 429, in apply_defaults
    result = func(self, **kwargs, default_args=default_args)
  File "/home/airflow/.local/lib/python3.7/site-packages/airflow/operators/python.py", line 168, in __init__
    raise AirflowException("`python_callable` param must be callable")
airflow.exceptions.AirflowException: `python_callable` param must be callable
[2025-03-02T23:31:07.190+0000] {processor.py:838} WARNING - No viable dags retrieved from /opt/airflow/dags/dag_pipeline_generate_data.py
[2025-03-02T23:31:13.064+0000] {processor.py:179} INFO - Processing /opt/airflow/dags/dag_pipeline_generate_data.py took 14.789 seconds
[2025-03-02T23:31:43.716+0000] {processor.py:157} INFO - Started process (PID=2001) to work on /opt/airflow/dags/dag_pipeline_generate_data.py
[2025-03-02T23:31:43.717+0000] {processor.py:826} INFO - Processing file /opt/airflow/dags/dag_pipeline_generate_data.py for tasks to queue
[2025-03-02T23:31:43.719+0000] {logging_mixin.py:149} INFO - [2025-03-02T23:31:43.718+0000] {dagbag.py:541} INFO - Filling up the DagBag from /opt/airflow/dags/dag_pipeline_generate_data.py
[2025-03-02T23:31:47.300+0000] {logging_mixin.py:149} INFO - [2025-03-02T23:31:47.294+0000] {dagbag.py:350} ERROR - Failed to import: /opt/airflow/dags/dag_pipeline_generate_data.py
Traceback (most recent call last):
  File "/home/airflow/.local/lib/python3.7/site-packages/airflow/models/dagbag.py", line 346, in parse
    loader.exec_module(new_module)
  File "<frozen importlib._bootstrap_external>", line 728, in exec_module
  File "<frozen importlib._bootstrap>", line 219, in _call_with_frames_removed
  File "/opt/airflow/dags/dag_pipeline_generate_data.py", line 26, in <module>
    dag=dag,
  File "/home/airflow/.local/lib/python3.7/site-packages/airflow/models/baseoperator.py", line 429, in apply_defaults
    result = func(self, **kwargs, default_args=default_args)
  File "/home/airflow/.local/lib/python3.7/site-packages/airflow/operators/python.py", line 168, in __init__
    raise AirflowException("`python_callable` param must be callable")
airflow.exceptions.AirflowException: `python_callable` param must be callable
[2025-03-02T23:31:47.301+0000] {processor.py:838} WARNING - No viable dags retrieved from /opt/airflow/dags/dag_pipeline_generate_data.py
[2025-03-02T23:31:48.244+0000] {processor.py:179} INFO - Processing /opt/airflow/dags/dag_pipeline_generate_data.py took 4.532 seconds
[2025-03-02T23:32:18.517+0000] {processor.py:157} INFO - Started process (PID=2032) to work on /opt/airflow/dags/dag_pipeline_generate_data.py
[2025-03-02T23:32:18.518+0000] {processor.py:826} INFO - Processing file /opt/airflow/dags/dag_pipeline_generate_data.py for tasks to queue
[2025-03-02T23:32:18.519+0000] {logging_mixin.py:149} INFO - [2025-03-02T23:32:18.519+0000] {dagbag.py:541} INFO - Filling up the DagBag from /opt/airflow/dags/dag_pipeline_generate_data.py
[2025-03-02T23:32:21.723+0000] {logging_mixin.py:149} INFO - [2025-03-02T23:32:21.718+0000] {dagbag.py:350} ERROR - Failed to import: /opt/airflow/dags/dag_pipeline_generate_data.py
Traceback (most recent call last):
  File "/home/airflow/.local/lib/python3.7/site-packages/airflow/models/dagbag.py", line 346, in parse
    loader.exec_module(new_module)
  File "<frozen importlib._bootstrap_external>", line 728, in exec_module
  File "<frozen importlib._bootstrap>", line 219, in _call_with_frames_removed
  File "/opt/airflow/dags/dag_pipeline_generate_data.py", line 26, in <module>
    dag=dag,
  File "/home/airflow/.local/lib/python3.7/site-packages/airflow/models/baseoperator.py", line 429, in apply_defaults
    result = func(self, **kwargs, default_args=default_args)
  File "/home/airflow/.local/lib/python3.7/site-packages/airflow/operators/python.py", line 168, in __init__
    raise AirflowException("`python_callable` param must be callable")
airflow.exceptions.AirflowException: `python_callable` param must be callable
[2025-03-02T23:32:21.724+0000] {processor.py:838} WARNING - No viable dags retrieved from /opt/airflow/dags/dag_pipeline_generate_data.py
[2025-03-02T23:32:22.099+0000] {processor.py:179} INFO - Processing /opt/airflow/dags/dag_pipeline_generate_data.py took 3.585 seconds
[2025-03-02T23:32:59.716+0000] {processor.py:157} INFO - Started process (PID=2076) to work on /opt/airflow/dags/dag_pipeline_generate_data.py
[2025-03-02T23:32:59.717+0000] {processor.py:826} INFO - Processing file /opt/airflow/dags/dag_pipeline_generate_data.py for tasks to queue
[2025-03-02T23:32:59.718+0000] {logging_mixin.py:149} INFO - [2025-03-02T23:32:59.718+0000] {dagbag.py:541} INFO - Filling up the DagBag from /opt/airflow/dags/dag_pipeline_generate_data.py
[2025-03-02T23:33:03.068+0000] {logging_mixin.py:149} INFO - [2025-03-02T23:33:03.064+0000] {dagbag.py:350} ERROR - Failed to import: /opt/airflow/dags/dag_pipeline_generate_data.py
Traceback (most recent call last):
  File "/home/airflow/.local/lib/python3.7/site-packages/airflow/models/dagbag.py", line 346, in parse
    loader.exec_module(new_module)
  File "<frozen importlib._bootstrap_external>", line 728, in exec_module
  File "<frozen importlib._bootstrap>", line 219, in _call_with_frames_removed
  File "/opt/airflow/dags/dag_pipeline_generate_data.py", line 26, in <module>
    dag=dag,
  File "/home/airflow/.local/lib/python3.7/site-packages/airflow/models/baseoperator.py", line 429, in apply_defaults
    result = func(self, **kwargs, default_args=default_args)
  File "/home/airflow/.local/lib/python3.7/site-packages/airflow/operators/python.py", line 168, in __init__
    raise AirflowException("`python_callable` param must be callable")
airflow.exceptions.AirflowException: `python_callable` param must be callable
[2025-03-02T23:33:03.069+0000] {processor.py:838} WARNING - No viable dags retrieved from /opt/airflow/dags/dag_pipeline_generate_data.py
[2025-03-02T23:33:06.025+0000] {processor.py:179} INFO - Processing /opt/airflow/dags/dag_pipeline_generate_data.py took 6.312 seconds
[2025-03-02T23:33:36.104+0000] {processor.py:157} INFO - Started process (PID=2107) to work on /opt/airflow/dags/dag_pipeline_generate_data.py
[2025-03-02T23:33:36.105+0000] {processor.py:826} INFO - Processing file /opt/airflow/dags/dag_pipeline_generate_data.py for tasks to queue
[2025-03-02T23:33:36.106+0000] {logging_mixin.py:149} INFO - [2025-03-02T23:33:36.106+0000] {dagbag.py:541} INFO - Filling up the DagBag from /opt/airflow/dags/dag_pipeline_generate_data.py
[2025-03-02T23:33:42.279+0000] {logging_mixin.py:149} INFO - [2025-03-02T23:33:42.272+0000] {dagbag.py:350} ERROR - Failed to import: /opt/airflow/dags/dag_pipeline_generate_data.py
Traceback (most recent call last):
  File "/home/airflow/.local/lib/python3.7/site-packages/airflow/models/dagbag.py", line 346, in parse
    loader.exec_module(new_module)
  File "<frozen importlib._bootstrap_external>", line 728, in exec_module
  File "<frozen importlib._bootstrap>", line 219, in _call_with_frames_removed
  File "/opt/airflow/dags/dag_pipeline_generate_data.py", line 26, in <module>
    dag=dag,
  File "/home/airflow/.local/lib/python3.7/site-packages/airflow/models/baseoperator.py", line 429, in apply_defaults
    result = func(self, **kwargs, default_args=default_args)
  File "/home/airflow/.local/lib/python3.7/site-packages/airflow/operators/python.py", line 168, in __init__
    raise AirflowException("`python_callable` param must be callable")
airflow.exceptions.AirflowException: `python_callable` param must be callable
[2025-03-02T23:33:42.281+0000] {processor.py:838} WARNING - No viable dags retrieved from /opt/airflow/dags/dag_pipeline_generate_data.py
[2025-03-02T23:33:42.954+0000] {processor.py:179} INFO - Processing /opt/airflow/dags/dag_pipeline_generate_data.py took 6.853 seconds
[2025-03-02T23:34:13.154+0000] {processor.py:157} INFO - Started process (PID=2138) to work on /opt/airflow/dags/dag_pipeline_generate_data.py
[2025-03-02T23:34:13.155+0000] {processor.py:826} INFO - Processing file /opt/airflow/dags/dag_pipeline_generate_data.py for tasks to queue
[2025-03-02T23:34:13.156+0000] {logging_mixin.py:149} INFO - [2025-03-02T23:34:13.156+0000] {dagbag.py:541} INFO - Filling up the DagBag from /opt/airflow/dags/dag_pipeline_generate_data.py
[2025-03-02T23:34:16.702+0000] {logging_mixin.py:149} INFO - [2025-03-02T23:34:16.696+0000] {dagbag.py:350} ERROR - Failed to import: /opt/airflow/dags/dag_pipeline_generate_data.py
Traceback (most recent call last):
  File "/home/airflow/.local/lib/python3.7/site-packages/airflow/models/dagbag.py", line 346, in parse
    loader.exec_module(new_module)
  File "<frozen importlib._bootstrap_external>", line 728, in exec_module
  File "<frozen importlib._bootstrap>", line 219, in _call_with_frames_removed
  File "/opt/airflow/dags/dag_pipeline_generate_data.py", line 26, in <module>
    dag=dag,
  File "/home/airflow/.local/lib/python3.7/site-packages/airflow/models/baseoperator.py", line 429, in apply_defaults
    result = func(self, **kwargs, default_args=default_args)
  File "/home/airflow/.local/lib/python3.7/site-packages/airflow/operators/python.py", line 168, in __init__
    raise AirflowException("`python_callable` param must be callable")
airflow.exceptions.AirflowException: `python_callable` param must be callable
[2025-03-02T23:34:16.702+0000] {processor.py:838} WARNING - No viable dags retrieved from /opt/airflow/dags/dag_pipeline_generate_data.py
[2025-03-02T23:34:17.278+0000] {processor.py:179} INFO - Processing /opt/airflow/dags/dag_pipeline_generate_data.py took 4.128 seconds
[2025-03-02T23:34:47.612+0000] {processor.py:157} INFO - Started process (PID=2161) to work on /opt/airflow/dags/dag_pipeline_generate_data.py
[2025-03-02T23:34:47.613+0000] {processor.py:826} INFO - Processing file /opt/airflow/dags/dag_pipeline_generate_data.py for tasks to queue
[2025-03-02T23:34:47.615+0000] {logging_mixin.py:149} INFO - [2025-03-02T23:34:47.614+0000] {dagbag.py:541} INFO - Filling up the DagBag from /opt/airflow/dags/dag_pipeline_generate_data.py
[2025-03-02T23:34:52.901+0000] {logging_mixin.py:149} INFO - [2025-03-02T23:34:52.893+0000] {dagbag.py:350} ERROR - Failed to import: /opt/airflow/dags/dag_pipeline_generate_data.py
Traceback (most recent call last):
  File "/home/airflow/.local/lib/python3.7/site-packages/airflow/models/dagbag.py", line 346, in parse
    loader.exec_module(new_module)
  File "<frozen importlib._bootstrap_external>", line 728, in exec_module
  File "<frozen importlib._bootstrap>", line 219, in _call_with_frames_removed
  File "/opt/airflow/dags/dag_pipeline_generate_data.py", line 26, in <module>
    dag=dag,
  File "/home/airflow/.local/lib/python3.7/site-packages/airflow/models/baseoperator.py", line 429, in apply_defaults
    result = func(self, **kwargs, default_args=default_args)
  File "/home/airflow/.local/lib/python3.7/site-packages/airflow/operators/python.py", line 168, in __init__
    raise AirflowException("`python_callable` param must be callable")
airflow.exceptions.AirflowException: `python_callable` param must be callable
[2025-03-02T23:34:52.903+0000] {processor.py:838} WARNING - No viable dags retrieved from /opt/airflow/dags/dag_pipeline_generate_data.py
[2025-03-02T23:34:55.024+0000] {processor.py:179} INFO - Processing /opt/airflow/dags/dag_pipeline_generate_data.py took 4.411 seconds
[2025-03-02T23:35:28.127+0000] {processor.py:157} INFO - Started process (PID=2192) to work on /opt/airflow/dags/dag_pipeline_generate_data.py
[2025-03-02T23:35:28.128+0000] {processor.py:826} INFO - Processing file /opt/airflow/dags/dag_pipeline_generate_data.py for tasks to queue
[2025-03-02T23:35:28.129+0000] {logging_mixin.py:149} INFO - [2025-03-02T23:35:28.129+0000] {dagbag.py:541} INFO - Filling up the DagBag from /opt/airflow/dags/dag_pipeline_generate_data.py
[2025-03-02T23:35:29.003+0000] {logging_mixin.py:149} INFO - [2025-03-02T23:35:28.993+0000] {dagbag.py:350} ERROR - Failed to import: /opt/airflow/dags/dag_pipeline_generate_data.py
Traceback (most recent call last):
  File "/home/airflow/.local/lib/python3.7/site-packages/airflow/models/dagbag.py", line 346, in parse
    loader.exec_module(new_module)
  File "<frozen importlib._bootstrap_external>", line 728, in exec_module
  File "<frozen importlib._bootstrap>", line 219, in _call_with_frames_removed
  File "/opt/airflow/dags/dag_pipeline_generate_data.py", line 4, in <module>
    import generate_data
  File "/opt/airflow/dags/generate_data.py", line 29, in <module>
    branch_data = pd.read_csv("df_branch.csv")
  File "/home/airflow/.local/lib/python3.7/site-packages/pandas/util/_decorators.py", line 311, in wrapper
    return func(*args, **kwargs)
  File "/home/airflow/.local/lib/python3.7/site-packages/pandas/io/parsers/readers.py", line 586, in read_csv
    return _read(filepath_or_buffer, kwds)
  File "/home/airflow/.local/lib/python3.7/site-packages/pandas/io/parsers/readers.py", line 482, in _read
    parser = TextFileReader(filepath_or_buffer, **kwds)
  File "/home/airflow/.local/lib/python3.7/site-packages/pandas/io/parsers/readers.py", line 811, in __init__
    self._engine = self._make_engine(self.engine)
  File "/home/airflow/.local/lib/python3.7/site-packages/pandas/io/parsers/readers.py", line 1040, in _make_engine
    return mapping[engine](self.f, **self.options)  # type: ignore[call-arg]
  File "/home/airflow/.local/lib/python3.7/site-packages/pandas/io/parsers/c_parser_wrapper.py", line 69, in __init__
    self._reader = parsers.TextReader(self.handles.handle, **kwds)
  File "pandas/_libs/parsers.pyx", line 549, in pandas._libs.parsers.TextReader.__cinit__
pandas.errors.EmptyDataError: No columns to parse from file
[2025-03-02T23:35:29.004+0000] {processor.py:838} WARNING - No viable dags retrieved from /opt/airflow/dags/dag_pipeline_generate_data.py
[2025-03-02T23:35:29.400+0000] {processor.py:179} INFO - Processing /opt/airflow/dags/dag_pipeline_generate_data.py took 1.277 seconds
[2025-03-02T23:36:01.677+0000] {processor.py:157} INFO - Started process (PID=2220) to work on /opt/airflow/dags/dag_pipeline_generate_data.py
[2025-03-02T23:36:01.678+0000] {processor.py:826} INFO - Processing file /opt/airflow/dags/dag_pipeline_generate_data.py for tasks to queue
[2025-03-02T23:36:01.679+0000] {logging_mixin.py:149} INFO - [2025-03-02T23:36:01.679+0000] {dagbag.py:541} INFO - Filling up the DagBag from /opt/airflow/dags/dag_pipeline_generate_data.py
[2025-03-02T23:36:05.770+0000] {logging_mixin.py:149} INFO - [2025-03-02T23:36:05.762+0000] {dagbag.py:350} ERROR - Failed to import: /opt/airflow/dags/dag_pipeline_generate_data.py
Traceback (most recent call last):
  File "/home/airflow/.local/lib/python3.7/site-packages/airflow/models/dagbag.py", line 346, in parse
    loader.exec_module(new_module)
  File "<frozen importlib._bootstrap_external>", line 728, in exec_module
  File "<frozen importlib._bootstrap>", line 219, in _call_with_frames_removed
  File "/opt/airflow/dags/dag_pipeline_generate_data.py", line 26, in <module>
    dag=dag,
  File "/home/airflow/.local/lib/python3.7/site-packages/airflow/models/baseoperator.py", line 429, in apply_defaults
    result = func(self, **kwargs, default_args=default_args)
  File "/home/airflow/.local/lib/python3.7/site-packages/airflow/operators/python.py", line 168, in __init__
    raise AirflowException("`python_callable` param must be callable")
airflow.exceptions.AirflowException: `python_callable` param must be callable
[2025-03-02T23:36:05.771+0000] {processor.py:838} WARNING - No viable dags retrieved from /opt/airflow/dags/dag_pipeline_generate_data.py
[2025-03-02T23:36:05.839+0000] {processor.py:179} INFO - Processing /opt/airflow/dags/dag_pipeline_generate_data.py took 4.165 seconds
[2025-03-02T23:36:36.590+0000] {processor.py:157} INFO - Started process (PID=2251) to work on /opt/airflow/dags/dag_pipeline_generate_data.py
[2025-03-02T23:36:36.591+0000] {processor.py:826} INFO - Processing file /opt/airflow/dags/dag_pipeline_generate_data.py for tasks to queue
[2025-03-02T23:36:36.592+0000] {logging_mixin.py:149} INFO - [2025-03-02T23:36:36.592+0000] {dagbag.py:541} INFO - Filling up the DagBag from /opt/airflow/dags/dag_pipeline_generate_data.py
[2025-03-02T23:36:40.088+0000] {logging_mixin.py:149} INFO - [2025-03-02T23:36:40.083+0000] {dagbag.py:350} ERROR - Failed to import: /opt/airflow/dags/dag_pipeline_generate_data.py
Traceback (most recent call last):
  File "/home/airflow/.local/lib/python3.7/site-packages/airflow/models/dagbag.py", line 346, in parse
    loader.exec_module(new_module)
  File "<frozen importlib._bootstrap_external>", line 728, in exec_module
  File "<frozen importlib._bootstrap>", line 219, in _call_with_frames_removed
  File "/opt/airflow/dags/dag_pipeline_generate_data.py", line 26, in <module>
    dag=dag,
  File "/home/airflow/.local/lib/python3.7/site-packages/airflow/models/baseoperator.py", line 429, in apply_defaults
    result = func(self, **kwargs, default_args=default_args)
  File "/home/airflow/.local/lib/python3.7/site-packages/airflow/operators/python.py", line 168, in __init__
    raise AirflowException("`python_callable` param must be callable")
airflow.exceptions.AirflowException: `python_callable` param must be callable
[2025-03-02T23:36:40.089+0000] {processor.py:838} WARNING - No viable dags retrieved from /opt/airflow/dags/dag_pipeline_generate_data.py
[2025-03-02T23:36:41.257+0000] {processor.py:179} INFO - Processing /opt/airflow/dags/dag_pipeline_generate_data.py took 4.670 seconds
[2025-03-02T23:37:11.683+0000] {processor.py:157} INFO - Started process (PID=2290) to work on /opt/airflow/dags/dag_pipeline_generate_data.py
[2025-03-02T23:37:11.685+0000] {processor.py:826} INFO - Processing file /opt/airflow/dags/dag_pipeline_generate_data.py for tasks to queue
[2025-03-02T23:37:11.686+0000] {logging_mixin.py:149} INFO - [2025-03-02T23:37:11.686+0000] {dagbag.py:541} INFO - Filling up the DagBag from /opt/airflow/dags/dag_pipeline_generate_data.py
[2025-03-02T23:37:15.298+0000] {logging_mixin.py:149} INFO - [2025-03-02T23:37:15.292+0000] {dagbag.py:350} ERROR - Failed to import: /opt/airflow/dags/dag_pipeline_generate_data.py
Traceback (most recent call last):
  File "/home/airflow/.local/lib/python3.7/site-packages/airflow/models/dagbag.py", line 346, in parse
    loader.exec_module(new_module)
  File "<frozen importlib._bootstrap_external>", line 728, in exec_module
  File "<frozen importlib._bootstrap>", line 219, in _call_with_frames_removed
  File "/opt/airflow/dags/dag_pipeline_generate_data.py", line 26, in <module>
    dag=dag,
  File "/home/airflow/.local/lib/python3.7/site-packages/airflow/models/baseoperator.py", line 429, in apply_defaults
    result = func(self, **kwargs, default_args=default_args)
  File "/home/airflow/.local/lib/python3.7/site-packages/airflow/operators/python.py", line 168, in __init__
    raise AirflowException("`python_callable` param must be callable")
airflow.exceptions.AirflowException: `python_callable` param must be callable
[2025-03-02T23:37:15.299+0000] {processor.py:838} WARNING - No viable dags retrieved from /opt/airflow/dags/dag_pipeline_generate_data.py
[2025-03-02T23:37:16.099+0000] {processor.py:179} INFO - Processing /opt/airflow/dags/dag_pipeline_generate_data.py took 4.419 seconds
[2025-03-02T23:37:46.290+0000] {processor.py:157} INFO - Started process (PID=2318) to work on /opt/airflow/dags/dag_pipeline_generate_data.py
[2025-03-02T23:37:46.291+0000] {processor.py:826} INFO - Processing file /opt/airflow/dags/dag_pipeline_generate_data.py for tasks to queue
[2025-03-02T23:37:46.292+0000] {logging_mixin.py:149} INFO - [2025-03-02T23:37:46.292+0000] {dagbag.py:541} INFO - Filling up the DagBag from /opt/airflow/dags/dag_pipeline_generate_data.py
[2025-03-02T23:37:49.747+0000] {logging_mixin.py:149} INFO - [2025-03-02T23:37:49.740+0000] {dagbag.py:350} ERROR - Failed to import: /opt/airflow/dags/dag_pipeline_generate_data.py
Traceback (most recent call last):
  File "/home/airflow/.local/lib/python3.7/site-packages/airflow/models/dagbag.py", line 346, in parse
    loader.exec_module(new_module)
  File "<frozen importlib._bootstrap_external>", line 728, in exec_module
  File "<frozen importlib._bootstrap>", line 219, in _call_with_frames_removed
  File "/opt/airflow/dags/dag_pipeline_generate_data.py", line 26, in <module>
    dag=dag,
  File "/home/airflow/.local/lib/python3.7/site-packages/airflow/models/baseoperator.py", line 429, in apply_defaults
    result = func(self, **kwargs, default_args=default_args)
  File "/home/airflow/.local/lib/python3.7/site-packages/airflow/operators/python.py", line 168, in __init__
    raise AirflowException("`python_callable` param must be callable")
airflow.exceptions.AirflowException: `python_callable` param must be callable
[2025-03-02T23:37:49.747+0000] {processor.py:838} WARNING - No viable dags retrieved from /opt/airflow/dags/dag_pipeline_generate_data.py
[2025-03-02T23:37:50.607+0000] {processor.py:179} INFO - Processing /opt/airflow/dags/dag_pipeline_generate_data.py took 4.321 seconds
[2025-03-02T23:38:20.891+0000] {processor.py:157} INFO - Started process (PID=2352) to work on /opt/airflow/dags/dag_pipeline_generate_data.py
[2025-03-02T23:38:20.892+0000] {processor.py:826} INFO - Processing file /opt/airflow/dags/dag_pipeline_generate_data.py for tasks to queue
[2025-03-02T23:38:20.893+0000] {logging_mixin.py:149} INFO - [2025-03-02T23:38:20.893+0000] {dagbag.py:541} INFO - Filling up the DagBag from /opt/airflow/dags/dag_pipeline_generate_data.py
[2025-03-02T23:38:24.661+0000] {logging_mixin.py:149} INFO - [2025-03-02T23:38:24.656+0000] {dagbag.py:350} ERROR - Failed to import: /opt/airflow/dags/dag_pipeline_generate_data.py
Traceback (most recent call last):
  File "/home/airflow/.local/lib/python3.7/site-packages/airflow/models/dagbag.py", line 346, in parse
    loader.exec_module(new_module)
  File "<frozen importlib._bootstrap_external>", line 728, in exec_module
  File "<frozen importlib._bootstrap>", line 219, in _call_with_frames_removed
  File "/opt/airflow/dags/dag_pipeline_generate_data.py", line 26, in <module>
    dag=dag,
  File "/home/airflow/.local/lib/python3.7/site-packages/airflow/models/baseoperator.py", line 429, in apply_defaults
    result = func(self, **kwargs, default_args=default_args)
  File "/home/airflow/.local/lib/python3.7/site-packages/airflow/operators/python.py", line 168, in __init__
    raise AirflowException("`python_callable` param must be callable")
airflow.exceptions.AirflowException: `python_callable` param must be callable
[2025-03-02T23:38:24.661+0000] {processor.py:838} WARNING - No viable dags retrieved from /opt/airflow/dags/dag_pipeline_generate_data.py
[2025-03-02T23:38:25.088+0000] {processor.py:179} INFO - Processing /opt/airflow/dags/dag_pipeline_generate_data.py took 4.199 seconds
[2025-03-02T23:38:55.425+0000] {processor.py:157} INFO - Started process (PID=2391) to work on /opt/airflow/dags/dag_pipeline_generate_data.py
[2025-03-02T23:38:55.426+0000] {processor.py:826} INFO - Processing file /opt/airflow/dags/dag_pipeline_generate_data.py for tasks to queue
[2025-03-02T23:38:55.427+0000] {logging_mixin.py:149} INFO - [2025-03-02T23:38:55.427+0000] {dagbag.py:541} INFO - Filling up the DagBag from /opt/airflow/dags/dag_pipeline_generate_data.py
[2025-03-02T23:38:58.727+0000] {logging_mixin.py:149} INFO - [2025-03-02T23:38:58.722+0000] {dagbag.py:350} ERROR - Failed to import: /opt/airflow/dags/dag_pipeline_generate_data.py
Traceback (most recent call last):
  File "/home/airflow/.local/lib/python3.7/site-packages/airflow/models/dagbag.py", line 346, in parse
    loader.exec_module(new_module)
  File "<frozen importlib._bootstrap_external>", line 728, in exec_module
  File "<frozen importlib._bootstrap>", line 219, in _call_with_frames_removed
  File "/opt/airflow/dags/dag_pipeline_generate_data.py", line 26, in <module>
    dag=dag,
  File "/home/airflow/.local/lib/python3.7/site-packages/airflow/models/baseoperator.py", line 429, in apply_defaults
    result = func(self, **kwargs, default_args=default_args)
  File "/home/airflow/.local/lib/python3.7/site-packages/airflow/operators/python.py", line 168, in __init__
    raise AirflowException("`python_callable` param must be callable")
airflow.exceptions.AirflowException: `python_callable` param must be callable
[2025-03-02T23:38:58.728+0000] {processor.py:838} WARNING - No viable dags retrieved from /opt/airflow/dags/dag_pipeline_generate_data.py
[2025-03-02T23:38:59.522+0000] {processor.py:179} INFO - Processing /opt/airflow/dags/dag_pipeline_generate_data.py took 4.101 seconds
[2025-03-02T23:39:29.841+0000] {processor.py:157} INFO - Started process (PID=2422) to work on /opt/airflow/dags/dag_pipeline_generate_data.py
[2025-03-02T23:39:29.842+0000] {processor.py:826} INFO - Processing file /opt/airflow/dags/dag_pipeline_generate_data.py for tasks to queue
[2025-03-02T23:39:29.843+0000] {logging_mixin.py:149} INFO - [2025-03-02T23:39:29.843+0000] {dagbag.py:541} INFO - Filling up the DagBag from /opt/airflow/dags/dag_pipeline_generate_data.py
[2025-03-02T23:39:33.918+0000] {logging_mixin.py:149} INFO - [2025-03-02T23:39:33.913+0000] {dagbag.py:350} ERROR - Failed to import: /opt/airflow/dags/dag_pipeline_generate_data.py
Traceback (most recent call last):
  File "/home/airflow/.local/lib/python3.7/site-packages/airflow/models/dagbag.py", line 346, in parse
    loader.exec_module(new_module)
  File "<frozen importlib._bootstrap_external>", line 728, in exec_module
  File "<frozen importlib._bootstrap>", line 219, in _call_with_frames_removed
  File "/opt/airflow/dags/dag_pipeline_generate_data.py", line 26, in <module>
    dag=dag,
  File "/home/airflow/.local/lib/python3.7/site-packages/airflow/models/baseoperator.py", line 429, in apply_defaults
    result = func(self, **kwargs, default_args=default_args)
  File "/home/airflow/.local/lib/python3.7/site-packages/airflow/operators/python.py", line 168, in __init__
    raise AirflowException("`python_callable` param must be callable")
airflow.exceptions.AirflowException: `python_callable` param must be callable
[2025-03-02T23:39:33.919+0000] {processor.py:838} WARNING - No viable dags retrieved from /opt/airflow/dags/dag_pipeline_generate_data.py
[2025-03-02T23:39:34.575+0000] {processor.py:179} INFO - Processing /opt/airflow/dags/dag_pipeline_generate_data.py took 4.736 seconds
[2025-03-02T23:40:04.835+0000] {processor.py:157} INFO - Started process (PID=2453) to work on /opt/airflow/dags/dag_pipeline_generate_data.py
[2025-03-02T23:40:04.836+0000] {processor.py:826} INFO - Processing file /opt/airflow/dags/dag_pipeline_generate_data.py for tasks to queue
[2025-03-02T23:40:04.837+0000] {logging_mixin.py:149} INFO - [2025-03-02T23:40:04.837+0000] {dagbag.py:541} INFO - Filling up the DagBag from /opt/airflow/dags/dag_pipeline_generate_data.py
[2025-03-02T23:40:08.390+0000] {logging_mixin.py:149} INFO - [2025-03-02T23:40:08.385+0000] {dagbag.py:350} ERROR - Failed to import: /opt/airflow/dags/dag_pipeline_generate_data.py
Traceback (most recent call last):
  File "/home/airflow/.local/lib/python3.7/site-packages/airflow/models/dagbag.py", line 346, in parse
    loader.exec_module(new_module)
  File "<frozen importlib._bootstrap_external>", line 728, in exec_module
  File "<frozen importlib._bootstrap>", line 219, in _call_with_frames_removed
  File "/opt/airflow/dags/dag_pipeline_generate_data.py", line 26, in <module>
    dag=dag,
  File "/home/airflow/.local/lib/python3.7/site-packages/airflow/models/baseoperator.py", line 429, in apply_defaults
    result = func(self, **kwargs, default_args=default_args)
  File "/home/airflow/.local/lib/python3.7/site-packages/airflow/operators/python.py", line 168, in __init__
    raise AirflowException("`python_callable` param must be callable")
airflow.exceptions.AirflowException: `python_callable` param must be callable
[2025-03-02T23:40:08.391+0000] {processor.py:838} WARNING - No viable dags retrieved from /opt/airflow/dags/dag_pipeline_generate_data.py
[2025-03-02T23:40:08.533+0000] {processor.py:179} INFO - Processing /opt/airflow/dags/dag_pipeline_generate_data.py took 3.700 seconds
[2025-03-02T23:40:41.617+0000] {processor.py:157} INFO - Started process (PID=2484) to work on /opt/airflow/dags/dag_pipeline_generate_data.py
[2025-03-02T23:40:41.618+0000] {processor.py:826} INFO - Processing file /opt/airflow/dags/dag_pipeline_generate_data.py for tasks to queue
[2025-03-02T23:40:41.619+0000] {logging_mixin.py:149} INFO - [2025-03-02T23:40:41.619+0000] {dagbag.py:541} INFO - Filling up the DagBag from /opt/airflow/dags/dag_pipeline_generate_data.py
[2025-03-02T23:40:44.779+0000] {logging_mixin.py:149} INFO - [2025-03-02T23:40:44.773+0000] {dagbag.py:350} ERROR - Failed to import: /opt/airflow/dags/dag_pipeline_generate_data.py
Traceback (most recent call last):
  File "/home/airflow/.local/lib/python3.7/site-packages/airflow/models/dagbag.py", line 346, in parse
    loader.exec_module(new_module)
  File "<frozen importlib._bootstrap_external>", line 728, in exec_module
  File "<frozen importlib._bootstrap>", line 219, in _call_with_frames_removed
  File "/opt/airflow/dags/dag_pipeline_generate_data.py", line 26, in <module>
    dag=dag,
  File "/home/airflow/.local/lib/python3.7/site-packages/airflow/models/baseoperator.py", line 429, in apply_defaults
    result = func(self, **kwargs, default_args=default_args)
  File "/home/airflow/.local/lib/python3.7/site-packages/airflow/operators/python.py", line 168, in __init__
    raise AirflowException("`python_callable` param must be callable")
airflow.exceptions.AirflowException: `python_callable` param must be callable
[2025-03-02T23:40:44.780+0000] {processor.py:838} WARNING - No viable dags retrieved from /opt/airflow/dags/dag_pipeline_generate_data.py
[2025-03-02T23:40:46.054+0000] {processor.py:179} INFO - Processing /opt/airflow/dags/dag_pipeline_generate_data.py took 4.441 seconds
[2025-03-02T23:41:16.721+0000] {processor.py:157} INFO - Started process (PID=2515) to work on /opt/airflow/dags/dag_pipeline_generate_data.py
[2025-03-02T23:41:16.722+0000] {processor.py:826} INFO - Processing file /opt/airflow/dags/dag_pipeline_generate_data.py for tasks to queue
[2025-03-02T23:41:16.723+0000] {logging_mixin.py:149} INFO - [2025-03-02T23:41:16.723+0000] {dagbag.py:541} INFO - Filling up the DagBag from /opt/airflow/dags/dag_pipeline_generate_data.py
[2025-03-02T23:41:22.983+0000] {logging_mixin.py:149} INFO - [2025-03-02T23:41:22.977+0000] {dagbag.py:350} ERROR - Failed to import: /opt/airflow/dags/dag_pipeline_generate_data.py
Traceback (most recent call last):
  File "/home/airflow/.local/lib/python3.7/site-packages/airflow/models/dagbag.py", line 346, in parse
    loader.exec_module(new_module)
  File "<frozen importlib._bootstrap_external>", line 728, in exec_module
  File "<frozen importlib._bootstrap>", line 219, in _call_with_frames_removed
  File "/opt/airflow/dags/dag_pipeline_generate_data.py", line 26, in <module>
    dag=dag,
  File "/home/airflow/.local/lib/python3.7/site-packages/airflow/models/baseoperator.py", line 429, in apply_defaults
    result = func(self, **kwargs, default_args=default_args)
  File "/home/airflow/.local/lib/python3.7/site-packages/airflow/operators/python.py", line 168, in __init__
    raise AirflowException("`python_callable` param must be callable")
airflow.exceptions.AirflowException: `python_callable` param must be callable
[2025-03-02T23:41:22.984+0000] {processor.py:838} WARNING - No viable dags retrieved from /opt/airflow/dags/dag_pipeline_generate_data.py
[2025-03-02T23:41:23.258+0000] {processor.py:179} INFO - Processing /opt/airflow/dags/dag_pipeline_generate_data.py took 6.540 seconds
[2025-03-02T23:41:53.749+0000] {processor.py:157} INFO - Started process (PID=2546) to work on /opt/airflow/dags/dag_pipeline_generate_data.py
[2025-03-02T23:41:53.750+0000] {processor.py:826} INFO - Processing file /opt/airflow/dags/dag_pipeline_generate_data.py for tasks to queue
[2025-03-02T23:41:53.751+0000] {logging_mixin.py:149} INFO - [2025-03-02T23:41:53.751+0000] {dagbag.py:541} INFO - Filling up the DagBag from /opt/airflow/dags/dag_pipeline_generate_data.py
[2025-03-02T23:41:59.757+0000] {logging_mixin.py:149} INFO - [2025-03-02T23:41:59.750+0000] {dagbag.py:350} ERROR - Failed to import: /opt/airflow/dags/dag_pipeline_generate_data.py
Traceback (most recent call last):
  File "/home/airflow/.local/lib/python3.7/site-packages/airflow/models/dagbag.py", line 346, in parse
    loader.exec_module(new_module)
  File "<frozen importlib._bootstrap_external>", line 728, in exec_module
  File "<frozen importlib._bootstrap>", line 219, in _call_with_frames_removed
  File "/opt/airflow/dags/dag_pipeline_generate_data.py", line 26, in <module>
    dag=dag,
  File "/home/airflow/.local/lib/python3.7/site-packages/airflow/models/baseoperator.py", line 429, in apply_defaults
    result = func(self, **kwargs, default_args=default_args)
  File "/home/airflow/.local/lib/python3.7/site-packages/airflow/operators/python.py", line 168, in __init__
    raise AirflowException("`python_callable` param must be callable")
airflow.exceptions.AirflowException: `python_callable` param must be callable
[2025-03-02T23:41:59.758+0000] {processor.py:838} WARNING - No viable dags retrieved from /opt/airflow/dags/dag_pipeline_generate_data.py
[2025-03-02T23:42:14.736+0000] {processor.py:179} INFO - Processing /opt/airflow/dags/dag_pipeline_generate_data.py took 18.055 seconds
[2025-03-02T23:42:44.874+0000] {processor.py:157} INFO - Started process (PID=2569) to work on /opt/airflow/dags/dag_pipeline_generate_data.py
[2025-03-02T23:42:44.875+0000] {processor.py:826} INFO - Processing file /opt/airflow/dags/dag_pipeline_generate_data.py for tasks to queue
[2025-03-02T23:42:44.876+0000] {logging_mixin.py:149} INFO - [2025-03-02T23:42:44.876+0000] {dagbag.py:541} INFO - Filling up the DagBag from /opt/airflow/dags/dag_pipeline_generate_data.py
[2025-03-02T23:42:48.547+0000] {logging_mixin.py:149} INFO - [2025-03-02T23:42:48.542+0000] {dagbag.py:350} ERROR - Failed to import: /opt/airflow/dags/dag_pipeline_generate_data.py
Traceback (most recent call last):
  File "/home/airflow/.local/lib/python3.7/site-packages/airflow/models/dagbag.py", line 346, in parse
    loader.exec_module(new_module)
  File "<frozen importlib._bootstrap_external>", line 728, in exec_module
  File "<frozen importlib._bootstrap>", line 219, in _call_with_frames_removed
  File "/opt/airflow/dags/dag_pipeline_generate_data.py", line 26, in <module>
    dag=dag,
  File "/home/airflow/.local/lib/python3.7/site-packages/airflow/models/baseoperator.py", line 429, in apply_defaults
    result = func(self, **kwargs, default_args=default_args)
  File "/home/airflow/.local/lib/python3.7/site-packages/airflow/operators/python.py", line 168, in __init__
    raise AirflowException("`python_callable` param must be callable")
airflow.exceptions.AirflowException: `python_callable` param must be callable
[2025-03-02T23:42:48.548+0000] {processor.py:838} WARNING - No viable dags retrieved from /opt/airflow/dags/dag_pipeline_generate_data.py
[2025-03-02T23:42:48.752+0000] {processor.py:179} INFO - Processing /opt/airflow/dags/dag_pipeline_generate_data.py took 3.881 seconds
[2025-03-02T23:43:19.225+0000] {processor.py:157} INFO - Started process (PID=2600) to work on /opt/airflow/dags/dag_pipeline_generate_data.py
[2025-03-02T23:43:19.226+0000] {processor.py:826} INFO - Processing file /opt/airflow/dags/dag_pipeline_generate_data.py for tasks to queue
[2025-03-02T23:43:19.227+0000] {logging_mixin.py:149} INFO - [2025-03-02T23:43:19.227+0000] {dagbag.py:541} INFO - Filling up the DagBag from /opt/airflow/dags/dag_pipeline_generate_data.py
[2025-03-02T23:43:22.559+0000] {logging_mixin.py:149} INFO - [2025-03-02T23:43:22.553+0000] {dagbag.py:350} ERROR - Failed to import: /opt/airflow/dags/dag_pipeline_generate_data.py
Traceback (most recent call last):
  File "/home/airflow/.local/lib/python3.7/site-packages/airflow/models/dagbag.py", line 346, in parse
    loader.exec_module(new_module)
  File "<frozen importlib._bootstrap_external>", line 728, in exec_module
  File "<frozen importlib._bootstrap>", line 219, in _call_with_frames_removed
  File "/opt/airflow/dags/dag_pipeline_generate_data.py", line 26, in <module>
    dag=dag,
  File "/home/airflow/.local/lib/python3.7/site-packages/airflow/models/baseoperator.py", line 429, in apply_defaults
    result = func(self, **kwargs, default_args=default_args)
  File "/home/airflow/.local/lib/python3.7/site-packages/airflow/operators/python.py", line 168, in __init__
    raise AirflowException("`python_callable` param must be callable")
airflow.exceptions.AirflowException: `python_callable` param must be callable
[2025-03-02T23:43:22.560+0000] {processor.py:838} WARNING - No viable dags retrieved from /opt/airflow/dags/dag_pipeline_generate_data.py
[2025-03-02T23:43:22.651+0000] {processor.py:179} INFO - Processing /opt/airflow/dags/dag_pipeline_generate_data.py took 3.429 seconds
[2025-03-02T23:43:53.225+0000] {processor.py:157} INFO - Started process (PID=2628) to work on /opt/airflow/dags/dag_pipeline_generate_data.py
[2025-03-02T23:43:53.226+0000] {processor.py:826} INFO - Processing file /opt/airflow/dags/dag_pipeline_generate_data.py for tasks to queue
[2025-03-02T23:43:53.227+0000] {logging_mixin.py:149} INFO - [2025-03-02T23:43:53.227+0000] {dagbag.py:541} INFO - Filling up the DagBag from /opt/airflow/dags/dag_pipeline_generate_data.py
[2025-03-02T23:43:59.855+0000] {logging_mixin.py:149} INFO - [2025-03-02T23:43:59.843+0000] {dagbag.py:350} ERROR - Failed to import: /opt/airflow/dags/dag_pipeline_generate_data.py
Traceback (most recent call last):
  File "/home/airflow/.local/lib/python3.7/site-packages/airflow/models/dagbag.py", line 346, in parse
    loader.exec_module(new_module)
  File "<frozen importlib._bootstrap_external>", line 728, in exec_module
  File "<frozen importlib._bootstrap>", line 219, in _call_with_frames_removed
  File "/opt/airflow/dags/dag_pipeline_generate_data.py", line 26, in <module>
    dag=dag,
  File "/home/airflow/.local/lib/python3.7/site-packages/airflow/models/baseoperator.py", line 429, in apply_defaults
    result = func(self, **kwargs, default_args=default_args)
  File "/home/airflow/.local/lib/python3.7/site-packages/airflow/operators/python.py", line 168, in __init__
    raise AirflowException("`python_callable` param must be callable")
airflow.exceptions.AirflowException: `python_callable` param must be callable
[2025-03-02T23:43:59.856+0000] {processor.py:838} WARNING - No viable dags retrieved from /opt/airflow/dags/dag_pipeline_generate_data.py
[2025-03-02T23:43:59.969+0000] {processor.py:179} INFO - Processing /opt/airflow/dags/dag_pipeline_generate_data.py took 3.589 seconds
[2025-03-02T23:44:30.136+0000] {processor.py:157} INFO - Started process (PID=2659) to work on /opt/airflow/dags/dag_pipeline_generate_data.py
[2025-03-02T23:44:30.137+0000] {processor.py:826} INFO - Processing file /opt/airflow/dags/dag_pipeline_generate_data.py for tasks to queue
[2025-03-02T23:44:30.138+0000] {logging_mixin.py:149} INFO - [2025-03-02T23:44:30.138+0000] {dagbag.py:541} INFO - Filling up the DagBag from /opt/airflow/dags/dag_pipeline_generate_data.py
[2025-03-02T23:44:33.950+0000] {logging_mixin.py:149} INFO - [2025-03-02T23:44:33.944+0000] {dagbag.py:350} ERROR - Failed to import: /opt/airflow/dags/dag_pipeline_generate_data.py
Traceback (most recent call last):
  File "/home/airflow/.local/lib/python3.7/site-packages/airflow/models/dagbag.py", line 346, in parse
    loader.exec_module(new_module)
  File "<frozen importlib._bootstrap_external>", line 728, in exec_module
  File "<frozen importlib._bootstrap>", line 219, in _call_with_frames_removed
  File "/opt/airflow/dags/dag_pipeline_generate_data.py", line 26, in <module>
    dag=dag,
  File "/home/airflow/.local/lib/python3.7/site-packages/airflow/models/baseoperator.py", line 429, in apply_defaults
    result = func(self, **kwargs, default_args=default_args)
  File "/home/airflow/.local/lib/python3.7/site-packages/airflow/operators/python.py", line 168, in __init__
    raise AirflowException("`python_callable` param must be callable")
airflow.exceptions.AirflowException: `python_callable` param must be callable
[2025-03-02T23:44:33.951+0000] {processor.py:838} WARNING - No viable dags retrieved from /opt/airflow/dags/dag_pipeline_generate_data.py
[2025-03-02T23:44:34.443+0000] {processor.py:179} INFO - Processing /opt/airflow/dags/dag_pipeline_generate_data.py took 4.311 seconds
[2025-03-02T23:45:05.306+0000] {processor.py:157} INFO - Started process (PID=2695) to work on /opt/airflow/dags/dag_pipeline_generate_data.py
[2025-03-02T23:45:05.307+0000] {processor.py:826} INFO - Processing file /opt/airflow/dags/dag_pipeline_generate_data.py for tasks to queue
[2025-03-02T23:45:05.308+0000] {logging_mixin.py:149} INFO - [2025-03-02T23:45:05.308+0000] {dagbag.py:541} INFO - Filling up the DagBag from /opt/airflow/dags/dag_pipeline_generate_data.py
[2025-03-02T23:45:08.691+0000] {logging_mixin.py:149} INFO - [2025-03-02T23:45:08.686+0000] {dagbag.py:350} ERROR - Failed to import: /opt/airflow/dags/dag_pipeline_generate_data.py
Traceback (most recent call last):
  File "/home/airflow/.local/lib/python3.7/site-packages/airflow/models/dagbag.py", line 346, in parse
    loader.exec_module(new_module)
  File "<frozen importlib._bootstrap_external>", line 728, in exec_module
  File "<frozen importlib._bootstrap>", line 219, in _call_with_frames_removed
  File "/opt/airflow/dags/dag_pipeline_generate_data.py", line 26, in <module>
    dag=dag,
  File "/home/airflow/.local/lib/python3.7/site-packages/airflow/models/baseoperator.py", line 429, in apply_defaults
    result = func(self, **kwargs, default_args=default_args)
  File "/home/airflow/.local/lib/python3.7/site-packages/airflow/operators/python.py", line 168, in __init__
    raise AirflowException("`python_callable` param must be callable")
airflow.exceptions.AirflowException: `python_callable` param must be callable
[2025-03-02T23:45:08.692+0000] {processor.py:838} WARNING - No viable dags retrieved from /opt/airflow/dags/dag_pipeline_generate_data.py
[2025-03-02T23:45:09.383+0000] {processor.py:179} INFO - Processing /opt/airflow/dags/dag_pipeline_generate_data.py took 4.081 seconds
[2025-03-02T23:45:39.653+0000] {processor.py:157} INFO - Started process (PID=2733) to work on /opt/airflow/dags/dag_pipeline_generate_data.py
[2025-03-02T23:45:39.654+0000] {processor.py:826} INFO - Processing file /opt/airflow/dags/dag_pipeline_generate_data.py for tasks to queue
[2025-03-02T23:45:39.655+0000] {logging_mixin.py:149} INFO - [2025-03-02T23:45:39.655+0000] {dagbag.py:541} INFO - Filling up the DagBag from /opt/airflow/dags/dag_pipeline_generate_data.py
[2025-03-02T23:45:42.962+0000] {logging_mixin.py:149} INFO - [2025-03-02T23:45:42.956+0000] {dagbag.py:350} ERROR - Failed to import: /opt/airflow/dags/dag_pipeline_generate_data.py
Traceback (most recent call last):
  File "/home/airflow/.local/lib/python3.7/site-packages/airflow/models/dagbag.py", line 346, in parse
    loader.exec_module(new_module)
  File "<frozen importlib._bootstrap_external>", line 728, in exec_module
  File "<frozen importlib._bootstrap>", line 219, in _call_with_frames_removed
  File "/opt/airflow/dags/dag_pipeline_generate_data.py", line 26, in <module>
    dag=dag,
  File "/home/airflow/.local/lib/python3.7/site-packages/airflow/models/baseoperator.py", line 429, in apply_defaults
    result = func(self, **kwargs, default_args=default_args)
  File "/home/airflow/.local/lib/python3.7/site-packages/airflow/operators/python.py", line 168, in __init__
    raise AirflowException("`python_callable` param must be callable")
airflow.exceptions.AirflowException: `python_callable` param must be callable
[2025-03-02T23:45:42.963+0000] {processor.py:838} WARNING - No viable dags retrieved from /opt/airflow/dags/dag_pipeline_generate_data.py
[2025-03-02T23:45:44.861+0000] {processor.py:179} INFO - Processing /opt/airflow/dags/dag_pipeline_generate_data.py took 5.213 seconds
[2025-03-02T23:46:15.116+0000] {processor.py:157} INFO - Started process (PID=2778) to work on /opt/airflow/dags/dag_pipeline_generate_data.py
[2025-03-02T23:46:15.117+0000] {processor.py:826} INFO - Processing file /opt/airflow/dags/dag_pipeline_generate_data.py for tasks to queue
[2025-03-02T23:46:15.118+0000] {logging_mixin.py:149} INFO - [2025-03-02T23:46:15.118+0000] {dagbag.py:541} INFO - Filling up the DagBag from /opt/airflow/dags/dag_pipeline_generate_data.py
[2025-03-02T23:46:18.974+0000] {logging_mixin.py:149} INFO - [2025-03-02T23:46:18.969+0000] {dagbag.py:350} ERROR - Failed to import: /opt/airflow/dags/dag_pipeline_generate_data.py
Traceback (most recent call last):
  File "/home/airflow/.local/lib/python3.7/site-packages/airflow/models/dagbag.py", line 346, in parse
    loader.exec_module(new_module)
  File "<frozen importlib._bootstrap_external>", line 728, in exec_module
  File "<frozen importlib._bootstrap>", line 219, in _call_with_frames_removed
  File "/opt/airflow/dags/dag_pipeline_generate_data.py", line 26, in <module>
    dag=dag,
  File "/home/airflow/.local/lib/python3.7/site-packages/airflow/models/baseoperator.py", line 429, in apply_defaults
    result = func(self, **kwargs, default_args=default_args)
  File "/home/airflow/.local/lib/python3.7/site-packages/airflow/operators/python.py", line 168, in __init__
    raise AirflowException("`python_callable` param must be callable")
airflow.exceptions.AirflowException: `python_callable` param must be callable
[2025-03-02T23:46:18.974+0000] {processor.py:838} WARNING - No viable dags retrieved from /opt/airflow/dags/dag_pipeline_generate_data.py
[2025-03-02T23:46:27.380+0000] {processor.py:179} INFO - Processing /opt/airflow/dags/dag_pipeline_generate_data.py took 9.358 seconds
[2025-03-02T23:47:00.748+0000] {processor.py:157} INFO - Started process (PID=2809) to work on /opt/airflow/dags/dag_pipeline_generate_data.py
[2025-03-02T23:47:00.749+0000] {processor.py:826} INFO - Processing file /opt/airflow/dags/dag_pipeline_generate_data.py for tasks to queue
[2025-03-02T23:47:00.751+0000] {logging_mixin.py:149} INFO - [2025-03-02T23:47:00.751+0000] {dagbag.py:541} INFO - Filling up the DagBag from /opt/airflow/dags/dag_pipeline_generate_data.py
[2025-03-02T23:47:04.071+0000] {logging_mixin.py:149} INFO - [2025-03-02T23:47:04.065+0000] {dagbag.py:350} ERROR - Failed to import: /opt/airflow/dags/dag_pipeline_generate_data.py
Traceback (most recent call last):
  File "/home/airflow/.local/lib/python3.7/site-packages/airflow/models/dagbag.py", line 346, in parse
    loader.exec_module(new_module)
  File "<frozen importlib._bootstrap_external>", line 728, in exec_module
  File "<frozen importlib._bootstrap>", line 219, in _call_with_frames_removed
  File "/opt/airflow/dags/dag_pipeline_generate_data.py", line 26, in <module>
    dag=dag,
  File "/home/airflow/.local/lib/python3.7/site-packages/airflow/models/baseoperator.py", line 429, in apply_defaults
    result = func(self, **kwargs, default_args=default_args)
  File "/home/airflow/.local/lib/python3.7/site-packages/airflow/operators/python.py", line 168, in __init__
    raise AirflowException("`python_callable` param must be callable")
airflow.exceptions.AirflowException: `python_callable` param must be callable
[2025-03-02T23:47:04.071+0000] {processor.py:838} WARNING - No viable dags retrieved from /opt/airflow/dags/dag_pipeline_generate_data.py
[2025-03-02T23:47:04.543+0000] {processor.py:179} INFO - Processing /opt/airflow/dags/dag_pipeline_generate_data.py took 3.797 seconds
[2025-03-02T23:47:34.946+0000] {processor.py:157} INFO - Started process (PID=2840) to work on /opt/airflow/dags/dag_pipeline_generate_data.py
[2025-03-02T23:47:34.947+0000] {processor.py:826} INFO - Processing file /opt/airflow/dags/dag_pipeline_generate_data.py for tasks to queue
[2025-03-02T23:47:34.948+0000] {logging_mixin.py:149} INFO - [2025-03-02T23:47:34.948+0000] {dagbag.py:541} INFO - Filling up the DagBag from /opt/airflow/dags/dag_pipeline_generate_data.py
[2025-03-02T23:47:38.365+0000] {logging_mixin.py:149} INFO - [2025-03-02T23:47:38.359+0000] {dagbag.py:350} ERROR - Failed to import: /opt/airflow/dags/dag_pipeline_generate_data.py
Traceback (most recent call last):
  File "/home/airflow/.local/lib/python3.7/site-packages/airflow/models/dagbag.py", line 346, in parse
    loader.exec_module(new_module)
  File "<frozen importlib._bootstrap_external>", line 728, in exec_module
  File "<frozen importlib._bootstrap>", line 219, in _call_with_frames_removed
  File "/opt/airflow/dags/dag_pipeline_generate_data.py", line 26, in <module>
    dag=dag,
  File "/home/airflow/.local/lib/python3.7/site-packages/airflow/models/baseoperator.py", line 429, in apply_defaults
    result = func(self, **kwargs, default_args=default_args)
  File "/home/airflow/.local/lib/python3.7/site-packages/airflow/operators/python.py", line 168, in __init__
    raise AirflowException("`python_callable` param must be callable")
airflow.exceptions.AirflowException: `python_callable` param must be callable
[2025-03-02T23:47:38.366+0000] {processor.py:838} WARNING - No viable dags retrieved from /opt/airflow/dags/dag_pipeline_generate_data.py
[2025-03-02T23:47:38.572+0000] {processor.py:179} INFO - Processing /opt/airflow/dags/dag_pipeline_generate_data.py took 3.629 seconds
[2025-03-02T23:48:08.781+0000] {processor.py:157} INFO - Started process (PID=2871) to work on /opt/airflow/dags/dag_pipeline_generate_data.py
[2025-03-02T23:48:08.782+0000] {processor.py:826} INFO - Processing file /opt/airflow/dags/dag_pipeline_generate_data.py for tasks to queue
[2025-03-02T23:48:08.783+0000] {logging_mixin.py:149} INFO - [2025-03-02T23:48:08.783+0000] {dagbag.py:541} INFO - Filling up the DagBag from /opt/airflow/dags/dag_pipeline_generate_data.py
[2025-03-02T23:48:12.080+0000] {logging_mixin.py:149} INFO - [2025-03-02T23:48:12.075+0000] {dagbag.py:350} ERROR - Failed to import: /opt/airflow/dags/dag_pipeline_generate_data.py
Traceback (most recent call last):
  File "/home/airflow/.local/lib/python3.7/site-packages/airflow/models/dagbag.py", line 346, in parse
    loader.exec_module(new_module)
  File "<frozen importlib._bootstrap_external>", line 728, in exec_module
  File "<frozen importlib._bootstrap>", line 219, in _call_with_frames_removed
  File "/opt/airflow/dags/dag_pipeline_generate_data.py", line 26, in <module>
    dag=dag,
  File "/home/airflow/.local/lib/python3.7/site-packages/airflow/models/baseoperator.py", line 429, in apply_defaults
    result = func(self, **kwargs, default_args=default_args)
  File "/home/airflow/.local/lib/python3.7/site-packages/airflow/operators/python.py", line 168, in __init__
    raise AirflowException("`python_callable` param must be callable")
airflow.exceptions.AirflowException: `python_callable` param must be callable
[2025-03-02T23:48:12.081+0000] {processor.py:838} WARNING - No viable dags retrieved from /opt/airflow/dags/dag_pipeline_generate_data.py
[2025-03-02T23:48:12.754+0000] {processor.py:179} INFO - Processing /opt/airflow/dags/dag_pipeline_generate_data.py took 3.976 seconds
[2025-03-02T23:48:42.921+0000] {processor.py:157} INFO - Started process (PID=2902) to work on /opt/airflow/dags/dag_pipeline_generate_data.py
[2025-03-02T23:48:42.922+0000] {processor.py:826} INFO - Processing file /opt/airflow/dags/dag_pipeline_generate_data.py for tasks to queue
[2025-03-02T23:48:42.923+0000] {logging_mixin.py:149} INFO - [2025-03-02T23:48:42.923+0000] {dagbag.py:541} INFO - Filling up the DagBag from /opt/airflow/dags/dag_pipeline_generate_data.py
[2025-03-02T23:48:46.082+0000] {logging_mixin.py:149} INFO - [2025-03-02T23:48:46.076+0000] {dagbag.py:350} ERROR - Failed to import: /opt/airflow/dags/dag_pipeline_generate_data.py
Traceback (most recent call last):
  File "/home/airflow/.local/lib/python3.7/site-packages/airflow/models/dagbag.py", line 346, in parse
    loader.exec_module(new_module)
  File "<frozen importlib._bootstrap_external>", line 728, in exec_module
  File "<frozen importlib._bootstrap>", line 219, in _call_with_frames_removed
  File "/opt/airflow/dags/dag_pipeline_generate_data.py", line 26, in <module>
    dag=dag,
  File "/home/airflow/.local/lib/python3.7/site-packages/airflow/models/baseoperator.py", line 429, in apply_defaults
    result = func(self, **kwargs, default_args=default_args)
  File "/home/airflow/.local/lib/python3.7/site-packages/airflow/operators/python.py", line 168, in __init__
    raise AirflowException("`python_callable` param must be callable")
airflow.exceptions.AirflowException: `python_callable` param must be callable
[2025-03-02T23:48:46.083+0000] {processor.py:838} WARNING - No viable dags retrieved from /opt/airflow/dags/dag_pipeline_generate_data.py
[2025-03-02T23:48:46.880+0000] {processor.py:179} INFO - Processing /opt/airflow/dags/dag_pipeline_generate_data.py took 3.962 seconds
[2025-03-02T23:49:17.516+0000] {processor.py:157} INFO - Started process (PID=2933) to work on /opt/airflow/dags/dag_pipeline_generate_data.py
[2025-03-02T23:49:17.517+0000] {processor.py:826} INFO - Processing file /opt/airflow/dags/dag_pipeline_generate_data.py for tasks to queue
[2025-03-02T23:49:17.519+0000] {logging_mixin.py:149} INFO - [2025-03-02T23:49:17.519+0000] {dagbag.py:541} INFO - Filling up the DagBag from /opt/airflow/dags/dag_pipeline_generate_data.py
[2025-03-02T23:49:21.227+0000] {logging_mixin.py:149} INFO - [2025-03-02T23:49:21.221+0000] {dagbag.py:350} ERROR - Failed to import: /opt/airflow/dags/dag_pipeline_generate_data.py
Traceback (most recent call last):
  File "/home/airflow/.local/lib/python3.7/site-packages/airflow/models/dagbag.py", line 346, in parse
    loader.exec_module(new_module)
  File "<frozen importlib._bootstrap_external>", line 728, in exec_module
  File "<frozen importlib._bootstrap>", line 219, in _call_with_frames_removed
  File "/opt/airflow/dags/dag_pipeline_generate_data.py", line 26, in <module>
    dag=dag,
  File "/home/airflow/.local/lib/python3.7/site-packages/airflow/models/baseoperator.py", line 429, in apply_defaults
    result = func(self, **kwargs, default_args=default_args)
  File "/home/airflow/.local/lib/python3.7/site-packages/airflow/operators/python.py", line 168, in __init__
    raise AirflowException("`python_callable` param must be callable")
airflow.exceptions.AirflowException: `python_callable` param must be callable
[2025-03-02T23:49:21.228+0000] {processor.py:838} WARNING - No viable dags retrieved from /opt/airflow/dags/dag_pipeline_generate_data.py
[2025-03-02T23:49:21.551+0000] {processor.py:179} INFO - Processing /opt/airflow/dags/dag_pipeline_generate_data.py took 4.038 seconds
[2025-03-02T23:49:52.468+0000] {processor.py:157} INFO - Started process (PID=2969) to work on /opt/airflow/dags/dag_pipeline_generate_data.py
[2025-03-02T23:49:52.469+0000] {processor.py:826} INFO - Processing file /opt/airflow/dags/dag_pipeline_generate_data.py for tasks to queue
[2025-03-02T23:49:52.470+0000] {logging_mixin.py:149} INFO - [2025-03-02T23:49:52.470+0000] {dagbag.py:541} INFO - Filling up the DagBag from /opt/airflow/dags/dag_pipeline_generate_data.py
[2025-03-02T23:49:55.654+0000] {logging_mixin.py:149} INFO - [2025-03-02T23:49:55.649+0000] {dagbag.py:350} ERROR - Failed to import: /opt/airflow/dags/dag_pipeline_generate_data.py
Traceback (most recent call last):
  File "/home/airflow/.local/lib/python3.7/site-packages/airflow/models/dagbag.py", line 346, in parse
    loader.exec_module(new_module)
  File "<frozen importlib._bootstrap_external>", line 728, in exec_module
  File "<frozen importlib._bootstrap>", line 219, in _call_with_frames_removed
  File "/opt/airflow/dags/dag_pipeline_generate_data.py", line 26, in <module>
    dag=dag,
  File "/home/airflow/.local/lib/python3.7/site-packages/airflow/models/baseoperator.py", line 429, in apply_defaults
    result = func(self, **kwargs, default_args=default_args)
  File "/home/airflow/.local/lib/python3.7/site-packages/airflow/operators/python.py", line 168, in __init__
    raise AirflowException("`python_callable` param must be callable")
airflow.exceptions.AirflowException: `python_callable` param must be callable
[2025-03-02T23:49:55.655+0000] {processor.py:838} WARNING - No viable dags retrieved from /opt/airflow/dags/dag_pipeline_generate_data.py
[2025-03-02T23:49:55.714+0000] {processor.py:179} INFO - Processing /opt/airflow/dags/dag_pipeline_generate_data.py took 3.249 seconds
[2025-03-02T23:50:26.139+0000] {processor.py:157} INFO - Started process (PID=3000) to work on /opt/airflow/dags/dag_pipeline_generate_data.py
[2025-03-02T23:50:26.140+0000] {processor.py:826} INFO - Processing file /opt/airflow/dags/dag_pipeline_generate_data.py for tasks to queue
[2025-03-02T23:50:26.141+0000] {logging_mixin.py:149} INFO - [2025-03-02T23:50:26.141+0000] {dagbag.py:541} INFO - Filling up the DagBag from /opt/airflow/dags/dag_pipeline_generate_data.py
[2025-03-02T23:50:29.365+0000] {logging_mixin.py:149} INFO - [2025-03-02T23:50:29.360+0000] {dagbag.py:350} ERROR - Failed to import: /opt/airflow/dags/dag_pipeline_generate_data.py
Traceback (most recent call last):
  File "/home/airflow/.local/lib/python3.7/site-packages/airflow/models/dagbag.py", line 346, in parse
    loader.exec_module(new_module)
  File "<frozen importlib._bootstrap_external>", line 728, in exec_module
  File "<frozen importlib._bootstrap>", line 219, in _call_with_frames_removed
  File "/opt/airflow/dags/dag_pipeline_generate_data.py", line 26, in <module>
    dag=dag,
  File "/home/airflow/.local/lib/python3.7/site-packages/airflow/models/baseoperator.py", line 429, in apply_defaults
    result = func(self, **kwargs, default_args=default_args)
  File "/home/airflow/.local/lib/python3.7/site-packages/airflow/operators/python.py", line 168, in __init__
    raise AirflowException("`python_callable` param must be callable")
airflow.exceptions.AirflowException: `python_callable` param must be callable
[2025-03-02T23:50:29.366+0000] {processor.py:838} WARNING - No viable dags retrieved from /opt/airflow/dags/dag_pipeline_generate_data.py
[2025-03-02T23:50:30.113+0000] {processor.py:179} INFO - Processing /opt/airflow/dags/dag_pipeline_generate_data.py took 3.977 seconds
[2025-03-02T23:51:00.175+0000] {processor.py:157} INFO - Started process (PID=3031) to work on /opt/airflow/dags/dag_pipeline_generate_data.py
[2025-03-02T23:51:00.176+0000] {processor.py:826} INFO - Processing file /opt/airflow/dags/dag_pipeline_generate_data.py for tasks to queue
[2025-03-02T23:51:00.177+0000] {logging_mixin.py:149} INFO - [2025-03-02T23:51:00.177+0000] {dagbag.py:541} INFO - Filling up the DagBag from /opt/airflow/dags/dag_pipeline_generate_data.py
[2025-03-02T23:51:03.209+0000] {logging_mixin.py:149} INFO - [2025-03-02T23:51:03.204+0000] {dagbag.py:350} ERROR - Failed to import: /opt/airflow/dags/dag_pipeline_generate_data.py
Traceback (most recent call last):
  File "/home/airflow/.local/lib/python3.7/site-packages/airflow/models/dagbag.py", line 346, in parse
    loader.exec_module(new_module)
  File "<frozen importlib._bootstrap_external>", line 728, in exec_module
  File "<frozen importlib._bootstrap>", line 219, in _call_with_frames_removed
  File "/opt/airflow/dags/dag_pipeline_generate_data.py", line 26, in <module>
    dag=dag,
  File "/home/airflow/.local/lib/python3.7/site-packages/airflow/models/baseoperator.py", line 429, in apply_defaults
    result = func(self, **kwargs, default_args=default_args)
  File "/home/airflow/.local/lib/python3.7/site-packages/airflow/operators/python.py", line 168, in __init__
    raise AirflowException("`python_callable` param must be callable")
airflow.exceptions.AirflowException: `python_callable` param must be callable
[2025-03-02T23:51:03.210+0000] {processor.py:838} WARNING - No viable dags retrieved from /opt/airflow/dags/dag_pipeline_generate_data.py
[2025-03-02T23:51:03.451+0000] {processor.py:179} INFO - Processing /opt/airflow/dags/dag_pipeline_generate_data.py took 3.279 seconds
[2025-03-02T23:51:33.607+0000] {processor.py:157} INFO - Started process (PID=3062) to work on /opt/airflow/dags/dag_pipeline_generate_data.py
[2025-03-02T23:51:33.608+0000] {processor.py:826} INFO - Processing file /opt/airflow/dags/dag_pipeline_generate_data.py for tasks to queue
[2025-03-02T23:51:33.609+0000] {logging_mixin.py:149} INFO - [2025-03-02T23:51:33.609+0000] {dagbag.py:541} INFO - Filling up the DagBag from /opt/airflow/dags/dag_pipeline_generate_data.py
[2025-03-02T23:51:36.621+0000] {logging_mixin.py:149} INFO - [2025-03-02T23:51:36.617+0000] {dagbag.py:350} ERROR - Failed to import: /opt/airflow/dags/dag_pipeline_generate_data.py
Traceback (most recent call last):
  File "/home/airflow/.local/lib/python3.7/site-packages/airflow/models/dagbag.py", line 346, in parse
    loader.exec_module(new_module)
  File "<frozen importlib._bootstrap_external>", line 728, in exec_module
  File "<frozen importlib._bootstrap>", line 219, in _call_with_frames_removed
  File "/opt/airflow/dags/dag_pipeline_generate_data.py", line 26, in <module>
    dag=dag,
  File "/home/airflow/.local/lib/python3.7/site-packages/airflow/models/baseoperator.py", line 429, in apply_defaults
    result = func(self, **kwargs, default_args=default_args)
  File "/home/airflow/.local/lib/python3.7/site-packages/airflow/operators/python.py", line 168, in __init__
    raise AirflowException("`python_callable` param must be callable")
airflow.exceptions.AirflowException: `python_callable` param must be callable
[2025-03-02T23:51:36.622+0000] {processor.py:838} WARNING - No viable dags retrieved from /opt/airflow/dags/dag_pipeline_generate_data.py
[2025-03-02T23:51:36.857+0000] {processor.py:179} INFO - Processing /opt/airflow/dags/dag_pipeline_generate_data.py took 3.252 seconds
[2025-03-02T23:52:07.144+0000] {processor.py:157} INFO - Started process (PID=3093) to work on /opt/airflow/dags/dag_pipeline_generate_data.py
[2025-03-02T23:52:07.145+0000] {processor.py:826} INFO - Processing file /opt/airflow/dags/dag_pipeline_generate_data.py for tasks to queue
[2025-03-02T23:52:07.146+0000] {logging_mixin.py:149} INFO - [2025-03-02T23:52:07.146+0000] {dagbag.py:541} INFO - Filling up the DagBag from /opt/airflow/dags/dag_pipeline_generate_data.py
[2025-03-02T23:52:10.423+0000] {logging_mixin.py:149} INFO - [2025-03-02T23:52:10.418+0000] {dagbag.py:350} ERROR - Failed to import: /opt/airflow/dags/dag_pipeline_generate_data.py
Traceback (most recent call last):
  File "/home/airflow/.local/lib/python3.7/site-packages/airflow/models/dagbag.py", line 346, in parse
    loader.exec_module(new_module)
  File "<frozen importlib._bootstrap_external>", line 728, in exec_module
  File "<frozen importlib._bootstrap>", line 219, in _call_with_frames_removed
  File "/opt/airflow/dags/dag_pipeline_generate_data.py", line 26, in <module>
    dag=dag,
  File "/home/airflow/.local/lib/python3.7/site-packages/airflow/models/baseoperator.py", line 429, in apply_defaults
    result = func(self, **kwargs, default_args=default_args)
  File "/home/airflow/.local/lib/python3.7/site-packages/airflow/operators/python.py", line 168, in __init__
    raise AirflowException("`python_callable` param must be callable")
airflow.exceptions.AirflowException: `python_callable` param must be callable
[2025-03-02T23:52:10.424+0000] {processor.py:838} WARNING - No viable dags retrieved from /opt/airflow/dags/dag_pipeline_generate_data.py
[2025-03-02T23:52:10.637+0000] {processor.py:179} INFO - Processing /opt/airflow/dags/dag_pipeline_generate_data.py took 3.496 seconds
[2025-03-02T23:52:41.088+0000] {processor.py:157} INFO - Started process (PID=3124) to work on /opt/airflow/dags/dag_pipeline_generate_data.py
[2025-03-02T23:52:41.089+0000] {processor.py:826} INFO - Processing file /opt/airflow/dags/dag_pipeline_generate_data.py for tasks to queue
[2025-03-02T23:52:41.091+0000] {logging_mixin.py:149} INFO - [2025-03-02T23:52:41.091+0000] {dagbag.py:541} INFO - Filling up the DagBag from /opt/airflow/dags/dag_pipeline_generate_data.py
[2025-03-02T23:52:44.456+0000] {logging_mixin.py:149} INFO - [2025-03-02T23:52:44.450+0000] {dagbag.py:350} ERROR - Failed to import: /opt/airflow/dags/dag_pipeline_generate_data.py
Traceback (most recent call last):
  File "/home/airflow/.local/lib/python3.7/site-packages/airflow/models/dagbag.py", line 346, in parse
    loader.exec_module(new_module)
  File "<frozen importlib._bootstrap_external>", line 728, in exec_module
  File "<frozen importlib._bootstrap>", line 219, in _call_with_frames_removed
  File "/opt/airflow/dags/dag_pipeline_generate_data.py", line 26, in <module>
    dag=dag,
  File "/home/airflow/.local/lib/python3.7/site-packages/airflow/models/baseoperator.py", line 429, in apply_defaults
    result = func(self, **kwargs, default_args=default_args)
  File "/home/airflow/.local/lib/python3.7/site-packages/airflow/operators/python.py", line 168, in __init__
    raise AirflowException("`python_callable` param must be callable")
airflow.exceptions.AirflowException: `python_callable` param must be callable
[2025-03-02T23:52:44.457+0000] {processor.py:838} WARNING - No viable dags retrieved from /opt/airflow/dags/dag_pipeline_generate_data.py
[2025-03-02T23:52:44.995+0000] {processor.py:179} INFO - Processing /opt/airflow/dags/dag_pipeline_generate_data.py took 3.910 seconds
[2025-03-02T23:53:15.088+0000] {processor.py:157} INFO - Started process (PID=3155) to work on /opt/airflow/dags/dag_pipeline_generate_data.py
[2025-03-02T23:53:15.089+0000] {processor.py:826} INFO - Processing file /opt/airflow/dags/dag_pipeline_generate_data.py for tasks to queue
[2025-03-02T23:53:15.090+0000] {logging_mixin.py:149} INFO - [2025-03-02T23:53:15.090+0000] {dagbag.py:541} INFO - Filling up the DagBag from /opt/airflow/dags/dag_pipeline_generate_data.py
[2025-03-02T23:53:18.325+0000] {logging_mixin.py:149} INFO - [2025-03-02T23:53:18.321+0000] {dagbag.py:350} ERROR - Failed to import: /opt/airflow/dags/dag_pipeline_generate_data.py
Traceback (most recent call last):
  File "/home/airflow/.local/lib/python3.7/site-packages/airflow/models/dagbag.py", line 346, in parse
    loader.exec_module(new_module)
  File "<frozen importlib._bootstrap_external>", line 728, in exec_module
  File "<frozen importlib._bootstrap>", line 219, in _call_with_frames_removed
  File "/opt/airflow/dags/dag_pipeline_generate_data.py", line 26, in <module>
    dag=dag,
  File "/home/airflow/.local/lib/python3.7/site-packages/airflow/models/baseoperator.py", line 429, in apply_defaults
    result = func(self, **kwargs, default_args=default_args)
  File "/home/airflow/.local/lib/python3.7/site-packages/airflow/operators/python.py", line 168, in __init__
    raise AirflowException("`python_callable` param must be callable")
airflow.exceptions.AirflowException: `python_callable` param must be callable
[2025-03-02T23:53:18.326+0000] {processor.py:838} WARNING - No viable dags retrieved from /opt/airflow/dags/dag_pipeline_generate_data.py
[2025-03-02T23:53:18.433+0000] {processor.py:179} INFO - Processing /opt/airflow/dags/dag_pipeline_generate_data.py took 3.349 seconds
[2025-03-02T23:53:48.922+0000] {processor.py:157} INFO - Started process (PID=3186) to work on /opt/airflow/dags/dag_pipeline_generate_data.py
[2025-03-02T23:53:48.923+0000] {processor.py:826} INFO - Processing file /opt/airflow/dags/dag_pipeline_generate_data.py for tasks to queue
[2025-03-02T23:53:48.924+0000] {logging_mixin.py:149} INFO - [2025-03-02T23:53:48.924+0000] {dagbag.py:541} INFO - Filling up the DagBag from /opt/airflow/dags/dag_pipeline_generate_data.py
[2025-03-02T23:53:52.438+0000] {logging_mixin.py:149} INFO - [2025-03-02T23:53:52.433+0000] {dagbag.py:350} ERROR - Failed to import: /opt/airflow/dags/dag_pipeline_generate_data.py
Traceback (most recent call last):
  File "/home/airflow/.local/lib/python3.7/site-packages/airflow/models/dagbag.py", line 346, in parse
    loader.exec_module(new_module)
  File "<frozen importlib._bootstrap_external>", line 728, in exec_module
  File "<frozen importlib._bootstrap>", line 219, in _call_with_frames_removed
  File "/opt/airflow/dags/dag_pipeline_generate_data.py", line 26, in <module>
    dag=dag,
  File "/home/airflow/.local/lib/python3.7/site-packages/airflow/models/baseoperator.py", line 429, in apply_defaults
    result = func(self, **kwargs, default_args=default_args)
  File "/home/airflow/.local/lib/python3.7/site-packages/airflow/operators/python.py", line 168, in __init__
    raise AirflowException("`python_callable` param must be callable")
airflow.exceptions.AirflowException: `python_callable` param must be callable
[2025-03-02T23:53:52.439+0000] {processor.py:838} WARNING - No viable dags retrieved from /opt/airflow/dags/dag_pipeline_generate_data.py
[2025-03-02T23:53:52.671+0000] {processor.py:179} INFO - Processing /opt/airflow/dags/dag_pipeline_generate_data.py took 3.752 seconds
[2025-03-02T23:54:25.194+0000] {processor.py:157} INFO - Started process (PID=3217) to work on /opt/airflow/dags/dag_pipeline_generate_data.py
[2025-03-02T23:54:25.195+0000] {processor.py:826} INFO - Processing file /opt/airflow/dags/dag_pipeline_generate_data.py for tasks to queue
[2025-03-02T23:54:25.196+0000] {logging_mixin.py:149} INFO - [2025-03-02T23:54:25.196+0000] {dagbag.py:541} INFO - Filling up the DagBag from /opt/airflow/dags/dag_pipeline_generate_data.py
[2025-03-02T23:54:28.310+0000] {logging_mixin.py:149} INFO - [2025-03-02T23:54:28.304+0000] {dagbag.py:350} ERROR - Failed to import: /opt/airflow/dags/dag_pipeline_generate_data.py
Traceback (most recent call last):
  File "/home/airflow/.local/lib/python3.7/site-packages/airflow/models/dagbag.py", line 346, in parse
    loader.exec_module(new_module)
  File "<frozen importlib._bootstrap_external>", line 728, in exec_module
  File "<frozen importlib._bootstrap>", line 219, in _call_with_frames_removed
  File "/opt/airflow/dags/dag_pipeline_generate_data.py", line 26, in <module>
    dag=dag,
  File "/home/airflow/.local/lib/python3.7/site-packages/airflow/models/baseoperator.py", line 429, in apply_defaults
    result = func(self, **kwargs, default_args=default_args)
  File "/home/airflow/.local/lib/python3.7/site-packages/airflow/operators/python.py", line 168, in __init__
    raise AirflowException("`python_callable` param must be callable")
airflow.exceptions.AirflowException: `python_callable` param must be callable
[2025-03-02T23:54:28.310+0000] {processor.py:838} WARNING - No viable dags retrieved from /opt/airflow/dags/dag_pipeline_generate_data.py
[2025-03-02T23:54:29.072+0000] {processor.py:179} INFO - Processing /opt/airflow/dags/dag_pipeline_generate_data.py took 3.881 seconds
[2025-03-02T23:54:59.406+0000] {processor.py:157} INFO - Started process (PID=3248) to work on /opt/airflow/dags/dag_pipeline_generate_data.py
[2025-03-02T23:54:59.407+0000] {processor.py:826} INFO - Processing file /opt/airflow/dags/dag_pipeline_generate_data.py for tasks to queue
[2025-03-02T23:54:59.408+0000] {logging_mixin.py:149} INFO - [2025-03-02T23:54:59.408+0000] {dagbag.py:541} INFO - Filling up the DagBag from /opt/airflow/dags/dag_pipeline_generate_data.py
[2025-03-02T23:55:02.691+0000] {logging_mixin.py:149} INFO - [2025-03-02T23:55:02.686+0000] {dagbag.py:350} ERROR - Failed to import: /opt/airflow/dags/dag_pipeline_generate_data.py
Traceback (most recent call last):
  File "/home/airflow/.local/lib/python3.7/site-packages/airflow/models/dagbag.py", line 346, in parse
    loader.exec_module(new_module)
  File "<frozen importlib._bootstrap_external>", line 728, in exec_module
  File "<frozen importlib._bootstrap>", line 219, in _call_with_frames_removed
  File "/opt/airflow/dags/dag_pipeline_generate_data.py", line 26, in <module>
    dag=dag,
  File "/home/airflow/.local/lib/python3.7/site-packages/airflow/models/baseoperator.py", line 429, in apply_defaults
    result = func(self, **kwargs, default_args=default_args)
  File "/home/airflow/.local/lib/python3.7/site-packages/airflow/operators/python.py", line 168, in __init__
    raise AirflowException("`python_callable` param must be callable")
airflow.exceptions.AirflowException: `python_callable` param must be callable
[2025-03-02T23:55:02.691+0000] {processor.py:838} WARNING - No viable dags retrieved from /opt/airflow/dags/dag_pipeline_generate_data.py
[2025-03-02T23:55:02.822+0000] {processor.py:179} INFO - Processing /opt/airflow/dags/dag_pipeline_generate_data.py took 3.418 seconds
[2025-03-02T23:55:33.609+0000] {processor.py:157} INFO - Started process (PID=3279) to work on /opt/airflow/dags/dag_pipeline_generate_data.py
[2025-03-02T23:55:33.610+0000] {processor.py:826} INFO - Processing file /opt/airflow/dags/dag_pipeline_generate_data.py for tasks to queue
[2025-03-02T23:55:33.611+0000] {logging_mixin.py:149} INFO - [2025-03-02T23:55:33.611+0000] {dagbag.py:541} INFO - Filling up the DagBag from /opt/airflow/dags/dag_pipeline_generate_data.py
[2025-03-02T23:55:36.970+0000] {logging_mixin.py:149} INFO - [2025-03-02T23:55:36.965+0000] {dagbag.py:350} ERROR - Failed to import: /opt/airflow/dags/dag_pipeline_generate_data.py
Traceback (most recent call last):
  File "/home/airflow/.local/lib/python3.7/site-packages/airflow/models/dagbag.py", line 346, in parse
    loader.exec_module(new_module)
  File "<frozen importlib._bootstrap_external>", line 728, in exec_module
  File "<frozen importlib._bootstrap>", line 219, in _call_with_frames_removed
  File "/opt/airflow/dags/dag_pipeline_generate_data.py", line 26, in <module>
    dag=dag,
  File "/home/airflow/.local/lib/python3.7/site-packages/airflow/models/baseoperator.py", line 429, in apply_defaults
    result = func(self, **kwargs, default_args=default_args)
  File "/home/airflow/.local/lib/python3.7/site-packages/airflow/operators/python.py", line 168, in __init__
    raise AirflowException("`python_callable` param must be callable")
airflow.exceptions.AirflowException: `python_callable` param must be callable
[2025-03-02T23:55:36.971+0000] {processor.py:838} WARNING - No viable dags retrieved from /opt/airflow/dags/dag_pipeline_generate_data.py
[2025-03-02T23:55:37.546+0000] {processor.py:179} INFO - Processing /opt/airflow/dags/dag_pipeline_generate_data.py took 3.940 seconds
[2025-03-02T23:56:07.686+0000] {processor.py:157} INFO - Started process (PID=3310) to work on /opt/airflow/dags/dag_pipeline_generate_data.py
[2025-03-02T23:56:07.687+0000] {processor.py:826} INFO - Processing file /opt/airflow/dags/dag_pipeline_generate_data.py for tasks to queue
[2025-03-02T23:56:07.688+0000] {logging_mixin.py:149} INFO - [2025-03-02T23:56:07.688+0000] {dagbag.py:541} INFO - Filling up the DagBag from /opt/airflow/dags/dag_pipeline_generate_data.py
[2025-03-02T23:56:11.519+0000] {logging_mixin.py:149} INFO - [2025-03-02T23:56:11.514+0000] {dagbag.py:350} ERROR - Failed to import: /opt/airflow/dags/dag_pipeline_generate_data.py
Traceback (most recent call last):
  File "/home/airflow/.local/lib/python3.7/site-packages/airflow/models/dagbag.py", line 346, in parse
    loader.exec_module(new_module)
  File "<frozen importlib._bootstrap_external>", line 728, in exec_module
  File "<frozen importlib._bootstrap>", line 219, in _call_with_frames_removed
  File "/opt/airflow/dags/dag_pipeline_generate_data.py", line 26, in <module>
    dag=dag,
  File "/home/airflow/.local/lib/python3.7/site-packages/airflow/models/baseoperator.py", line 429, in apply_defaults
    result = func(self, **kwargs, default_args=default_args)
  File "/home/airflow/.local/lib/python3.7/site-packages/airflow/operators/python.py", line 168, in __init__
    raise AirflowException("`python_callable` param must be callable")
airflow.exceptions.AirflowException: `python_callable` param must be callable
[2025-03-02T23:56:11.520+0000] {processor.py:838} WARNING - No viable dags retrieved from /opt/airflow/dags/dag_pipeline_generate_data.py
[2025-03-02T23:56:11.783+0000] {processor.py:179} INFO - Processing /opt/airflow/dags/dag_pipeline_generate_data.py took 4.099 seconds
[2025-03-02T23:56:41.887+0000] {processor.py:157} INFO - Started process (PID=3346) to work on /opt/airflow/dags/dag_pipeline_generate_data.py
[2025-03-02T23:56:41.888+0000] {processor.py:826} INFO - Processing file /opt/airflow/dags/dag_pipeline_generate_data.py for tasks to queue
[2025-03-02T23:56:41.889+0000] {logging_mixin.py:149} INFO - [2025-03-02T23:56:41.889+0000] {dagbag.py:541} INFO - Filling up the DagBag from /opt/airflow/dags/dag_pipeline_generate_data.py
[2025-03-02T23:56:45.428+0000] {logging_mixin.py:149} INFO - [2025-03-02T23:56:45.422+0000] {dagbag.py:350} ERROR - Failed to import: /opt/airflow/dags/dag_pipeline_generate_data.py
Traceback (most recent call last):
  File "/home/airflow/.local/lib/python3.7/site-packages/airflow/models/dagbag.py", line 346, in parse
    loader.exec_module(new_module)
  File "<frozen importlib._bootstrap_external>", line 728, in exec_module
  File "<frozen importlib._bootstrap>", line 219, in _call_with_frames_removed
  File "/opt/airflow/dags/dag_pipeline_generate_data.py", line 26, in <module>
    dag=dag,
  File "/home/airflow/.local/lib/python3.7/site-packages/airflow/models/baseoperator.py", line 429, in apply_defaults
    result = func(self, **kwargs, default_args=default_args)
  File "/home/airflow/.local/lib/python3.7/site-packages/airflow/operators/python.py", line 168, in __init__
    raise AirflowException("`python_callable` param must be callable")
airflow.exceptions.AirflowException: `python_callable` param must be callable
[2025-03-02T23:56:45.429+0000] {processor.py:838} WARNING - No viable dags retrieved from /opt/airflow/dags/dag_pipeline_generate_data.py
[2025-03-02T23:56:46.156+0000] {processor.py:179} INFO - Processing /opt/airflow/dags/dag_pipeline_generate_data.py took 4.272 seconds
[2025-03-02T23:57:16.643+0000] {processor.py:157} INFO - Started process (PID=3377) to work on /opt/airflow/dags/dag_pipeline_generate_data.py
[2025-03-02T23:57:16.644+0000] {processor.py:826} INFO - Processing file /opt/airflow/dags/dag_pipeline_generate_data.py for tasks to queue
[2025-03-02T23:57:16.646+0000] {logging_mixin.py:149} INFO - [2025-03-02T23:57:16.645+0000] {dagbag.py:541} INFO - Filling up the DagBag from /opt/airflow/dags/dag_pipeline_generate_data.py
[2025-03-02T23:57:20.185+0000] {logging_mixin.py:149} INFO - [2025-03-02T23:57:20.179+0000] {dagbag.py:350} ERROR - Failed to import: /opt/airflow/dags/dag_pipeline_generate_data.py
Traceback (most recent call last):
  File "/home/airflow/.local/lib/python3.7/site-packages/airflow/models/dagbag.py", line 346, in parse
    loader.exec_module(new_module)
  File "<frozen importlib._bootstrap_external>", line 728, in exec_module
  File "<frozen importlib._bootstrap>", line 219, in _call_with_frames_removed
  File "/opt/airflow/dags/dag_pipeline_generate_data.py", line 26, in <module>
    dag=dag,
  File "/home/airflow/.local/lib/python3.7/site-packages/airflow/models/baseoperator.py", line 429, in apply_defaults
    result = func(self, **kwargs, default_args=default_args)
  File "/home/airflow/.local/lib/python3.7/site-packages/airflow/operators/python.py", line 168, in __init__
    raise AirflowException("`python_callable` param must be callable")
airflow.exceptions.AirflowException: `python_callable` param must be callable
[2025-03-02T23:57:20.185+0000] {processor.py:838} WARNING - No viable dags retrieved from /opt/airflow/dags/dag_pipeline_generate_data.py
[2025-03-02T23:57:20.520+0000] {processor.py:179} INFO - Processing /opt/airflow/dags/dag_pipeline_generate_data.py took 3.880 seconds
[2025-03-02T23:57:50.613+0000] {processor.py:157} INFO - Started process (PID=3408) to work on /opt/airflow/dags/dag_pipeline_generate_data.py
[2025-03-02T23:57:50.614+0000] {processor.py:826} INFO - Processing file /opt/airflow/dags/dag_pipeline_generate_data.py for tasks to queue
[2025-03-02T23:57:50.615+0000] {logging_mixin.py:149} INFO - [2025-03-02T23:57:50.615+0000] {dagbag.py:541} INFO - Filling up the DagBag from /opt/airflow/dags/dag_pipeline_generate_data.py
[2025-03-02T23:57:54.322+0000] {logging_mixin.py:149} INFO - [2025-03-02T23:57:54.317+0000] {dagbag.py:350} ERROR - Failed to import: /opt/airflow/dags/dag_pipeline_generate_data.py
Traceback (most recent call last):
  File "/home/airflow/.local/lib/python3.7/site-packages/airflow/models/dagbag.py", line 346, in parse
    loader.exec_module(new_module)
  File "<frozen importlib._bootstrap_external>", line 728, in exec_module
  File "<frozen importlib._bootstrap>", line 219, in _call_with_frames_removed
  File "/opt/airflow/dags/dag_pipeline_generate_data.py", line 26, in <module>
    dag=dag,
  File "/home/airflow/.local/lib/python3.7/site-packages/airflow/models/baseoperator.py", line 429, in apply_defaults
    result = func(self, **kwargs, default_args=default_args)
  File "/home/airflow/.local/lib/python3.7/site-packages/airflow/operators/python.py", line 168, in __init__
    raise AirflowException("`python_callable` param must be callable")
airflow.exceptions.AirflowException: `python_callable` param must be callable
[2025-03-02T23:57:54.323+0000] {processor.py:838} WARNING - No viable dags retrieved from /opt/airflow/dags/dag_pipeline_generate_data.py
[2025-03-02T23:57:54.715+0000] {processor.py:179} INFO - Processing /opt/airflow/dags/dag_pipeline_generate_data.py took 4.105 seconds
[2025-03-02T23:58:25.175+0000] {processor.py:157} INFO - Started process (PID=3439) to work on /opt/airflow/dags/dag_pipeline_generate_data.py
[2025-03-02T23:58:25.176+0000] {processor.py:826} INFO - Processing file /opt/airflow/dags/dag_pipeline_generate_data.py for tasks to queue
[2025-03-02T23:58:25.177+0000] {logging_mixin.py:149} INFO - [2025-03-02T23:58:25.177+0000] {dagbag.py:541} INFO - Filling up the DagBag from /opt/airflow/dags/dag_pipeline_generate_data.py
[2025-03-02T23:58:28.911+0000] {logging_mixin.py:149} INFO - [2025-03-02T23:58:28.905+0000] {dagbag.py:350} ERROR - Failed to import: /opt/airflow/dags/dag_pipeline_generate_data.py
Traceback (most recent call last):
  File "/home/airflow/.local/lib/python3.7/site-packages/airflow/models/dagbag.py", line 346, in parse
    loader.exec_module(new_module)
  File "<frozen importlib._bootstrap_external>", line 728, in exec_module
  File "<frozen importlib._bootstrap>", line 219, in _call_with_frames_removed
  File "/opt/airflow/dags/dag_pipeline_generate_data.py", line 26, in <module>
    dag=dag,
  File "/home/airflow/.local/lib/python3.7/site-packages/airflow/models/baseoperator.py", line 429, in apply_defaults
    result = func(self, **kwargs, default_args=default_args)
  File "/home/airflow/.local/lib/python3.7/site-packages/airflow/operators/python.py", line 168, in __init__
    raise AirflowException("`python_callable` param must be callable")
airflow.exceptions.AirflowException: `python_callable` param must be callable
[2025-03-02T23:58:28.912+0000] {processor.py:838} WARNING - No viable dags retrieved from /opt/airflow/dags/dag_pipeline_generate_data.py
[2025-03-02T23:58:29.170+0000] {processor.py:179} INFO - Processing /opt/airflow/dags/dag_pipeline_generate_data.py took 3.998 seconds
[2025-03-02T23:58:59.833+0000] {processor.py:157} INFO - Started process (PID=3470) to work on /opt/airflow/dags/dag_pipeline_generate_data.py
[2025-03-02T23:58:59.834+0000] {processor.py:826} INFO - Processing file /opt/airflow/dags/dag_pipeline_generate_data.py for tasks to queue
[2025-03-02T23:58:59.835+0000] {logging_mixin.py:149} INFO - [2025-03-02T23:58:59.835+0000] {dagbag.py:541} INFO - Filling up the DagBag from /opt/airflow/dags/dag_pipeline_generate_data.py
[2025-03-02T23:59:06.322+0000] {logging_mixin.py:149} INFO - [2025-03-02T23:59:06.317+0000] {dagbag.py:350} ERROR - Failed to import: /opt/airflow/dags/dag_pipeline_generate_data.py
Traceback (most recent call last):
  File "/home/airflow/.local/lib/python3.7/site-packages/airflow/models/dagbag.py", line 346, in parse
    loader.exec_module(new_module)
  File "<frozen importlib._bootstrap_external>", line 728, in exec_module
  File "<frozen importlib._bootstrap>", line 219, in _call_with_frames_removed
  File "/opt/airflow/dags/dag_pipeline_generate_data.py", line 26, in <module>
    dag=dag,
  File "/home/airflow/.local/lib/python3.7/site-packages/airflow/models/baseoperator.py", line 429, in apply_defaults
    result = func(self, **kwargs, default_args=default_args)
  File "/home/airflow/.local/lib/python3.7/site-packages/airflow/operators/python.py", line 168, in __init__
    raise AirflowException("`python_callable` param must be callable")
airflow.exceptions.AirflowException: `python_callable` param must be callable
[2025-03-02T23:59:06.323+0000] {processor.py:838} WARNING - No viable dags retrieved from /opt/airflow/dags/dag_pipeline_generate_data.py
[2025-03-02T23:59:06.662+0000] {processor.py:179} INFO - Processing /opt/airflow/dags/dag_pipeline_generate_data.py took 3.848 seconds
[2025-03-02T23:59:39.217+0000] {processor.py:157} INFO - Started process (PID=3501) to work on /opt/airflow/dags/dag_pipeline_generate_data.py
[2025-03-02T23:59:39.218+0000] {processor.py:826} INFO - Processing file /opt/airflow/dags/dag_pipeline_generate_data.py for tasks to queue
[2025-03-02T23:59:39.219+0000] {logging_mixin.py:149} INFO - [2025-03-02T23:59:39.219+0000] {dagbag.py:541} INFO - Filling up the DagBag from /opt/airflow/dags/dag_pipeline_generate_data.py
[2025-03-02T23:59:42.451+0000] {logging_mixin.py:149} INFO - [2025-03-02T23:59:42.446+0000] {dagbag.py:350} ERROR - Failed to import: /opt/airflow/dags/dag_pipeline_generate_data.py
Traceback (most recent call last):
  File "/home/airflow/.local/lib/python3.7/site-packages/airflow/models/dagbag.py", line 346, in parse
    loader.exec_module(new_module)
  File "<frozen importlib._bootstrap_external>", line 728, in exec_module
  File "<frozen importlib._bootstrap>", line 219, in _call_with_frames_removed
  File "/opt/airflow/dags/dag_pipeline_generate_data.py", line 26, in <module>
    dag=dag,
  File "/home/airflow/.local/lib/python3.7/site-packages/airflow/models/baseoperator.py", line 429, in apply_defaults
    result = func(self, **kwargs, default_args=default_args)
  File "/home/airflow/.local/lib/python3.7/site-packages/airflow/operators/python.py", line 168, in __init__
    raise AirflowException("`python_callable` param must be callable")
airflow.exceptions.AirflowException: `python_callable` param must be callable
[2025-03-02T23:59:42.452+0000] {processor.py:838} WARNING - No viable dags retrieved from /opt/airflow/dags/dag_pipeline_generate_data.py
[2025-03-02T23:59:43.515+0000] {processor.py:179} INFO - Processing /opt/airflow/dags/dag_pipeline_generate_data.py took 4.301 seconds
